Workbook

Sheet Rowdata-EB
A1: Channel | B1: Brand | C1: Brand Type | D1: Region | E1: City Type | F1: City | G1: Code | H1: Btq/POS Name | I1: Shopping Mall | J1: Commercial Area | K1: Opening Date | L1: If in the same shopping mall | M1: Month | N1: LE23 Sales Value (w/o VAT) | O1: FY22 Sales Value (w/o VAT) | P1: FY21 Sales Value (w/o VAT) | Q1: FY20 Sales Value (w/o VAT) | R1: LE23 vs FY22 | S1: FY22 vs FY21 | T1: FY21 vs FY20 | U1: Sqm Efficiency | V1: 去除O
A2: External | B2: BOSS | C2: Fashion | D2: External | E2: PROVINCIAL CAPITALS | F2: Shenzhen | G2: 374870 | H2: SZ BA | I2: BaoAn Airport | L2: Y | M2: Apr | N2: 575221.24 | O2: 2096421.7 | R2: -0.72561759 | S2: 0 | T2: 0 | U2: 0
A3: External | B3: Burberry | C3: Fashion | D3: External | E3: PROVINCIAL CAPITALS | F3: Shenzhen | G3: 374870 | H3: SZ BA | I3: BaoAn Airport | K3: 2020 Sep | L3: Y | M3: Apr | N3: 1601769.9 | O3: 7823580 | R3: -0.79526382 | S3: 0 | T3: 0 | U3: 0
A4: External | B4: Bvlgari | C4: Fashion | D4: External | E4: PROVINCIAL CAPITALS | F4: Shenzhen | G4: 374870 | H4: SZ BA | I4: BaoAn Airport | K4: new opening | L4: Y | M4: Apr | N4: 1323238.9 | R4: 0 | S4: 0 | T4: 0 | U4: 0
A5: External | B5: Cartier | C5: Watch & Jew | D5: External | E5: PROVINCIAL CAPITALS | F5: Shenzhen | G5: 374870 | H5: SZ BA | I5: BaoAn Airport | J5: 120 | K5: 2020 Aug | L5: Y | M5: Apr | N5: 2526400 | O5: 9805433.6 | R5: -0.74234694 | S5: 0 | T5: 0 | U5: ACTIVE
A6: External | B6: EA | C6: Fashion | D6: External | E6: PROVINCIAL CAPITALS | F6: Shenzhen | G6: 374870 | H6: SZ BA | I6: BaoAn Airport | L6: Y | M6: Apr | N6: 557522.12 | O6: 2239495 | R6: -0.75105007 | S6: 0 | T6: 0 | U6: 0
A7: External | B7: Ermenegildo | C7: Fashion | D7: External | E7: PROVINCIAL CAPITALS | F7: Shenzhen | G7: 374870 | H7: SZ BA | I7: BaoAn Airport | J7: 75 | K7: 2020 Aug | L7: Y | M7: Apr | N7: 796460.18 | O7: 2977238 | R7: -0.73248354 | S7: 0 | T7: 0 | U7: ACTIVE
A8: External | B8: Ferragamo | C8: Fashion | D8: External | E8: PROVINCIAL CAPITALS | F8: Shenzhen | G8: 374870 | H8: SZ BA | I8: BaoAn Airport | J8: 85 | K8: 2020 Aug | L8: Y | M8: Apr | N8: 1238938.1 | O8: 2476516.5 | R8: -0.4997255 | S8: 0 | T8: 0 | U8: ACTIVE
A9: External | B9: GUCCI | C9: Fashion | D9: External | E9: PROVINCIAL CAPITALS | F9: Shenzhen | G9: 374870 | H9: SZ BA | I9: BaoAn Airport | L9: Y | M9: Apr | N9: 1875110 | R9: 0 | S9: 0 | T9: 0 | U9: 0
A10: External | B10: Max Mara | C10: Fashion | D10: External | E10: PROVINCIAL CAPITALS | F10: Shenzhen | G10: 374870 | H10: SZ BA | I10: BaoAn Airport | L10: Y | M10: Apr | N10: 619469.03 | O10: 1432688 | R10: -0.56761763 | S10: 0 | T10: 0 | U10: 0
A11: External | B11: Prada | C11: Fashion | D11: External | E11: PROVINCIAL CAPITALS | F11: Shenzhen | G11: 374870 | H11: SZ BA | I11: BaoAn Airport | L11: Y | M11: Apr | N11: 946902 | R11: 0 | S11: 0 | T11: 0 | U11: 0
A12: External | B12: BOSS | C12: Fashion | D12: External | E12: PROVINCIAL CAPITALS | F12: Shenzhen | G12: 374870 | H12: SZ BA | I12: BaoAn Airport | L12: Y | M12: Jun | N12: 884955.75 | O12: 769870 | R12: 0.14948725 | S12: 0 | T12: 0 | U12: 0
A13: External | B13: Burberry | C13: Fashion | D13: External | E13: PROVINCIAL CAPITALS | F13: Shenzhen | G13: 374870 | H13: SZ BA | I13: BaoAn Airport | K13: 2020 Sep | L13: Y | M13: Jun | N13: 1592920.4 | O13: 2173190 | R13: -0.26701285 | S13: 0 | T13: 0 | U13: 0
A14: External | B14: Bvlgari | C14: Fashion | D14: External | E14: PROVINCIAL CAPITALS | F14: Shenzhen | G14: 374870 | H14: SZ BA | I14: BaoAn Airport | K14: new opening | L14: Y | M14: Jun | N14: 2654867.3 | O14: 1236740 | R14: 1.1466656 | S14: 0 | T14: 0 | U14: 0
A15: External | B15: Cartier | C15: Watch & Jew | D15: External | E15: PROVINCIAL CAPITALS | F15: Shenzhen | G15: 374870 | H15: SZ BA | I15: BaoAn Airport | J15: 120 | K15: 2020 Aug | L15: Y | M15: Jun | N15: 4619192 | O15: 1858761.1 | R15: 1.4850919 | S15: 0 | T15: 0 | U15: ACTIVE
A16: External | B16: EA | C16: Fashion | D16: External | E16: PROVINCIAL CAPITALS | F16: Shenzhen | G16: 374870 | H16: SZ BA | I16: BaoAn Airport | L16: Y | M16: Jun | N16: 796460.18 | O16: 614557 | R16: 0.29599073 | S16: 0 | T16: 0 | U16: 0
A17: External | B17: Ermenegildo | C17: Fashion | D17: External | E17: PROVINCIAL CAPITALS | F17: Shenzhen | G17: 374870 | H17: SZ BA | I17: BaoAn Airport | J17: 75 | K17: 2020 Aug | L17: Y | M17: Jun | N17: 973451.33 | O17: 858745 | R17: 0.13357438 | S17: 0 | T17: 0 | U17: ACTIVE
A18: External | B18: Ferragamo | C18: Fashion | D18: External | E18: PROVINCIAL CAPITALS | F18: Shenzhen | G18: 374870 | H18: SZ BA | I18: BaoAn Airport | J18: 85 | K18: 2020 Aug | L18: Y | M18: Jun | N18: 2212389.4 | O18: 1287058 | R18: 0.7189508 | S18: 0 | T18: 0 | U18: ACTIVE
A19: External | B19: GUCCI | C19: Fashion | D19: External | E19: PROVINCIAL CAPITALS | F19: Shenzhen | G19: 374870 | H19: SZ BA | I19: BaoAn Airport | L19: Y | M19: Jun | N19: 3681597 | R19: 0 | S19: 0 | T19: 0 | U19: 0
A20: External | B20: Max Mara | C20: Fashion | D20: External | E20: PROVINCIAL CAPITALS | F20: Shenzhen | G20: 374870 | H20: SZ BA | I20: BaoAn Airport | L20: Y | M20: Jun | N20: 1592920.4 | O20: 562814 | R20: 1.8302785 | S20: 0 | T20: 0 | U20: 0
A21: External | B21: Prada | C21: Fashion | D21: External | E21: PROVINCIAL CAPITALS | F21: Shenzhen | G21: 374870 | H21: SZ BA | I21: BaoAn Airport | L21: Y | M21: Jun | N21: 2230080 | R21: 0 | S21: 0 | T21: 0 | U21: 0
A22: External | B22: BOSS | C22: Fashion | D22: External | E22: PROVINCIAL CAPITALS | F22: Shenzhen | G22: 374870 | H22: SZ BA | I22: BaoAn Airport | L22: Y | M22: May | N22: 893805.31 | O22: 2137615 | R22: -0.58186797 | S22: 0 | T22: 0 | U22: 0
A23: External | B23: Burberry | C23: Fashion | D23: External | E23: PROVINCIAL CAPITALS | F23: Shenzhen | G23: 374870 | H23: SZ BA | I23: BaoAn Airport | K23: 2020 Sep | L23: Y | M23: May | N23: 2681415.9 | O23: 7072890 | R23: -0.62088822 | S23: 0 | T23: 0 | U23: 0
A24: External | B24: Bvlgari | C24: Fashion | D24: External | E24: PROVINCIAL CAPITALS | F24: Shenzhen | G24: 374870 | H24: SZ BA | I24: BaoAn Airport | K24: new opening | L24: Y | M24: May | N24: 1764318.6 | O24: 4627800 | R24: -0.61875652 | S24: 0 | T24: 0 | U24: 0
A25: External | B25: Cartier | C25: Watch & Jew | D25: External | E25: PROVINCIAL CAPITALS | F25: Shenzhen | G25: 374870 | H25: SZ BA | I25: BaoAn Airport | J25: 120 | K25: 2020 Aug | L25: Y | M25: May | N25: 5877334 | O25: 9051455.8 | R25: -0.35067528 | S25: 0 | T25: 0 | U25: ACTIVE
A26: External | B26: EA | C26: Fashion | D26: External | E26: PROVINCIAL CAPITALS | F26: Shenzhen | G26: 374870 | H26: SZ BA | I26: BaoAn Airport | L26: Y | M26: May | N26: 734513.27 | O26: 2117101.5 | R26: -0.65305713 | S26: 0 | T26: 0 | U26: 0
A27: External | B27: Ermenegildo | C27: Fashion | D27: External | E27: PROVINCIAL CAPITALS | F27: Shenzhen | G27: 374870 | H27: SZ BA | I27: BaoAn Airport | J27: 75 | K27: 2020 Aug | L27: Y | M27: May | N27: 1017699.1 | O27: 2498720 | R27: -0.59271182 | S27: 0 | T27: 0 | U27: ACTIVE
A28: External | B28: Ferragamo | C28: Fashion | D28: External | E28: PROVINCIAL CAPITALS | F28: Shenzhen | G28: 374870 | H28: SZ BA | I28: BaoAn Airport | J28: 85 | K28: 2020 Aug | L28: Y | M28: May | N28: 1893805.3 | O28: 2742878.5 | R28: -0.30955552 | S28: 0 | T28: 0 | U28: ACTIVE
A29: External | B29: GUCCI | C29: Fashion | D29: External | E29: PROVINCIAL CAPITALS | F29: Shenzhen | G29: 374870 | H29: SZ BA | I29: BaoAn Airport | L29: Y | M29: May | N29: 3095982 | R29: 0 | S29: 0 | T29: 0 | U29: 0
A30: External | B30: Max Mara | C30: Fashion | D30: External | E30: PROVINCIAL CAPITALS | F30: Shenzhen | G30: 374870 | H30: SZ BA | I30: BaoAn Airport | L30: Y | M30: May | N30: 557522.12 | O30: 1544008 | R30: -0.63891241 | S30: 0 | T30: 0 | U30: 0
A31: External | B31: Prada | C31: Fashion | D31: External | E31: PROVINCIAL CAPITALS | F31: Shenzhen | G31: 374870 | H31: SZ BA | I31: BaoAn Airport | L31: Y | M31: May | N31: 1584070.8 | R31: 0 | S31: 0 | T31: 0 | U31: 0
A32: Travel Retail | B32: BOSS | C32: Fashion | D32: External | E32: PROVINCIAL CAPITALS | F32: Shenzhen | G32: 374870 | H32: SZ BA | I32: BaoAn Airport | L32: Y | M32: Jul | N32: 973451.33 | O32: 1293905 | R32: -0.24766399 | S32: 0 | T32: 0 | U32: 0
A33: Travel Retail | B33: Burberry | C33: Fashion | D33: External | E33: PROVINCIAL CAPITALS | F33: Shenzhen | G33: 374870 | H33: SZ BA | I33: BaoAn Airport | K33: 2020 Sep | L33: Y | M33: Jul | N33: 1221238.9 | O33: 3212165 | R33: -0.61980815 | S33: 0 | T33: 0 | U33: 0
A34: Travel Retail | B34: Bvlgari | C34: Fashion | D34: External | E34: PROVINCIAL CAPITALS | F34: Shenzhen | G34: 374870 | H34: SZ BA | I34: BaoAn Airport | L34: Y | M34: Jul | N34: 890641.59 | O34: 2892315 | R34: -0.69206618 | S34: 0 | T34: 0 | U34: 0
A35: Travel Retail | B35: Cartier | C35: Watch & Jew | D35: External | E35: PROVINCIAL CAPITALS | F35: Shenzhen | G35: 374870 | H35: SZ BA | I35: BaoAn Airport | J35: 120 | K35: 2020 Aug | L35: Y | M35: Jul | N35: 3095962 | O35: 4629331.9 | R35: -0.33122919 | S35: 0 | T35: 0 | U35: ACTIVE
A36: Travel Retail | B36: EA | C36: Fashion | D36: External | E36: PROVINCIAL CAPITALS | F36: Shenzhen | G36: 374870 | H36: SZ BA | I36: BaoAn Airport | L36: Y | M36: Jul | N36: 663716.81 | O36: 1364437.5 | R36: -0.51356012 | S36: 0 | T36: 0 | U36: 0
A37: Travel Retail | B37: Ermenegildo | C37: Fashion | D37: External | E37: PROVINCIAL CAPITALS | F37: Shenzhen | G37: 374870 | H37: SZ BA | I37: BaoAn Airport | J37: 75 | K37: 2020 Aug | L37: Y | M37: Jul | N37: 867256.64 | O37: 1227250 | R37: -0.29333336 | S37: 0 | T37: 0 | U37: ACTIVE
A38: Travel Retail | B38: Ferragamo | C38: Fashion | D38: External | E38: PROVINCIAL CAPITALS | F38: Shenzhen | G38: 374870 | H38: SZ BA | I38: BaoAn Airport | J38: 85 | K38: 2020 Aug | L38: Y | M38: Jul | N38: 1654867.3 | O38: 1490858 | R38: 0.11000998 | S38: 0 | T38: 0 | U38: ACTIVE
A39: Travel Retail | B39: GUCCI | C39: Fashion | D39: External | E39: PROVINCIAL CAPITALS | F39: Shenzhen | G39: 374870 | H39: SZ BA | I39: BaoAn Airport | L39: Y | M39: Jul | N39: 3337766 | R39: 0 | S39: 0 | T39: 0 | U39: 0
A40: Travel Retail | B40: Max Mara | C40: Fashion | D40: External | E40: PROVINCIAL CAPITALS | F40: Shenzhen | G40: 374870 | H40: SZ BA | I40: BaoAn Airport | L40: Y | M40: Jul | N40: 1221238.9 | O40: 1797236 | R40: -0.3204905 | S40: 0 | T40: 0 | U40: 0
...

Sheet weekly
A1: BTQ | B1: 列2 | C1: 列3 | D1: 列4 | H1: Competitor | I1: CDIFS | J1: CDTKL | K1: CDSKP | L1: GZTKH | M1: SZBAY | N1: SZLH | O1: CDIFS | P1: CDTKL | Q1: CDSKP | R1: GZTKH | S1: SZBAY | T1: SZLH | U1: CDIFS | V1: CDTKL | W1: CDSKP | X1: GZTKH | Y1: SZBAY | Z1: SZLH | AA1: CDIFS | AB1: CDTKL | AC1: CDSKP | AD1: GZTKH | AE1: SZBAY | AF1: SZLH | AG1: CDIFS | AH1: CDTKL | AI1: CDSKP | AJ1: GZTKH | AK1: SZBAY | AL1: SZLH | AM1: Competitor | AN1: CDIFS | AO1: CDTKL | AP1: CDSKP | AQ1: GZTKH | AR1: SZBAY | AS1: SZLH
A2: BTQ | B2: MTD | C2: LY | D2: vs LY | I2: week 1 | J2: week 1 | K2: week 1 | L2: week 1 | M2: week 1 | N2: week 1 | O2: week 2 | P2: week 2 | Q2: week 2 | R2: week 2 | S2: week 2 | T2: week 2 | U2: week 3 | V2: week 3 | W2: week 3 | X2: week 3 | Y2: week 3 | Z2: week 3 | AA2: week 4 | AB2: week 4 | AC2: week 4 | AD2: week 4 | AE2: week 4 | AF2: week 4 | AG2: week 5 | AH2: week 5 | AI2: week 5 | AJ2: week 5 | AK2: week 5 | AL2: week 5 | AN2: m | AO2: m | AP2: m | AQ2: m | AR2: m | AS2: m
I3: 4/1-/7 | J3: 4/1-/7 | K3: 4/1-/7 | L3: 4/1-/7 | M3: 4/1-/7 | N3: 4/1-/7 | O3: 4/8-4/14 | P3: 4/8-4/14 | Q3: 4/8-4/14 | R3: 4/8-4/14 | S3: 4/8-4/14 | T3: 4/8-4/14 | U3: 4/15-4/21 | V3: 4/15-4/21 | W3: 4/15-4/21 | X3: 4/15-4/21 | Y3: 4/15-4/21 | Z3: 4/15-4/21 | AA3: 4/22-4/28 | AB3: 4/22-4/28 | AC3: 4/22-4/28 | AD3: 4/22-4/28 | AE3: 4/22-4/28 | AF3: 4/22-4/28 | AG3: 4/29-4/30 | AH3: 4/29-4/30 | AI3: 4/29-4/30 | AJ3: 4/29-4/30 | AK3: 4/29-4/30 | AL3: 4/29-4/30
A4: CDIFS | B4: 1375187 | C4: 2908187 | D4: -0.52713254 | H4: Cartier | I4: Jul | J4: Jul | K4: Jul | L4: Jul | M4: Jul | N4: Jul | O4: 562290.7 | P4: 1204558 | Q4: 3312616.3 | R4: 1693530.5 | S4: 1695305.3 | T4: 2510320.4 | U4: 2230196.3 | V4: 1208971.6 | W4: 830384.08 | X4: 3006178.1 | Y4: 1999077.4 | Z4: 1513181.8 | AA4: -0.74787389 | AB4: -0.0036506896 | AC4: 2.989258 | AD4: -0.43664997 | AE4: -0.15195613 | AF4: 0.65896812 | AG4: 0 | AH4: 0 | AI4: 0 | AJ4: 0 | AK4: 0 | AL4: 0 | AM4: Cartier | AN4: =I4+O4+U4+AA4+AG4 -> #VALUE! | AO4: =J4+P4+V4+AB4+AH4 -> #VALUE! | AP4: =K4+Q4+W4+AC4+AI4 -> #VALUE! | AQ4: =L4+R4+X4+AD4+AJ4 -> #VALUE! | AR4: =M4+S4+Y4+AE4+AK4 -> #VALUE! | AS4: =N4+T4+Z4+AF4+AL4 -> #VALUE!
A5: CDTKL | B5: 1873195 | C5: 2497108 | D5: -0.24985423 | H5: Bulgari | I5: Jul | J5: Jul | K5: Jul | L5: Jul | M5: Jul | N5: Jul | O5: - | P5: 4000000 | Q5: 5550000 | R5: 4610000 | S5: 3000000 | T5: 3630000 | U5: - | V5: 11100000 | W5: 2300000 | X5: 7000000 | Y5: - | Z5: 7450000 | AA5: #VALUE! | AB5: -0.63963964 | AC5: 1.4130435 | AD5: -0.34142857 | AE5: #VALUE! | AF5: -0.51275168 | AG5: #VALUE! | AH5: 0.3011395 | AI5: 0.59686781 | AJ5: 0.3673602 | AK5: 0.56510177 | AL5: 0.69154831 | AM5: Bulgari | AN5: =I5+O5+U5+AA5+AG5 -> #VALUE! | AO5: =J5+P5+V5+AB5+AH5 -> #VALUE! | AP5: =K5+Q5+W5+AC5+AI5 -> #VALUE! | AQ5: =L5+R5+X5+AD5+AJ5 -> #VALUE! | AR5: =M5+S5+Y5+AE5+AK5 -> #VALUE! | AS5: =N5+T5+Z5+AF5+AL5 -> #VALUE!
A6: CDSKP | B6: 9706222 | C6: 14974849 | D6: -0.35183173 | H6: Tiffany | I6: Aug | J6: Aug | K6: Aug | L6: Aug | M6: Aug | N6: Aug | O6: 0 | P6: 5000000 | Q6: 6430000 | R6: 6900000 | S6: 4500000 | T6: 23570000 | U6: - | V6: 13000000 | W6: 12000000 | X6: 10300000 | Y6: - | Z6: 10000000 | AA6: #VALUE! | AB6: -0.61538462 | AC6: -0.46416667 | AD6: -0.33009709 | AE6: #VALUE! | AF6: 1.357 | AG6: #DIV/0! | AH6: 0.32868992 | AI6: 0.62333722 | AJ6: 0.48202662 | AK6: 0.84587947 | AL6: 0.094236692 | AM6: Tiffany | AN6: =I6+O6+U6+AA6+AG6 -> #VALUE! | AO6: =J6+P6+V6+AB6+AH6 -> #VALUE! | AP6: =K6+Q6+W6+AC6+AI6 -> #VALUE! | AQ6: =L6+R6+X6+AD6+AJ6 -> #VALUE! | AR6: =M6+S6+Y6+AE6+AK6 -> #VALUE! | AS6: =N6+T6+Z6+AF6+AL6 -> #VALUE!
A7: GZTKH | B7: 2953030 | C7: 797742 | D7: 2.7017356 | H7: VCA | I7: Aug | J7: Aug | K7: Aug | L7: Aug | M7: Aug | N7: Aug | O7: 1577706.2 | P7: 1643449.6 | Q7: 4008058.4 | R7: 3325983.7 | S7: 3806457.6 | T7: 2221158.8 | U7: 1634026 | V7: 2041356.6 | W7: 12006049 | X7: 4536762.7 | Y7: 3824329.9 | Z7: 3012063.2 | AA7: -0.034466913 | AB7: -0.19492283 | AC7: -0.66616343 | AD7: -0.26688171 | AE7: -0.0046733217 | AF7: -0.26257895 | AG7: 0 | AH7: 0 | AI7: 0 | AJ7: 0 | AK7: 0 | AL7: 0 | AM7: VCA | AN7: =I7+O7+U7+AA7+AG7 -> #VALUE! | AO7: =J7+P7+V7+AB7+AH7 -> #VALUE! | AP7: =K7+Q7+W7+AC7+AI7 -> #VALUE! | AQ7: =L7+R7+X7+AD7+AJ7 -> #VALUE! | AR7: =M7+S7+Y7+AE7+AK7 -> #VALUE! | AS7: =N7+T7+Z7+AF7+AL7 -> #VALUE!
A8: SZBAY | B8: 1573117 | C8: 2262078 | D8: -0.30456996
A9: SZLH | B9: 971802 | C9: 10493306 | D9: -0.90738839
A10: CD | B10: 12954604 | C10: 20380144 | D10: -0.36435169
A11: SZ | B11: 2544919 | C11: 12755384 | D11: -0.80048276
A12: GZ | B12: 2953030 | C12: 797742 | D12: 2.7017356
A13: South | B13: =SUM(B4:B9) -> 18452553 | C13: =SUM(C4:C9) -> 33933270 | D13: =B13/C13-1 -> -0.45621059

Sheet Dashboard 
B1: Chaumet vs Competitor Sales Performance
B2: Year Month | C2: 202505
C3: MTD | J3: MTD | W3: YTD | AD3: YTD
C4: Mar vs LY | D4: BTQ | J4: CITY | P4: CITY | S4: REGION | W4: YTD vs LY | X4: BTQ | AD4: CITY | AJ4: CITY | AM4: REGION
D5: CDIFS | E5: CDTKL | F5: CDSKP | G5: GZTKH | H5: SZBAY | I5: SZLH | J5: CD MTD | K5: CD 2024 | L5: GZ MTD | M5: GZ 2024 | N5: SZ MTD | O5: SZ 2024 | P5: CD | Q5: GZ | R5: SZ | S5: SOUTH | X5: CDIFS | Y5: CDTKL | Z5: CDSKP | AA5: GZTKH | AB5: SZBAY | AC5: SZLH | AD5: CD YTD | AE5: CD LY | AF5: GZ YTD | AG5: GZ LY | AH5: SZ YTD | AI5: SZ LY | AJ5: CD | AK5: GZ | AL5: SZ | AM5: SOUTH
C6: Chaumet | D6: =CDIFS!F35 -> -0.33101516 | E6: =CDTKL!#REF! -> #REF! | F6: =CDSKP!#REF! -> #REF! | G6: =GZTKH!#REF! -> #REF! | H6: =SZBAY!#REF! -> #REF! | I6: =SZLH!#REF! -> #REF! | J6: =CDIFS!D35+CDTKL!E22+CDSKP!E22 -> 4002670.4 | K6: =CDIFS!E35+CDTKL!#REF!+CDSKP!#REF! -> #REF! | L6: =GZTKH!E22 -> 1492618.1 | M6: =GZTKH!#REF! -> #REF! | N6: =SZBAY!E22+SZLH!E22 -> 6767993.4 | O6: =SZBAY!#REF!+SZLH!#REF! -> #REF! | P6: =J6/K6-1 -> #REF! | Q6: =L6/M6-1 -> #REF! | R6: =N6/O6-1 -> #REF! | S6: =South!F35 -> -0.26906612 | T6: 已填写公式 | W6: Chaumet | X6: =CDIFS!F2 -> 0.2392491 | Y6: =CDTKL!#REF! -> #REF! | Z6: =CDSKP!#REF! -> #REF! | AA6: =GZTKH!#REF! -> #REF! | AB6: =SZBAY!#REF! -> #REF! | AC6: =SZLH!#REF! -> #REF! | AD6: =SUM(CDIFS!D2,CDTKL!#REF!,CDSKP!#REF!) -> #REF! | AE6: =SUM(CDIFS!E2,CDTKL!#REF!,CDSKP!#REF!) -> #REF! | AF6: =GZTKH!#REF! -> #REF! | AG6: =GZTKH!#REF! -> #REF! | AH6: =SUM(SZBAY!#REF!,SZLH!#REF!) -> #REF! | AI6: =SUM(SZBAY!#REF!,SZLH!#REF!) -> #REF! | AJ6: =AD6/AE6-1 -> #REF! | AK6: =AF6/AG6-1 -> #REF! | AL6: =AH6/AI6-1 -> #REF! | AM6: =South!F2 -> -0.061103692 | AN6: 已填写公式
C7: Cartier | D7: =CDIFS!F36 | E7: =CDTKL!#REF! -> #REF! | F7: =CDSKP!#REF! -> #REF! | G7: =GZTKH!#REF! -> #REF! | H7: =SZBAY!#REF! -> #REF! | I7: =SZLH!#REF! -> #REF! | J7: =CDIFS!D36+CDTKL!E23+CDSKP!E23 -> 27870000 | K7: =CDIFS!E36+CDTKL!#REF!+CDSKP!#REF! -> #REF! | L7: =GZTKH!E23 -> 28000000 | M7: =GZTKH!#REF! -> #REF! | N7: =SZBAY!E23+SZLH!E23 -> 32180000 | O7: =SZBAY!#REF!+SZLH!#REF! -> #REF! | P7: =J7/K7-1 -> #REF! | Q7: =G7 -> #REF! | R7: =N7/O7-1 -> #REF! | S7: =South!F36 -> -0.0086692186 | T7: 已填写公式 | W7: Cartier | X7: =CDIFS!F3 | Y7: =CDTKL!#REF! -> #REF! | Z7: =CDSKP!#REF! -> #REF! | AA7: =GZTKH!#REF! -> #REF! | AB7: =SZBAY!#REF! -> #REF! | AC7: =SZLH!#REF! -> #REF! | AD7: =SUM(CDIFS!D3,CDTKL!#REF!,CDSKP!#REF!) -> #REF! | AE7: =SUM(CDIFS!E3,CDTKL!#REF!,CDSKP!#REF!) -> #REF! | AF7: =GZTKH!#REF! -> #REF! | AG7: =GZTKH!#REF! -> #REF! | AH7: =SUM(SZBAY!#REF!,SZLH!#REF!) -> #REF! | AI7: =SUM(SZBAY!#REF!,SZLH!#REF!) -> #REF! | AJ7: =AD7/AE7-1 -> #REF! | AK7: =AA7 -> #REF! | AL7: =AH7/AI7-1 -> #REF! | AM7: =South!F3 -> -0.079637933 | AN7: 已填写公式
C8: Mix% | D8: =CDIFS!G36 | E8: =CDTKL!#REF! -> #REF! | F8: =CDSKP!#REF! -> #REF! | G8: =GZTKH!#REF! -> #REF! | H8: =SZBAY!#REF! -> #REF! | I8: =SZLH!#REF! -> #REF! | J8: =J6/J7 -> 0.14361932 | K8: =K6/K7 -> #REF! | L8: =L6/L7 -> 0.05330779 | M8: =M6/M7 -> #REF! | N8: =N6/N7 -> 0.21031676 | O8: =O6/O7 -> #REF! | P8: =J8 -> 0.14361932 | Q8: =L8 -> 0.05330779 | R8: =N8 -> 0.21031676 | S8: =South!G36 -> 0.13927634 | T8: 已填写公式 | W8: Mix% | X8: =CDIFS!G3 | Y8: =CDTKL!#REF! -> #REF! | Z8: =CDSKP!#REF! -> #REF! | AA8: =GZTKH!#REF! -> #REF! | AB8: =SZBAY!#REF! -> #REF! | AC8: =SZLH!#REF! -> #REF! | AD8: =AD6/AD7 -> #REF! | AE8: =AE6/AE7 -> #REF! | AF8: =AF6/AF7 -> #REF! | AG8: =AG6/AG7 -> #REF! | AH8: =AH6/AH7 -> #REF! | AI8: =AI6/AI7 -> #REF! | AJ8: =AD8 -> #REF! | AK8: =AF8 -> #REF! | AL8: =AH8 -> #REF! | AM8: =South!G3 -> 0.176794 | AN8: 已填写公式
C9: Bulgari | D9: =CDIFS!F37 -> -0.27426528 | E9: =CDTKL!#REF! -> #REF! | F9: =CDSKP!#REF! -> #REF! | G9: =GZTKH!#REF! -> #REF! | H9: =SZBAY!#REF! -> #REF! | I9: =SZLH!#REF! -> #REF! | J9: =CDIFS!D37+CDTKL!E24+CDSKP!E24 -> 8735290 | K9: =CDIFS!E37+CDTKL!#REF!+CDSKP!#REF! -> #REF! | L9: =GZTKH!E24 -> 10250000 | M9: =GZTKH!#REF! -> #REF! | N9: =SZBAY!E24+SZLH!E24 -> 8700000 | O9: =SZBAY!#REF!+SZLH!#REF! -> #REF! | P9: =J9/K9-1 -> #REF! | Q9: =L9/M9-1 -> #REF! | R9: =N9/O9-1 -> #REF! | S9: =South!F37 -> -0.12554359 | T9: 已填写公式 | W9: Bulgari | X9: =CDIFS!F4 -> -0.26642337 | Y9: =CDTKL!#REF! -> #REF! | Z9: =CDSKP!#REF! -> #REF! | AA9: =GZTKH!#REF! -> #REF! | AB9: =SZBAY!#REF! -> #REF! | AC9: =SZLH!#REF! -> #REF! | AD9: =SUM(CDIFS!D4,CDTKL!#REF!,CDSKP!#REF!) -> #REF! | AE9: =SUM(CDIFS!E4,CDTKL!#REF!,CDSKP!#REF!) -> #REF! | AF9: =GZTKH!#REF! -> #REF! | AG9: =GZTKH!#REF! -> #REF! | AH9: =SUM(SZBAY!#REF!,SZLH!#REF!) -> #REF! | AI9: =SUM(SZBAY!#REF!,SZLH!#REF!) -> #REF! | AJ9: =AD9/AE9-1 -> #REF! | AK9: =AA9 -> #REF! | AL9: =AH9/AI9-1 -> #REF! | AM9: =South!F4 -> -0.01252016 | AN9: 已填写公式
C10: Mix% | D10: =CDIFS!G37 -> 0.13922735 | E10: =CDTKL!#REF! -> #REF! | F10: =CDSKP!#REF! -> #REF! | G10: =GZTKH!#REF! -> #REF! | H10: =SZBAY!#REF! -> #REF! | I10: =SZLH!#REF! -> #REF! | J10: =J6/J9 -> 0.45821838 | K10: =K6/K9 -> #REF! | L10: =L6/L9 -> 0.14562128 | M10: =M6/M9 -> #REF! | N10: =N6/N9 -> 0.77793027 | O10: =O6/O9 -> #REF! | P10: =J10 -> 0.45821838 | Q10: =L10 -> 0.14562128 | R10: =N10 -> 0.77793027 | S10: =South!G37 -> 0.44295299 | T10: 已填写公式 | W10: Mix% | X10: =CDIFS!G4 -> 0.26509885 | Y10: =CDTKL!#REF! -> #REF! | Z10: =CDSKP!#REF! -> #REF! | AA10: =GZTKH!#REF! -> #REF! | AB10: =SZBAY!#REF! -> #REF! | AC10: =SZLH!#REF! -> #REF! | AD10: =AD6/AD9 -> #REF! | AE10: =AE6/AE9 -> #REF! | AF10: =AF6/AF9 -> #REF! | AG10: =AG6/AG9 -> #REF! | AH10: =AH6/AH9 -> #REF! | AI10: =AI6/AI9 -> #REF! | AJ10: =AD10 -> #REF! | AK10: =AF10 -> #REF! | AL10: =AH10 -> #REF! | AM10: =South!G4 -> 0.41747544 | AN10: 已填写公式
C11: Tiffany | D11: =CDIFS!F38 | E11: =CDTKL!#REF! -> #REF! | F11: =CDSKP!#REF! -> #REF! | G11: =GZTKH!#REF! -> #REF! | H11: =SZBAY!#REF! -> #REF! | I11: =SZLH!#REF! -> #REF! | J11: =CDIFS!D38+CDTKL!E25+CDSKP!E25 -> 10438000 | K11: =CDIFS!E38+CDTKL!#REF!+CDSKP!#REF! -> #REF! | L11: =GZTKH!E25 -> 6550000 | M11: =GZTKH!#REF! -> #REF! | N11: =SZBAY!E25+SZLH!E25 -> 8380000 | O11: =SZBAY!#REF!+SZLH!#REF! -> #REF! | P11: =J11/K11-1 -> #REF! | Q11: =L11/M11-1 -> #REF! | R11: =N11/O11-1 -> #REF! | S11: =South!F38 -> -0.085442353 | T11: 已填写公式 | W11: Tiffany | X11: =CDIFS!F5 | Y11: =CDTKL!#REF! -> #REF! | Z11: =CDSKP!#REF! -> #REF! | AA11: =GZTKH!#REF! -> #REF! | AB11: =SZBAY!#REF! -> #REF! | AC11: =SZLH!#REF! -> #REF! | AD11: =SUM(CDIFS!D5,CDTKL!#REF!,CDSKP!#REF!) -> #REF! | AE11: =SUM(CDIFS!E5,CDTKL!#REF!,CDSKP!#REF!) -> #REF! | AF11: =GZTKH!#REF! -> #REF! | AG11: =GZTKH!#REF! -> #REF! | AH11: =SUM(SZBAY!#REF!,SZLH!#REF!) -> #REF! | AI11: =SUM(SZBAY!#REF!,SZLH!#REF!) -> #REF! | AJ11: =AD11/AE11-1 -> #REF! | AK11: =AA11 -> #REF! | AL11: =AH11/AI11-1 -> #REF! | AM11: =South!F5 -> -0.029020675 | AN11: 已填写公式
C12: Mix% | D12: =CDIFS!G38 -> 0.53889133 | E12: =CDTKL!#REF! -> #REF! | F12: =CDSKP!#REF! -> #REF! | G12: =GZTKH!#REF! -> #REF! | H12: =SZBAY!#REF! -> #REF! | I12: =SZLH!#REF! -> #REF! | J12: =J6/J11 -> 0.38347101 | K12: =K6/K11 -> #REF! | L12: =L6/L11 -> 0.22788063 | M12: =M6/M11 -> #REF! | N12: =N6/N11 -> 0.80763644 | O12: =O6/O11 -> #REF! | P12: =J12 -> 0.38347101 | Q12: =L12 -> 0.22788063 | R12: =N12 -> 0.80763644 | S12: =South!G38 -> 0.4834154 | T12: 已填写公式 | W12: Mix% | X12: =CDIFS!G5 -> 1.2024712 | Y12: =CDTKL!#REF! -> #REF! | Z12: =CDSKP!#REF! -> #REF! | AA12: =GZTKH!#REF! -> #REF! | AB12: =SZBAY!#REF! -> #REF! | AC12: =SZLH!#REF! -> #REF! | AD12: =AD6/AD11 -> #REF! | AE12: =AE6/AE11 -> #REF! | AF12: =AF6/AF11 -> #REF! | AG12: =AG6/AG11 -> #REF! | AH12: =AH6/AH11 -> #REF! | AI12: =AI6/AI11 -> #REF! | AJ12: =AD12 -> #REF! | AK12: =AF12 -> #REF! | AL12: =AH12 -> #REF! | AM12: =South!G5 -> 0.47957209 | AN12: 已填写公式
C13: VCA | D13: =CDIFS!F39 -> -0.39121173 | E13: =CDTKL!#REF! -> #REF! | F13: =CDSKP!#REF! -> #REF! | G13: =GZTKH!#REF! -> #REF! | H13: =SZBAY!#REF! -> #REF! | I13: =SZLH!#REF! -> #REF! | J13: =CDIFS!D39+CDTKL!E26+CDSKP!E26 -> 23142583 | K13: =CDIFS!E39+CDTKL!#REF!+CDSKP!#REF! -> #REF! | L13: =GZTKH!E26 -> 13500000 | M13: =GZTKH!#REF! -> #REF! | N13: =SZBAY!E26+SZLH!E26 -> 22290000 | O13: =SZBAY!#REF!+SZLH!#REF! -> #REF! | P13: =J13/K13-1 -> #REF! | Q13: =L13/M13-1 -> #REF! | R13: =N13/O13-1 -> #REF! | S13: =South!F39 -> -0.17264379 | T13: 已填写公式 | W13: VCA | X13: =CDIFS!F6 -> -0.29470421 | Y13: =CDTKL!#REF! -> #REF! | Z13: =CDSKP!#REF! -> #REF! | AA13: =GZTKH!#REF! -> #REF! | AB13: =SZBAY!#REF! -> #REF! | AC13: =SZLH!#REF! -> #REF! | AD13: =SUM(CDIFS!D6,CDTKL!#REF!,CDSKP!#REF!) -> #REF! | AE13: =SUM(CDIFS!E6,CDTKL!#REF!,CDSKP!#REF!) -> #REF! | AF13: =GZTKH!#REF! -> #REF! | AG13: =GZTKH!#REF! -> #REF! | AH13: =SUM(SZBAY!#REF!,SZLH!#REF!) -> #REF! | AI13: =SUM(SZBAY!#REF!,SZLH!#REF!) -> #REF! | AJ13: =AD13/AE13-1 -> #REF! | AK13: =AA13 -> #REF! | AL13: =AH13/AI13-1 -> #REF! | AM13: =South!F6 -> 0.0086451052 | AN13: 已填写公式
C14: Mix% | D14: =CDIFS!G39 -> 0.064594711 | E14: =CDTKL!#REF! -> #REF! | F14: =CDSKP!#REF! -> #REF! | G14: =GZTKH!#REF! -> #REF! | H14: =SZBAY!#REF! -> #REF! | I14: =SZLH!#REF! -> #REF! | J14: =J6/J13 -> 0.17295694 | K14: =K6/K13 -> #REF! | L14: =L6/L13 -> 0.11056431 | M14: =M6/M13 -> #REF! | N14: =N6/N13 -> 0.30363362 | O14: =O6/O13 -> #REF! | P14: =J14 -> 0.17295694 | Q14: =L14 -> 0.11056431 | R14: =N14 -> 0.30363362 | S14: =South!G39 -> 0.20809001 | T14: 已填写公式 | W14: Mix% | X14: =CDIFS!G6 -> 0.14770778 | Y14: =CDTKL!#REF! -> #REF! | Z14: =CDSKP!#REF! -> #REF! | AA14: =GZTKH!#REF! -> #REF! | AB14: =SZBAY!#REF! -> #REF! | AC14: =SZLH!#REF! -> #REF! | AD14: =AD6/AD13 -> #REF! | AE14: =AE6/AE13 -> #REF! | AF14: =AF6/AF13 -> #REF! | AG14: =AG6/AG13 -> #REF! | AH14: =AH6/AH13 -> #REF! | AI14: =AI6/AI13 -> #REF! | AJ14: =AD14 -> #REF! | AK14: =AF14 -> #REF! | AL14: =AH14 -> #REF! | AM14: =South!G6 -> 0.24509155 | AN14: 已填写公式
C15: TTL | D15: =CDIFS!F40 -> -0.30693814 | E15: =CDTKL!#REF! -> #REF! | F15: =CDSKP!#REF! -> #REF! | G15: =GZTKH!#REF! -> #REF! | H15: =SZBAY!#REF! -> #REF! | I15: =SZLH!#REF! -> #REF! | J15: =SUM(J6+J7+J9+J11+J13) -> 74188543 | K15: =SUM(K6+K7+K9+K11+K13) -> #REF! | L15: =SUM(L6+L7+L9+L11+L13) -> 59792618 | M15: =SUM(M6+M7+M9+M11+M13) -> #REF! | N15: =SUM(N6+N7+N9+N11+N13) -> 78317993 | O15: =SUM(O6+O7+O9+O11+O13) -> #REF! | P15: =J15/K15-1 -> #REF! | Q15: =L15/M15-1 -> #REF! | R15: =N15/O15-1 -> #REF! | S15: =South!F40 -> -0.10128624 | T15: 已填写公式 | W15: TTL | X15: =CDIFS!F7 -> -0.20415204 | Y15: =CDTKL!#REF! -> #REF! | Z15: =CDSKP!#REF! -> #REF! | AA15: =GZTKH!#REF! -> #REF! | AB15: =SZBAY!#REF! -> #REF! | AC15: =SZLH!#REF! -> #REF! | AD15: =SUM(AD6+AD7+AD9+AD11+AD13) -> #REF! | AE15: =SUM(AE6+AE7+AE9+AE11+AE13) -> #REF! | AF15: =SUM(AF6+AF7+AF9+AF11+AF13) -> #REF! | AG15: =SUM(AG6+AG7+AG9+AG11+AG13) -> #REF! | AH15: =SUM(AH6+AH7+AH9+AH11+AH13) -> #REF! | AI15: =SUM(AI6+AI7+AI9+AI11+AI13) -> #REF! | AJ15: =AD15/AE15-1 -> #REF! | AK15: =AA15 -> #REF! | AL15: =AH15/AI15-1 -> #REF! | AM15: =South!F7 -> -0.038677664 | AN15: 已填写公式
C16: Mix% | D16: =CDIFS!G40 -> 0.039186025 | E16: =CDTKL!#REF! -> #REF! | F16: =CDSKP!#REF! -> #REF! | G16: =GZTKH!#REF! -> #REF! | H16: =SZBAY!#REF! -> #REF! | I16: =SZLH!#REF! -> #REF! | J16: =J6/J15 -> 0.053952675 | K16: =K6/K15 -> #REF! | L16: =L6/L15 -> 0.024963251 | M16: =M6/M15 -> #REF! | N16: =N6/N15 -> 0.086416838 | O16: =O6/O15 -> #REF! | P16: =J16-K16 -> #REF! | Q16: =L16-M16 -> #REF! | R16: =N16-O16 -> #REF! | S16: =South!I40 -> -0.013259289 | T16: 已填写公式 | W16: Mix% | X16: =CDIFS!G7 -> 0.080815116 | Y16: =CDTKL!#REF! -> #REF! | Z16: =CDSKP!#REF! -> #REF! | AA16: =GZTKH!#REF! -> #REF! | AB16: =SZBAY!#REF! -> #REF! | AC16: =SZLH!#REF! -> #REF! | AD16: =AD6/AD15 -> #REF! | AE16: =AE6/AE15 -> #REF! | AF16: =AF6/AF15 -> #REF! | AG16: =AG6/AG15 -> #REF! | AH16: =AH6/AH15 -> #REF! | AI16: =AI6/AI15 -> #REF! | AJ16: =AD16-AE16 -> #REF! | AK16: =AF16-AG16 -> #REF! | AL16: =AH16-AI16 -> #REF! | AM16: =South!I7 -> -0.0015696653 | AN16: 已填写公式
C18: Mix % explanation | D18: By Brand Mix % is 2025
D19: Total Brand Mix % is 2025 vs LY.
B26: MTD Chaumet vs Competitor | J26: MTD
C27: 2025 Mar Mix | D27: STORE | P27: CITY | S27: REGION | W27: 2025 YTD MIX | X27: STORE | AJ27: CITY | AM27: REGION | AN27: 已填写公式
D28: CDIFS | E28: CDTKL | F28: CDSKP | G28: GZTKH | H28: SZBAY | I28: SZLH | J28: CD MIX | K28: CD 2024 | L28: GZTKH | M28: GZ 2024 | N28: SZ MIX | O28: SZ 2024 | P28: CD | Q28: GZ | R28: SZ | S28: SOUTH | X28: CDIFS | Y28: CDTKL | Z28: CDSKP | AA28: GZTKH | AB28: SZBAY | AC28: SZLH | AD28: CD YTD | AE28: CD LY | AF28: GZ YTD | AG28: GZ LY | AH28: SZ YTD | AI28: SZ LY | AJ28: CD | AK28: GZ | AL28: SZ | AM28: SOUTH | AN28: 已填写公式
C29: Chaumet | T29: 已填写公式 | W29: Chaumet | AN29: 已填写公式
C30: vs Cartier | D30: =CDIFS!G30 | E30: =CDTKL!#REF! -> #REF! | F30: =CDSKP!#REF! -> #REF! | G30: =GZTKH!#REF! -> #REF! | H30: =SZBAY!#REF! -> #REF! | I30: =SZLH!#REF! -> #REF! | T30: 已填写公式 | W30: vs Cartier | AN30: 已填写公式
C31: vs Bulgari | D31: =CDIFS!G31 -> 0.24589052 | E31: =CDTKL!#REF! -> #REF! | F31: =CDSKP!#REF! -> #REF! | G31: =GZTKH!#REF! -> #REF! | H31: =SZBAY!#REF! -> #REF! | I31: =SZLH!#REF! -> #REF! | T31: 已填写公式 | W31: vs Bulgari | AN31: 已填写公式
C32: vs Tiffany | D32: =CDIFS!G32 -> 0.8098806 | E32: =CDTKL!#REF! -> #REF! | F32: =CDSKP!#REF! -> #REF! | G32: =GZTKH!#REF! -> #REF! | H32: =SZBAY!#REF! -> #REF! | I32: =SZLH!#REF! -> #REF! | T32: 已填写公式 | W32: vs Tiffany | AN32: 已填写公式
C33: vs VCA | D33: =CDIFS!G33 -> 0.11041123 | E33: =CDTKL!#REF! -> #REF! | F33: =CDSKP!#REF! -> #REF! | G33: =GZTKH!#REF! -> #REF! | H33: =SZBAY!#REF! -> #REF! | I33: =SZLH!#REF! -> #REF! | T33: 已填写公式 | W33: vs VCA | AN33: 已填写公式
C34: TTL | D34: =CDIFS!G34 -> 0.065109887 | E34: =CDTKL!#REF! -> #REF! | F34: =CDSKP!#REF! -> #REF! | G34: =GZTKH!#REF! -> #REF! | H34: =SZBAY!#REF! -> #REF! | I34: =SZLH!#REF! -> #REF! | T34: 已填写公式 | W34: TTL | AN34: 已填写公式
W41: 2024 YTD RATIO | X41: STORE | AJ41: CITY | AM41: REGION | AN41: 已填写公式
X42: CDIFS | Y42: CDTKL | Z42: CDSKP | AA42: GZTKH | AB42: SZBAY | AC42: SZLH | AJ42: CD | AK42: GZ | AL42: SZ | AM42: SOUTH | AN42: 已填写公式
W43: Chaumet | AN43: 已填写公式
W44: Cartier | X44: =CDIFS!H3 | Y44: =CDTKL!#REF! -> #REF! | Z44: =CDSKP!#REF! -> #REF! | AA44: =GZTKH!#REF! -> #REF! | AB44: =SZBAY!#REF! -> #REF! | AC44: =SZLH!#REF! -> #REF! | AJ44: =$AE$6/AE7 -> #REF! | AK44: =AA44 -> #REF! | AL44: =$AI$6/AI7 -> #REF! | AM44: =#REF! -> #REF! | AN44: 已填写公式
W45: Bulgari | X45: =CDIFS!H4 -> 0.15692593 | Y45: =CDTKL!#REF! -> #REF! | Z45: =CDSKP!#REF! -> #REF! | AA45: =GZTKH!#REF! -> #REF! | AB45: =SZBAY!#REF! -> #REF! | AC45: =SZLH!#REF! -> #REF! | AJ45: =$AE$6/AE9 -> #REF! | AK45: =AA45 -> #REF! | AL45: =$AI$6/AI9 -> #REF! | AM45: =#REF! -> #REF! | AN45: 已填写公式
W46: Tiffany | X46: =CDIFS!H5 | Y46: =CDTKL!#REF! -> #REF! | Z46: =CDSKP!#REF! -> #REF! | AA46: =GZTKH!#REF! -> #REF! | AB46: =SZBAY!#REF! -> #REF! | AC46: =SZLH!#REF! -> #REF! | AJ46: =$AE$6/AE11 -> #REF! | AK46: =AA46 -> #REF! | AL46: =$AI$6/AI11 -> #REF! | AM46: =#REF! -> #REF! | AN46: 已填写公式
W47: VCA | X47: =CDIFS!H6 -> 0.084065159 | Y47: =CDTKL!#REF! -> #REF! | Z47: =CDSKP!#REF! -> #REF! | AA47: =GZTKH!#REF! -> #REF! | AB47: =SZBAY!#REF! -> #REF! | AC47: =SZLH!#REF! -> #REF! | AJ47: =$AE$6/AE13 -> #REF! | AK47: =AA47 -> #REF! | AL47: =$AI$6/AI13 -> #REF! | AM47: =#REF! -> #REF! | AN47: 已填写公式
W48: TTL | X48: =CDIFS!H7 -> 0.05189961 | Y48: =CDTKL!#REF! -> #REF! | Z48: =CDSKP!#REF! -> #REF! | AA48: =GZTKH!#REF! -> #REF! | AB48: =SZBAY!#REF! -> #REF! | AC48: =SZLH!#REF! -> #REF! | AJ48: =$AE$6/AE15 -> #REF! | AK48: =AA48 -> #REF! | AL48: =$AI$6/AI15 -> #REF! | AM48: =#REF! -> #REF! | AN48: 已填写公式

Sheet South
B1: Brand | C1: YTD | D1: 2025 Sales | E1: 2024 Sales | F1: 25 vs24 | G1: 2025 YTD Mix | H1: 2024 YTD Mix | I1: Market share gaining
B2: Chaumet | D2: =SUM(D11,D17,D23,D29,D35,D41,D47,D53,D59,D65,D71,D77) -> 66396756 | E2: =SUMIFS($E$11:$E$82,$D$11:$D$82,">0",$B$11:$B$82,B2) -> 70717880 | F2: =D2/E2-1 -> -0.061103692 | M2: 已填写公式
B3: Cartier | D3: =SUM(D12,D18,D24,D30,D36,D42,D48,D54,D60,D66,D72,D78,) -> 375560000 | E3: =SUMIFS($E$11:$E$82,$D$11:$D$82,">0",$B$11:$B$82,B3) -> 408056800 | F3: =D3/E3-1 -> -0.079637933 | G3: =IFERROR($D$2/$D3,"") -> 0.176794 | H3: =IFERROR($E$2/$E3,"") -> 0.17330401 | I3: =G3-H3 -> 0.0034899942 | M3: 已填写公式
B4: Bulgari | D4: =SUM(D13,D19,D25,D31,D37,D43,D49,D55,D61,D67,D73,D79,) -> 159043503 | E4: =SUMIFS($E$11:$E$82,$D$11:$D$82,">0",$B$11:$B$82,B4) -> 161060000 | F4: =D4/E4-1 -> -0.01252016 | G4: =IFERROR($D$2/$D4,"") -> 0.41747544 | H4: =IFERROR($E$2/$E4,"") -> 0.43907786 | I4: =G4-H4 -> -0.021602419 | M4: 已填写公式
B5: Tiffany | D5: =SUM(D14,D20,D26,D32,D38,D44,D50,D56,D62,D68,D74,D80,) -> 138450000 | E5: =SUMIFS($E$11:$E$82,$D$11:$D$82,">0",$B$11:$B$82,B5) -> 142588000 | F5: =D5/E5-1 -> -0.029020675 | G5: =IFERROR($D$2/$D5,"") -> 0.47957209 | H5: =IFERROR($E$2/$E5,"") -> 0.49595955 | I5: =G5-H5 -> -0.016387453 | M5: 已填写公式
B6: VCA | D6: =SUM(D15,D21,D27,D33,D39,D45,D51,D57,D63,D69,D75,D81,) -> 2.7090594e+08 | E6: =SUMIFS($E$11:$E$82,$D$11:$D$82,">0",$B$11:$B$82,B6) -> 268584000 | F6: =D6/E6-1 -> 0.0086451052 | G6: =IFERROR($D$2/$D6,"") -> 0.24509155 | H6: =IFERROR($E$2/$E6,"") -> 0.26329893 | I6: =G6-H6 -> -0.018207379 | M6: 已填写公式
B7: TTL | D7: =SUM(D16,D22,D28,D34,D40,D46,D52,D58,D64,D70,D76,D82,) -> 1.0103562e+09 | E7: =SUMIFS($E$11:$E$82,$D$11:$D$82,">0",$B$11:$B$82,B7) -> 1.0510067e+09 | F7: =D7/E7-1 -> -0.038677664 | G7: =IFERROR($D$2/$D7,"") -> 0.065716186 | H7: =IFERROR($E$2/$E7,"") -> 0.067285852 | I7: =G7-H7 -> -0.0015696653 | M7: 已填写公式
D9: 每月更新
B10: Brand | C10: MTD | D10: 2025 Sales Value (w/o VAT) | E10: 2024 Sales Value (w/o VAT) | F10: 25 vs24 | G10: 2025 MTD Mix vs Competitor | H10: 2024 MTD Mix vs Competitor | I10: Market share gaining | J10: Commercial Area | K10: Opening Date | L10: Productivity
B11: Chaumet | C11: Jan | D11: =SUM([1]CDIFS!D11,[1]CDTKL!D11,[1]CDSKP!D11,[1]SZLH!D11,[1]SZBAY!D11,[1]GZTKH!D11) -> 10006431 | E11: =SUM([1]CDIFS!E11,[1]CDTKL!E11,[1]CDSKP!E11,[1]SZLH!E11,[1]SZBAY!E11,[1]GZTKH!E11) -> 13486428 | F11: =D11/E11-1 -> -0.25803698 | M11: 已填写公式
B12: Cartier | C12: Jan | D12: =SUM([1]CDIFS!D12,[1]CDTKL!D12,[1]CDSKP!D12,[1]SZLH!D12,[1]SZBAY!D12,[1]GZTKH!D12) -> 77400000 | E12: =SUM([1]CDIFS!E12,[1]CDTKL!E12,[1]CDSKP!E12,[1]SZLH!E12,[1]SZBAY!E12,[1]GZTKH!E12) -> 81030000 | F12: =D12/E12-1 -> -0.044798223 | G12: =IFERROR($D$11/D12,"") -> 0.12928205 | H12: =IFERROR($E$11/E12,"") -> 0.16643747 | I12: =IFERROR(G12-H12,"") -> -0.037155416 | M12: 已填写公式
B13: Bulgari | C13: Jan | D13: =SUM([1]CDIFS!D13,[1]CDTKL!D13,[1]CDSKP!D13,[1]SZLH!D13,[1]SZBAY!D13,[1]GZTKH!D13) -> 39420000 | E13: =SUM([1]CDIFS!E13,[1]CDTKL!E13,[1]CDSKP!E13,[1]SZLH!E13,[1]SZBAY!E13,[1]GZTKH!E13) -> 31200000 | F13: =D13/E13-1 -> 0.26346154 | G13: =IFERROR($D$11/D13,"") -> 0.25384148 | H13: =IFERROR($E$11/E13,"") -> 0.43225731 | I13: =IFERROR(G13-H13,"") -> -0.17841584 | M13: 已填写公式
B14: Tiffany | C14: Jan | D14: =SUM([1]CDIFS!D14,[1]CDTKL!D14,[1]CDSKP!D14,[1]SZLH!D14,[1]SZBAY!D14,[1]GZTKH!D14) -> 27010000 | E14: =SUM([1]CDIFS!E14,[1]CDTKL!E14,[1]CDSKP!E14,[1]SZLH!E14,[1]SZBAY!E14,[1]GZTKH!E14) -> 25080000 | F14: =D14/E14-1 -> 0.076953748 | G14: =IFERROR($D$11/D14,"") -> 0.37047134 | H14: =IFERROR($E$11/E14,"") -> 0.53773637 | I14: =IFERROR(G14-H14,"") -> -0.16726503 | M14: 已填写公式
B15: VCA | C15: Jan | D15: =SUM([1]CDIFS!D15,[1]CDTKL!D15,[1]CDSKP!D15,[1]SZLH!D15,[1]SZBAY!D15,[1]GZTKH!D15) -> 62501188 | E15: =SUM([1]CDIFS!E15,[1]CDTKL!E15,[1]CDSKP!E15,[1]SZLH!E15,[1]SZBAY!E15,[1]GZTKH!E15) -> 47056000 | F15: =D15/E15-1 -> 0.32822994 | G15: =IFERROR($D$11/D15,"") -> 0.16009985 | H15: =IFERROR($E$11/E15,"") -> 0.2866038 | I15: =IFERROR(G15-H15,"") -> -0.12650394 | M15: 已填写公式
B16: TTL | C16: Jan | D16: =SUM(D11:D15) -> 2.1633762e+08 | E16: =SUM(E11:E15) -> 1.9785243e+08 | F16: =D16/E16-1 -> 0.093429183 | G16: =IFERROR($D$11/D16,"") -> 0.046253772 | H16: =IFERROR($E$11/E16,"") -> 0.068164077 | I16: =IFERROR(G16-H16,"") -> -0.021910305 | M16: 已填写公式
B17: Chaumet | C17: Feb | D17: =SUM([1]CDIFS!D17,[1]CDTKL!D17,[1]CDSKP!D17,[1]SZLH!D17,[1]SZBAY!D17,[1]GZTKH!D17) -> 12760231 | E17: =SUM([1]CDIFS!E17,[1]CDTKL!E17,[1]CDSKP!E17,[1]SZLH!E17,[1]SZBAY!E17,[1]GZTKH!E17) -> 12204216 | F17: =D17/E17-1 -> 0.045559174 | M17: 已填写公式
B18: Cartier | C18: Feb | D18: =SUM([1]CDIFS!D18,[1]CDTKL!D18,[1]CDSKP!D18,[1]SZLH!D18,[1]SZBAY!D18,[1]GZTKH!D18) -> 66410000 | E18: =SUM([1]CDIFS!E18,[1]CDTKL!E18,[1]CDSKP!E18,[1]SZLH!E18,[1]SZBAY!E18,[1]GZTKH!E18) -> 83630000 | F18: =D18/E18-1 -> -0.20590697 | G18: =IFERROR($D$11/D18,"") -> 0.15067657 | H18: =IFERROR($E$17/E18,"") -> 0.14593108 | I18: =IFERROR(G18-H18,"") -> 0.0047454862 | M18: 已填写公式
B19: Bulgari | C19: Feb | D19: =SUM([1]CDIFS!D19,[1]CDTKL!D19,[1]CDSKP!D19,[1]SZLH!D19,[1]SZBAY!D19,[1]GZTKH!D19) -> 32555342 | E19: =SUM([1]CDIFS!E19,[1]CDTKL!E19,[1]CDSKP!E19,[1]SZLH!E19,[1]SZBAY!E19,[1]GZTKH!E19) -> 32050000 | F19: =D19/E19-1 -> 0.015767301 | G19: =IFERROR($D$17/$D19,"") -> 0.39195504 | H19: =IFERROR($E$17/E19,"") -> 0.38078679 | I19: =IFERROR(G19-H19,"") -> 0.011168258 | M19: 已填写公式
B20: Tiffany | C20: Feb | D20: =SUM([1]CDIFS!D20,[1]CDTKL!D20,[1]CDSKP!D20,[1]SZLH!D20,[1]SZBAY!D20,[1]GZTKH!D20) -> 25785000 | E20: =SUM([1]CDIFS!E20,[1]CDTKL!E20,[1]CDSKP!E20,[1]SZLH!E20,[1]SZBAY!E20,[1]GZTKH!E20) -> 31660000 | F20: =D20/E20-1 -> -0.18556538 | G20: =IFERROR($D$17/$D20,"") -> 0.49487029 | H20: =IFERROR($E$17/E20,"") -> 0.38547746 | I20: =IFERROR(G20-H20,"") -> 0.10939283 | M20: 已填写公式
B21: VCA | C21: Feb | D21: =SUM([1]CDIFS!D21,[1]CDTKL!D21,[1]CDSKP!D21,[1]SZLH!D21,[1]SZBAY!D21,[1]GZTKH!D21) -> 47400931 | E21: =SUM([1]CDIFS!E21,[1]CDTKL!E21,[1]CDSKP!E21,[1]SZLH!E21,[1]SZBAY!E21,[1]GZTKH!E21) -> 54776000 | F21: =D21/E21-1 -> -0.13464052 | G21: =IFERROR($D$17/$D21,"") -> 0.26919789 | H21: =IFERROR($E$17/E21,"") -> 0.22280226 | I21: =IFERROR(G21-H21,"") -> 0.04639563 | M21: 已填写公式
B22: TTL | C22: Feb | D22: =SUM(D17:D21) -> 1.849115e+08 | E22: =SUM(E17:E21) -> 2.1432022e+08 | F22: =D22/E22-1 -> -0.13721857 | G22: =IFERROR($D$17/$D22,"") -> 0.069007229 | H22: =IFERROR($E$17/E22,"") -> 0.056943842 | I22: =IFERROR(G22-H22,"") -> 0.012063387 | M22: 已填写公式
B23: Chaumet | C23: Mar | D23: =SUM([1]CDIFS!D23,[1]CDTKL!D23,[1]CDSKP!D23,[1]SZLH!D23,[1]SZBAY!D23,[1]GZTKH!D23) -> 12189500 | E23: =SUM([1]CDIFS!E23,[1]CDTKL!E23,[1]CDSKP!E23,[1]SZLH!E23,[1]SZBAY!E23,[1]GZTKH!E23) -> 9095385.5 | F23: =D23/E23-1 -> 0.34018509 | M23: 已填写公式
B24: Cartier | C24: Mar | D24: =SUM([1]CDIFS!D24,[1]CDTKL!D24,[1]CDSKP!D24,[1]SZLH!D24,[1]SZBAY!D24,[1]GZTKH!D24) -> 71260000 | E24: =SUM([1]CDIFS!E24,[1]CDTKL!E24,[1]CDSKP!E24,[1]SZLH!E24,[1]SZBAY!E24,[1]GZTKH!E24) -> 79270000 | F24: =D24/E24-1 -> -0.10104705 | G24: =IFERROR($D$11/D24,"") -> 0.14042143 | H24: =IFERROR($E$23/E24,"") -> 0.11473932 | I24: =IFERROR(G24-H24,"") -> 0.025682113 | M24: 已填写公式
B25: Bulgari | C25: Mar | D25: =SUM([1]CDIFS!D25,[1]CDTKL!D25,[1]CDSKP!D25,[1]SZLH!D25,[1]SZBAY!D25,[1]GZTKH!D25) -> 27860475 | E25: =SUM([1]CDIFS!E25,[1]CDTKL!E25,[1]CDSKP!E25,[1]SZLH!E25,[1]SZBAY!E25,[1]GZTKH!E25) -> 32460000 | F25: =D25/E25-1 -> -0.14169824 | G25: =IFERROR($D$23/$D25,"") -> 0.43751946 | H25: =IFERROR($E$23/E25,"") -> 0.28020288 | I25: =IFERROR(G25-H25,"") -> 0.15731658 | M25: 已填写公式
B26: Tiffany | C26: Mar | D26: =SUM([1]CDIFS!D26,[1]CDTKL!D26,[1]CDSKP!D26,[1]SZLH!D26,[1]SZBAY!D26,[1]GZTKH!D26) -> 29407000 | E26: =SUM([1]CDIFS!E26,[1]CDTKL!E26,[1]CDSKP!E26,[1]SZLH!E26,[1]SZBAY!E26,[1]GZTKH!E26) -> 25440000 | F26: =D26/E26-1 -> 0.15593553 | G26: =IFERROR($D$23/$D26,"") -> 0.41451015 | H26: =IFERROR($E$23/E26,"") -> 0.35752302 | I26: =IFERROR(G26-H26,"") -> 0.056987137 | M26: 已填写公式
B27: VCA | C27: Mar | D27: =SUM([1]CDIFS!D27,[1]CDTKL!D27,[1]CDSKP!D27,[1]SZLH!D27,[1]SZBAY!D27,[1]GZTKH!D27) -> 46369080 | E27: =SUM([1]CDIFS!E27,[1]CDTKL!E27,[1]CDSKP!E27,[1]SZLH!E27,[1]SZBAY!E27,[1]GZTKH!E27) -> 49470000 | F27: =D27/E27-1 -> -0.062682839 | G27: =IFERROR($D$23/$D27,"") -> 0.26287992 | H27: =IFERROR($E$23/E27,"") -> 0.18385659 | I27: =IFERROR(G27-H27,"") -> 0.07902333 | M27: 已填写公式
B28: TTL | C28: Mar | D28: =SUM(D23:D27) -> 1.8708606e+08 | E28: =SUM(E23:E27) -> 1.9573539e+08 | F28: =D28/E28-1 -> -0.044188896 | G28: =IFERROR($D$23/$D28,"") -> 0.065154509 | H28: =IFERROR($E$23/E28,"") -> 0.046467763 | I28: =IFERROR(G28-H28,"") -> 0.018686746 | M28: 已填写公式
B29: Chaumet | C29: Apr | D29: =CDIFS!D29+CDTKL!E17+CDSKP!E17+GZTKH!E17+SZBAY!E17+SZLH!E17 -> 19177313 | E29: =SUM([1]CDIFS!E29,[1]CDTKL!E29,[1]CDSKP!E29,[1]SZLH!E29,[1]SZBAY!E29,[1]GZTKH!E29) -> 19154297 | F29: =D29/E29-1 -> 0.0012016179 | M29: 已填写公式
B30: Cartier | C30: Apr | D30: =CDIFS!D30+CDTKL!E18+CDSKP!E18+GZTKH!E18+SZBAY!E18+SZLH!E18 -> 72440000 | E30: =SUM([1]CDIFS!E30,[1]CDTKL!E30,[1]CDSKP!E30,[1]SZLH!E30,[1]SZBAY!E30,[1]GZTKH!E30) -> 75306800 | F30: =D30/E30-1 -> -0.038068275 | G30: =IFERROR($D$11/D30,"") -> 0.13813406 | H30: =IFERROR($E$29/E30,"") -> 0.25435016 | I30: =IFERROR(G30-H30,"") -> -0.1162161 | M30: 已填写公式
B31: Bulgari | C31: Apr | D31: =CDIFS!D31+CDTKL!E19+CDSKP!E19+GZTKH!E19+SZBAY!E19+SZLH!E19 -> 31522396 | E31: =SUM([1]CDIFS!E31,[1]CDTKL!E31,[1]CDSKP!E31,[1]SZLH!E31,[1]SZBAY!E31,[1]GZTKH!E31) -> 33690000 | F31: =D31/E31-1 -> -0.064339685 | G31: =IFERROR($D$29/$D31,"") -> 0.60837104 | H31: =IFERROR($E$29/E31,"") -> 0.56854546 | I31: =IFERROR(G31-H31,"") -> 0.039825575 | M31: 已填写公式
B32: Tiffany | C32: Apr | D32: =CDIFS!D32+CDTKL!E20+CDSKP!E20+GZTKH!E20+SZBAY!E20+SZLH!E20 -> 30880000 | E32: =SUM([1]CDIFS!E32,[1]CDTKL!E32,[1]CDSKP!E32,[1]SZLH!E32,[1]SZBAY!E32,[1]GZTKH!E32) -> 32670000 | F32: =D32/E32-1 -> -0.054790328 | G32: =IFERROR($D$29/$D32,"") -> 0.62102697 | H32: =IFERROR($E$29/E32,"") -> 0.58629619 | I32: =IFERROR(G32-H32,"") -> 0.034730775 | M32: 已填写公式
B33: VCA | C33: Apr | D33: =CDIFS!D33+CDTKL!E21+CDSKP!E21+GZTKH!E21+SZBAY!E21+SZLH!E21 -> 55702155 | E33: =SUM([1]CDIFS!E33,[1]CDTKL!E33,[1]CDSKP!E33,[1]SZLH!E33,[1]SZBAY!E33,[1]GZTKH!E33) -> 46052000 | F33: =D33/E33-1 -> 0.2095491 | G33: =IFERROR($D$29/$D33,"") -> 0.34428314 | H33: =IFERROR($E$29/E33,"") -> 0.41592757 | I33: =IFERROR(G33-H33,"") -> -0.071644434 | M33: 已填写公式
B34: TTL | C34: Apr | D34: =SUM(D29:D33) -> 2.0972186e+08 | E34: =SUM(E29:E33) -> 2.068731e+08 | F34: =D34/E34-1 -> 0.013770602 | G34: =IFERROR($D$29/$D34,"") -> 0.091441647 | H34: =IFERROR($E$29/E34,"") -> 0.092589597 | I34: =IFERROR(G34-H34,"") -> -0.0011479492 | M34: 已填写公式
B35: Chaumet | C35: May | D35: =CDIFS!D35+CDTKL!E22+CDSKP!E22+GZTKH!E22+SZBAY!E22+SZLH!E22 -> 12263282 | E35: =SUM([1]CDIFS!E35,[1]CDTKL!E35,[1]CDSKP!E35,[1]SZLH!E35,[1]SZBAY!E35,[1]GZTKH!E35) -> 16777553 | F35: =D35/E35-1 -> -0.26906612 | M35: 已填写公式
B36: Cartier | C36: May | D36: =CDIFS!D36+CDTKL!E23+CDSKP!E23+GZTKH!E23+SZBAY!E23+SZLH!E23 -> 88050000 | E36: =SUM([1]CDIFS!E36,[1]CDTKL!E36,[1]CDSKP!E36,[1]SZLH!E36,[1]SZBAY!E36,[1]GZTKH!E36) -> 88820000 | F36: =D36/E36-1 -> -0.0086692186 | G36: =IFERROR($D$35/D36,"") -> 0.13927634 | H36: =IFERROR($E$35/E36,"") -> 0.18889386 | I36: =IFERROR(G36-H36,"") -> -0.049617521 | M36: 已填写公式
B37: Bulgari | C37: May | D37: =CDIFS!D37+CDTKL!E24+CDSKP!E24+GZTKH!E24+SZBAY!E24+SZLH!E24 -> 27685290 | E37: =SUM([1]CDIFS!E37,[1]CDTKL!E37,[1]CDSKP!E37,[1]SZLH!E37,[1]SZBAY!E37,[1]GZTKH!E37) -> 31660000 | F37: =D37/E37-1 -> -0.12554359 | G37: =IFERROR($D$35/D37,"") -> 0.44295299 | H37: =IFERROR($E$35/E37,"") -> 0.52992902 | I37: =IFERROR(G37-H37,"") -> -0.086976037 | M37: 已填写公式
B38: Tiffany | C38: May | D38: =CDIFS!D38+CDTKL!E25+CDSKP!E25+GZTKH!E25+SZBAY!E25+SZLH!E25 -> 25368000 | E38: =SUM([1]CDIFS!E38,[1]CDTKL!E38,[1]CDSKP!E38,[1]SZLH!E38,[1]SZBAY!E38,[1]GZTKH!E38) -> 27738000 | F38: =D38/E38-1 -> -0.085442353 | G38: =IFERROR($D$35/D38,"") -> 0.4834154 | H38: =IFERROR($E$35/E38,"") -> 0.60485806 | I38: =IFERROR(G38-H38,"") -> -0.12144266 | M38: 已填写公式
B39: VCA | C39: May | D39: =CDIFS!D39+CDTKL!E26+CDSKP!E26+GZTKH!E26+SZBAY!E26+SZLH!E26 -> 58932583 | E39: =SUM([1]CDIFS!E39,[1]CDTKL!E39,[1]CDSKP!E39,[1]SZLH!E39,[1]SZBAY!E39,[1]GZTKH!E39) -> 71230000 | F39: =D39/E39-1 -> -0.17264379 | G39: =IFERROR($D$35/D39,"") -> 0.20809001 | H39: =IFERROR($E$35/E39,"") -> 0.23554054 | I39: =IFERROR(G39-H39,"") -> -0.027450531 | M39: 已填写公式
B40: TTL | C40: May | D40: =SUM(D35:D39) -> 2.1229915e+08 | E40: =SUM(E35:E39) -> 2.3622555e+08 | F40: =D40/E40-1 -> -0.10128624 | G40: =IFERROR($D$35/D40,"") -> 0.057764158 | H40: =IFERROR($E$35/E40,"") -> 0.071023446 | I40: =IFERROR(G40-H40,"") -> -0.013259289 | M40: 已填写公式
B41: Chaumet | C41: Jun | D41: =SUM([1]CDIFS!D41,[1]CDTKL!D41,[1]CDSKP!D41,[1]SZLH!D41,[1]SZBAY!D41,[1]GZTKH!D41) -> 0 | E41: =SUM([1]CDIFS!E41,[1]CDTKL!E41,[1]CDSKP!E41,[1]SZLH!E41,[1]SZBAY!E41,[1]GZTKH!E41) -> 9730646.8 | F41: =D41/E41-1 -> -1 | M41: 已填写公式
...

Sheet CDIFS
B1: Brand | C1: YTD | D1: 2025 Sales | E1: 2024 Sales | F1: 25 vs24 | G1: 2025 YTD Mix | H1: 2024 YTD Mix | I1: Market share gaining
B2: Chaumet | D2: =SUM(D11,D17,D23,D29,D35,D41,D47,D53,D59,D65,D71,D77,) -> 7596010.8 | E2: =SUMIFS($E$11:$E$82,$D$11:$D$82,">0",$B$11:$B$82,B2) -> 6129527 | F2: =D2/E2-1 -> 0.2392491 | M2: 已填写公式
B3: Cartier | D3: =SUM(D12,D18,D24,D30,D36,D42,D48,D54,D60,D66,D72,D78,) -> 0 | E3: =SUMIFS($E$11:$E$82,$D$11:$D$82,">0",$B$11:$B$82,B3) -> 0 | F3: =IFERROR(D3/E3-1,"") | G3: =IFERROR($D$2/$D3,"") | H3: =IFERROR($E$2/$E3,"") | I3: =IFERROR(G3-H3,"") | M3: 已填写公式
B4: Bulgari | D4: =SUM(D13,D19,D25,D31,D37,D43,D49,D55,D61,D67,D73,D79,) -> 28653503 | E4: =SUMIFS($E$11:$E$82,$D$11:$D$82,">0",$B$11:$B$82,B4) -> 39060000 | F4: =D4/E4-1 -> -0.26642337 | G4: =IFERROR($D$2/$D4,"") -> 0.26509885 | H4: =IFERROR($E$2/$E4,"") -> 0.15692593 | I4: =IFERROR(G4-H4,"") -> 0.10817292 | M4: 已填写公式
B5: Tiffany | D5: =SUM(D14,D20,D26,D32,D38,D44,D50,D56,D62,D68,D74,D80,) -> 6317000 | E5: =SUMIFS($E$11:$E$82,$D$11:$D$82,">0",$B$11:$B$82,B5) -> 0 | F5: =IFERROR(D5/E5-1,"") | G5: =IFERROR($D$2/$D5,"") -> 1.2024712 | H5: =IFERROR($E$2/$E5,"") | I5: =IFERROR(G5-H5,"") | M5: 已填写公式
B6: VCA | D6: =SUM(D15,D21,D27,D33,D39,D45,D51,D57,D63,D69,D75,D81,) -> 51425937 | E6: =SUMIFS($E$11:$E$82,$D$11:$D$82,">0",$B$11:$B$82,B6) -> 72914000 | F6: =D6/E6-1 -> -0.29470421 | G6: =IFERROR($D$2/$D6,"") -> 0.14770778 | H6: =IFERROR($E$2/$E6,"") -> 0.084065159 | I6: =IFERROR(G6-H6,"") -> 0.063642617 | M6: 已填写公式
B7: TTL | D7: =SUM(D16,D22,D28,D34,D40,D46,D52,D58,D64,D70,D76,D82,) -> 93992451 | E7: =SUMIFS($E$11:$E$82,$D$11:$D$82,">0",$B$11:$B$82,B7) -> 1.1810353e+08 | F7: =D7/E7-1 -> -0.20415204 | G7: =IFERROR($D$2/$D7,"") -> 0.080815116 | H7: =IFERROR($E$2/$E7,"") -> 0.05189961 | I7: =IFERROR(G7-H7,"") -> 0.028915506 | M7: 已填写公式
D9: 每月更新
B10: Brand | C10: MTD | D10: 2025 Sales Value (w/o VAT) | E10: 2024 Sales Value (w/o VAT) | F10: 25 vs 24 | G10: 2025 MTD Mix vs Competitor | H10: 2024 MTD Mix vs Competitor | I10: Market share gaining | J10: Commercial Area | K10: Opening Date | L10: Productivity
B11: Chaumet | C11: Jan | D11: 2942030 | E11: 1452550 | F11: =D11/E11-1 -> 1.0254243 | M11: 需每月更新
B12: Cartier | C12: Jan | D12: 0 | E12: 0 | F12: =IFERROR(D12/E12-1,"") | G12: =IFERROR($D$11/D12,"") | H12: =IFERROR($E$11/E12,"") | I12: =IFERROR(G12-H12,"")
B13: Bulgari | C13: Jan | D13: 8920000 | E13: 7660000 | F13: =IFERROR(D13/E13-1,"") -> 0.16449086 | G13: =IFERROR($D$11/D13,"") -> 0.32982399 | H13: =IFERROR($E$11/E13,"") -> 0.18962793 | I13: =IFERROR(G13-H13,"") -> 0.14019606
B14: Tiffany | C14: Jan | D14: 1590000 | E14: 0 | F14: =IFERROR(D14/E14-1,"") | G14: =IFERROR($D$11/D14,"") -> 1.8503333 | H14: =IFERROR($E$11/E14,"") | I14: =IFERROR(G14-H14,"")
B15: VCA | C15: Jan | D15: 14501188 | E15: 15056000 | F15: =IFERROR(D15/E15-1,"") -> -0.036849894 | G15: =IFERROR($D$11/D15,"") -> 0.202882 | H15: =IFERROR($E$11/E15,"") -> 0.096476485 | I15: =IFERROR(G15-H15,"") -> 0.10640551
B16: TTL | C16: Jan | D16: =SUM(D11:D15) -> 27953218 | E16: =SUM(E11:E15) -> 24168550 | F16: =IFERROR(D16/E16-1,"") -> 0.15659475 | G16: =IFERROR($D$11/D16,"") -> 0.10524835 | H16: =IFERROR($E$11/E16,"") -> 0.060100832 | I16: =IFERROR(G16-H16,"") -> 0.045147515
B17: Chaumet | C17: Feb | D17: 1996264.2 | E17: 1272293.8 | F17: =D17/E17-1 -> 0.56902763
B18: Cartier | C18: Feb | D18: 0 | E18: 0 | F18: =IFERROR(D18/E18-1,"") | G18: =IFERROR($D$11/D18,"") | H18: =IFERROR($E$17/E18,"") | I18: =IFERROR(G18-H18,"")
B19: Bulgari | C19: Feb | D19: 6425342 | E19: 10000000 | F19: =IFERROR(D19/E19-1,"") -> -0.3574658 | G19: =IFERROR($D$17/$D19,"") -> 0.31068605 | H19: =IFERROR($E$17/E19,"") -> 0.12722938 | I19: =IFERROR(G19-H19,"") -> 0.18345667
B20: Tiffany | C20: Feb | D20: 1320000 | E20: 0 | F20: =IFERROR(D20/E20-1,"") | G20: =IFERROR($D$17/$D20,"") -> 1.5123213 | H20: =IFERROR($E$17/E20,"") | I20: =IFERROR(G20-H20,"")
B21: VCA | C21: Feb | D21: 7830931 | E21: 16226000 | F21: =IFERROR(D21/E21-1,"") -> -0.51738377 | G21: =IFERROR($D$17/$D21,"") -> 0.25492041 | H21: =IFERROR($E$17/E21,"") -> 0.078410811 | I21: =IFERROR(G21-H21,"") -> 0.1765096
B22: TTL | C22: Feb | D22: =SUM(D17:D21) -> 17572537 | E22: =SUM(E17:E21) -> 27498294 | F22: =IFERROR(D22/E22-1,"") -> -0.360959 | G22: =IFERROR($D$17/$D22,"") -> 0.11360136 | H22: =IFERROR($E$17/E22,"") -> 0.0462681 | I22: =IFERROR(G22-H22,"") -> 0.067333262
B23: Chaumet | C23: Mar | D23: 958356.64 | E23: 946586.74 | F23: =D23/E23-1 -> 0.01243404
B24: Cartier | C24: Mar | D24: 0 | E24: 0 | F24: =IFERROR(D24/E24-1,"") | G24: =IFERROR($D$23/D24,"") | H24: =IFERROR($E$23/E24,"") | I24: =IFERROR(G24-H24,"")
B25: Bulgari | C25: Mar | D25: 4130475 | E25: 6700000 | F25: =IFERROR(D25/E25-1,"") -> -0.38351119 | G25: =IFERROR($D$23/$D25,"") -> 0.23202093 | H25: =IFERROR($E$23/E25,"") -> 0.1412816 | I25: =IFERROR(G25-H25,"") -> 0.090739324
B26: Tiffany | C26: Mar | D26: 857000 | E26: 0 | F26: =IFERROR(D26/E26-1,"") | G26: =IFERROR($D$23/$D26,"") -> 1.1182691 | H26: =IFERROR($E$23/E26,"") | I26: =IFERROR(G26-H26,"")
B27: VCA | C27: Mar | D27: 9029079.9 | E27: 12300000 | F27: =IFERROR(D27/E27-1,"") -> -0.26592846 | G27: =IFERROR($D$23/$D27,"") -> 0.10614112 | H27: =IFERROR($E$23/E27,"") -> 0.076958272 | I27: =IFERROR(G27-H27,"") -> 0.029182846
B28: TTL | C28: Mar | D28: =SUM(D23:D27) -> 14974912 | E28: =SUM(E23:E27) -> 19946587 | F28: =IFERROR(D28/E28-1,"") -> -0.24924942 | G28: =IFERROR($D$23/$D28,"") -> 0.063997482 | H28: =IFERROR($E$23/E28,"") -> 0.047456076 | I28: =IFERROR(G28-H28,"") -> 0.016541406
B29: Chaumet | C29: Apr | D29: 971856.72 | E29: 1370623 | F29: =D29/E29-1 -> -0.29093797
B30: Cartier | C30: Apr | D30: 0 | E30: 0 | F30: =IFERROR(D30/E30-1,"") | G30: =IFERROR($D$29/D30,"") | H30: =IFERROR($E$29/E30,"") | I30: =IFERROR(G30-H30,"")
B31: Bulgari | C31: Apr | D31: 3952396 | E31: 7500000 | F31: =IFERROR(D31/E31-1,"") -> -0.47301387 | G31: =IFERROR($D$29/$D31,"") -> 0.24589052 | H31: =IFERROR($E$29/E31,"") -> 0.18274973 | I31: =IFERROR(G31-H31,"") -> 0.063140792
B32: Tiffany | C32: Apr | D32: 1200000 | E32: 0 | F32: =IFERROR(D32/E32-1,"") | G32: =IFERROR($D$29/$D32,"") -> 0.8098806 | H32: =IFERROR($E$29/E32,"") | I32: =IFERROR(G32-H32,"")
B33: VCA | C33: Apr | D33: 8802155 | E33: 10832000 | F33: =IFERROR(D33/E33-1,"") -> -0.18739337 | G33: =IFERROR($D$29/$D33,"") -> 0.11041123 | H33: =IFERROR($E$29/E33,"") -> 0.12653462 | I33: =IFERROR(G33-H33,"") -> -0.016123393
B34: TTL | C34: Apr | D34: =SUM(D29:D33) -> 14926408 | E34: =SUM(E29:E33) -> 19702623 | F34: =IFERROR(D34/E34-1,"") -> -0.2424152 | G34: =IFERROR($D$29/$D34,"") -> 0.065109887 | H34: =IFERROR($E$29/E34,"") -> 0.069565508 | I34: =IFERROR(G34-H34,"") -> -0.0044556214
B35: Chaumet | C35: May | D35: 727503.29 | E35: 1087473.5 | F35: =D35/E35-1 -> -0.33101516
B36: Cartier | C36: May | E36: 0 | F36: =IFERROR(D36/E36-1,"") | G36: =IFERROR($D$35/D36,"") | H36: =IFERROR($E$35/E36,"") | I36: =IFERROR(G36-H36,"")
B37: Bulgari | C37: May | D37: 5225290 | E37: 7200000 | F37: =IFERROR(D37/E37-1,"") -> -0.27426528 | G37: =IFERROR($D$35/D37,"") -> 0.13922735 | H37: =IFERROR($E$35/E37,"") -> 0.15103799 | I37: =IFERROR(G37-H37,"") -> -0.011810635
B38: Tiffany | C38: May | D38: 1350000 | E38: 0 | F38: =IFERROR(D38/E38-1,"") | G38: =IFERROR($D$35/D38,"") -> 0.53889133 | H38: =IFERROR($E$35/E38,"") | I38: =IFERROR(G38-H38,"")
B39: VCA | C39: May | D39: 11262583 | E39: 18500000 | F39: =IFERROR(D39/E39-1,"") -> -0.39121173 | G39: =IFERROR($D$35/D39,"") -> 0.064594711 | H39: =IFERROR($E$35/E39,"") -> 0.058782352 | I39: =IFERROR(G39-H39,"") -> 0.005812359
B40: TTL | C40: May | D40: =SUM(D35:D39) -> 18565376 | E40: =SUM(E35:E39) -> 26787474 | F40: =IFERROR(D40/E40-1,"") -> -0.30693814 | G40: =IFERROR($D$35/D40,"") -> 0.039186025 | H40: =IFERROR($E$35/E40,"") -> 0.040596345 | I40: =IFERROR(G40-H40,"") -> -0.0014103201
B41: Chaumet | C41: Jun | E41: 1277523 | F41: =D41/E41-1 -> -1
...

Sheet CDTKL
B1: Date | C1: Mall | D1: Brand | E1: Sales
B2: 45292 | C2: CDTKL | D2: Chaumet | E2: 720453.06
B3: 45292 | C3: CDTKL | D3: Cartier | E3: 10000000
B4: 45292 | C4: CDTKL | D4: Bulgari
B5: 45292 | C5: CDTKL | D5: Tiffany | E5: 5000000
B6: 45292 | C6: CDTKL | D6: VCA
B7: 45323 | C7: CDTKL | D7: Chaumet | E7: 1444337
B8: 45323 | C8: CDTKL | D8: Cartier | E8: 24000000
B9: 45323 | C9: CDTKL | D9: Bulgari
B10: 45323 | C10: CDTKL | D10: Tiffany | E10: 6200000
B11: 45323 | C11: CDTKL | D11: VCA
B12: 45352 | C12: CDTKL | D12: Chaumet | E12: 586931.81
B13: 45352 | C13: CDTKL | D13: Cartier | E13: 16000000
B14: 45352 | C14: CDTKL | D14: Bulgari
B15: 45352 | C15: CDTKL | D15: Tiffany | E15: 4800000
B16: 45352 | C16: CDTKL | D16: VCA
B17: 45383 | C17: CDTKL | D17: Chaumet | E17: 1869885.9
B18: 45383 | C18: CDTKL | D18: Cartier | E18: 16500000
B19: 45383 | C19: CDTKL | D19: Bulgari
B20: 45383 | C20: CDTKL | D20: Tiffany | E20: 3100000
B21: 45383 | C21: CDTKL | D21: VCA
B22: 45413 | C22: CDTKL | D22: Chaumet | E22: 1361089.4
B23: 45413 | C23: CDTKL | D23: Cartier | E23: 19000000
B24: 45413 | C24: CDTKL | D24: Bulgari
B25: 45413 | C25: CDTKL | D25: Tiffany | E25: 5260000
B26: 45413 | C26: CDTKL | D26: VCA
B27: 45444 | C27: CDTKL | D27: Chaumet | E27: 654196.88
B28: 45444 | C28: CDTKL | D28: Cartier | E28: 14000000
B29: 45444 | C29: CDTKL | D29: Bulgari
B30: 45444 | C30: CDTKL | D30: Tiffany | E30: 2700000
B31: 45444 | C31: CDTKL | D31: VCA
B32: 45474 | C32: CDTKL | D32: Chaumet | E32: 1204558
B33: 45474 | C33: CDTKL | D33: Cartier | E33: 13500000
B34: 45474 | C34: CDTKL | D34: Bulgari
B35: 45474 | C35: CDTKL | D35: Tiffany | E35: 4000000
B36: 45474 | C36: CDTKL | D36: VCA
B37: 45505 | C37: CDTKL | D37: Chaumet | E37: 1643449.6
B38: 45505 | C38: CDTKL | D38: Cartier | E38: 22000000
B39: 45505 | C39: CDTKL | D39: Bulgari
B40: 45505 | C40: CDTKL | D40: Tiffany | E40: 5000000
...

Sheet CDSKP
B1: Date | C1: Mall | D1: Brand | E1: Sales
B2: 45292 | C2: CDSKP | D2: Chaumet | E2: 1675186
B3: 45292 | C3: CDSKP | D3: Cartier | E3: 11000000
B4: 45292 | C4: CDSKP | D4: Bulgari | E4: 2530000
B5: 45292 | C5: CDSKP | D5: Tiffany | E5: 4500000
B6: 45292 | C6: CDSKP | D6: VCA | E6: 5830000
B7: 45323 | C7: CDSKP | D7: Chaumet | E7: 3735375
B8: 45323 | C8: CDSKP | D8: Cartier | E8: 11200000
B9: 45323 | C9: CDSKP | D9: Bulgari | E9: 4070000
B10: 45323 | C10: CDSKP | D10: Tiffany | E10: 5200000
B11: 45323 | C11: CDSKP | D11: VCA | E11: 8710000
B12: 45352 | C12: CDSKP | D12: Chaumet | E12: 963022
B13: 45352 | C13: CDSKP | D13: Cartier | E13: 16000000
... B76: 45717 | C76: CDSKP | D76: VCA | E76: 7200000
B77: =B79 -> 45748 | C77: CDSKP | D77: Chaumet | E77: 6466059.4
B78: 45748 | C78: CDSKP | D78: Cartier | E78: 10000000
B79: 45748 | C79: CDSKP | D79: Bulgari | E79: 9300000
B80: 45748 | C80: CDSKP | D80: Tiffany | E80: 8000000
B81: 45748 | C81: CDSKP | D81: VCA | E81: 10000000
B82: 45778 | C82: CDSKP | D82: Chaumet | E82: 1834844.7
B83: 45778 | C83: CDSKP | D83: Cartier | E83: 10000000
B84: 45778 | C84: CDSKP | D84: Bulgari | E84: 3800000
B85: 45778 | C85: CDSKP | D85: Tiffany | E85: 3500000
B86: 45778 | C86: CDSKP | D86: VCA | E86: 9000000
B87: 45809 | C87: CDSKP | D87: Chaumet
B88: 45809 | C88: CDSKP | D88: Cartier
B89: 45809 | C89: CDSKP | D89: Bulgari
B90: 45809 | C90: CDSKP | D90: Tiffany
B91: 45809 | C91: CDSKP | D91: VCA
B92: 45839 | C92: CDSKP | D92: Chaumet
B93: 45839 | C93: CDSKP | D93: Cartier
B94: 45839 | C94: CDSKP | D94: Bulgari
B95: 45839 | C95: CDSKP | D95: Tiffany
B96: 45839 | C96: CDSKP | D96: VCA
B97: 45870 | C97: CDSKP | D97: Chaumet
B98: 45870 | C98: CDSKP | D98: Cartier
... B121: 45992 | C121: CDSKP | D121: VCA

Sheet GZTKH
B1: Date | C1: Mall | D1: Brand | E1: Sales
B2: 45658 | C2: GZTKH | D2: Chaumet | E2: 1159807
B3: 45658 | C3: GZTKH | D3: Cartier | E3: 26200000
B4: 45658 | C4: GZTKH | D4: Bulgari | E4: 13800000
B5: 45658 | C5: GZTKH | D5: Tiffany | E5: 6630000
B6: 45658 | C6: GZTKH | D6: VCA | E6: 21000000
B7: 45689 | C7: GZTKH | D7: Chaumet | E7: 1492626.6
B8: 45689 | C8: GZTKH | D8: Cartier | E8: 17000000
B9: 45689 | C9: GZTKH | D9: Bulgari | E9: 10700000
B10: 45689 | C10: GZTKH | D10: Tiffany | E10: 5965000
B11: 45689 | C11: GZTKH | D11: VCA | E11: 13500000
B12: 45717 | C12: GZTKH | D12: Chaumet | E12: 1669225.6
B13: 45717 | C13: GZTKH | D13: Cartier | E13: 22000000
... B16: 45717 | C16: GZTKH | D16: VCA | E16: 12300000
B17: =B19 -> 45748 | C17: GZTKH | D17: Chaumet | E17: 1359820.8
B18: 45748 | C18: GZTKH | D18: Cartier | E18: 20400000
B19: 45748 | C19: GZTKH | D19: Bulgari | E19: 6340000
B20: 45748 | C20: GZTKH | D20: Tiffany | E20: 4150000
B21: 45748 | C21: GZTKH | D21: VCA | E21: 14000000
B22: 45778 | C22: GZTKH | D22: Chaumet | E22: 1492618.1
B23: 45778 | C23: GZTKH | D23: Cartier | E23: 28000000
B24: 45778 | C24: GZTKH | D24: Bulgari | E24: 10250000
B25: 45778 | C25: GZTKH | D25: Tiffany | E25: 6550000
B26: 45778 | C26: GZTKH | D26: VCA | E26: 13500000
B27: 45809 | C27: GZTKH | D27: Chaumet
B28: 45809 | C28: GZTKH | D28: Cartier
B29: 45809 | C29: GZTKH | D29: Bulgari
B30: 45809 | C30: GZTKH | D30: Tiffany
B31: 45809 | C31: GZTKH | D31: VCA
B32: 45839 | C32: GZTKH | D32: Chaumet
B33: 45839 | C33: GZTKH | D33: Cartier
B34: 45839 | C34: GZTKH | D34: Bulgari
B35: 45839 | C35: GZTKH | D35: Tiffany
B36: 45839 | C36: GZTKH | D36: VCA
B37: 45870 | C37: GZTKH | D37: Chaumet
B38: 45870 | C38: GZTKH | D38: Cartier
... B61: 45992 | C61: GZTKH | D61: VCA
B62: 45292 | C62: GZTKH | D62: Chaumet | E62: 4558318.5
B63: 45292 | C63: GZTKH | D63: Cartier | E63: 30200000
B64: 45292 | C64: GZTKH | D64: Bulgari | E64: 9840000
...

Sheet SZBAY
B1: Date | C1: Mall | D1: Brand | E1: Sales
B2: 45658 | C2: SZBAY | D2: Chaumet | E2: 1162626.5
B3: 45658 | C3: SZBAY | D3: Cartier | E3: 15700000
B4: 45658 | C4: SZBAY | D4: Bulgari | E4: 4800000
B5: 45658 | C5: SZBAY | D5: Tiffany | E5: 4080000
B6: 45658 | C6: SZBAY | D6: VCA | E6: 20000000
B7: 45689 | C7: SZBAY | D7: Chaumet | E7: 3673166.4
B8: 45689 | C8: SZBAY | D8: Cartier | E8: 17130000
B9: 45689 | C9: SZBAY | D9: Bulgari | E9: 4750000
B10: 45689 | C10: SZBAY | D10: Tiffany | E10: 4080000
B11: 45689 | C11: SZBAY | D11: VCA | E11: 17720000
B12: 45717 | C12: SZBAY | D12: Chaumet | E12: 1727785
B13: 45717 | C13: SZBAY | D13: Cartier | E13: 11800000
... B16: 45717 | C16: SZBAY | D16: VCA | E16: 17840000
B17: =B19 -> 45748 | C17: SZBAY | D17: Chaumet | E17: 3333901.9
B18: 45748 | C18: SZBAY | D18: Cartier | E18: 15500000
B19: 45748 | C19: SZBAY | D19: Bulgari | E19: 4730000
B20: 45748 | C20: SZBAY | D20: Tiffany | E20: 2300000
B21: 45748 | C21: SZBAY | D21: VCA | E21: 23700000
B22: 45778 | C22: SZBAY | D22: Chaumet | E22: 3793661.1
B23: 45778 | C23: SZBAY | D23: Cartier | E23: 17110000
B24: 45778 | C24: SZBAY | D24: Bulgari | E24: 5500000
B25: 45778 | C25: SZBAY | D25: Tiffany | E25: 4600000
B26: 45778 | C26: SZBAY | D26: VCA | E26: 22290000
B27: 45809 | C27: SZBAY | D27: Chaumet
B28: 45809 | C28: SZBAY | D28: Cartier
B29: 45809 | C29: SZBAY | D29: Bulgari
B30: 45809 | C30: SZBAY | D30: Tiffany
B31: 45809 | C31: SZBAY | D31: VCA
B32: 45839 | C32: SZBAY | D32: Chaumet
B33: 45839 | C33: SZBAY | D33: Cartier
B34: 45839 | C34: SZBAY | D34: Bulgari
B35: 45839 | C35: SZBAY | D35: Tiffany
B36: 45839 | C36: SZBAY | D36: VCA
B37: 45870 | C37: SZBAY | D37: Chaumet
B38: 45870 | C38: SZBAY | D38: Cartier
... B61: 45992 | C61: SZBAY | D61: VCA
B62: 45292 | C62: SZBAY | E62: 2347846
B63: 45292 | C63: SZBAY | E63: 14830000
B64: 45292 | C64: SZBAY | E64: 7970000
...

Sheet SZLH
B1: Date | C1: Mall | D1: Brand | E1: Sales
B2: 45658 | C2: SZLH | D2: Chaumet | E2: 2455069
B3: 45658 | C3: SZLH | D3: Cartier | E3: 12800000
B4: 45658 | C4: SZLH | D4: Bulgari | E4: 7000000
B5: 45658 | C5: SZLH | D5: Tiffany | E5: 3900000
B6: 45658 | C6: SZLH | D6: VCA | E6: 0
B7: 45689 | C7: SZLH | D7: Chaumet | E7: 2103602.7
B8: 45689 | C8: SZLH | D8: Cartier | E8: 11700000
B9: 45689 | C9: SZLH | D9: Bulgari | E9: 5180000
B10: 45689 | C10: SZLH | D10: Tiffany | E10: 2670000
B11: 45689 | C11: SZLH | D11: VCA | E11: 0
B12: 45717 | C12: SZLH | D12: Chaumet | E12: 2082042.5
B13: 45717 | C13: SZLH | D13: Cartier | E13: 19310000
... B16: 45717 | C16: SZLH | D16: VCA | E16: 0
B17: =B19 -> 45748 | C17: SZLH | D17: Chaumet | E17: 1216261.9
