Workbook

Sheet Sheet2
A1: Year | B1: 2025
A2: Month | B2: 2
A4: Row Labels | B4: Sum of Total Capex Cost | C4: Sum of Remaining Capex Cost | D4: Sum of Total Spend
A5: Adonis 1P | B5: 1296200 | C5: 1296200 | D5: 0
A6: Alto Device | B6: 600000 | C6: 0 | D6: 0
A7: Alto Pod | B7: 67776119 | C7: 5755257.4 | D7: 8645429.5
A8: Box 5000 Full 2.0 | C8: 0 | D8: 0
A9: Box 800 Full 2.0 | B9: 14000 | C9: -1699.0204 | D9: 0
A10: Hyper Core | B10: 3254051 | C10: 1639779 | D10: 61858.57
A11: Hyper Pro | D11: 6711.73
A12: Hyper Pro | B12: 1314400 | C12: -346227.87 | D12: 301707.37
A13: KUMA E-Box NZ | B13: 0 | C13: 0 | D13: 0
A14: KUMA E-Pen 1.0 ROW | B14: 1960000 | C14: 1423826.1 | D14: 1089578.7
A15: Pen 800 Full 2.0 | B15: 111000 | C15: 110343.87 | D15: 178941.57
A16: Prismatic Device | B16: 0 | C16: 0 | D16: 0
A17: Prismatic Pod | B17: 8518207.2 | C17: 8518207.2 | D17: 0
A18: Vega | B18: 18800000 | C18: 0 | D18: 126545.15
A19: Grand Total | B19: 1.0364398e+08 | C19: 18395687 | D19: 10410773

Sheet Sheet3
A1: Tool type | B1: (Multiple Items)
A3: Row Labels | B3: Sum of Total Tool cost
A4: Adonis 1P | B4: 1296200
A5: Alto Device | B5: 600000
A6: Alto Pod | B6: 67776120
A7: Box 5000 Full 2.0 | B7: 0
A8: Box 800 Full 2.0 | B8: 14000
A9: Hyper Core | B9: 3241452
A10: Hyper Pro 2P | B10: 1327000
A11: KUMA E-Pen 1.0 ROW | B11: 1960000
A12: Pen 800 Full 2.0 | B12: 111000
A13: Prismatic Pod | B13: 8518207.2
A14: VEGA | B14: 18800000
A15: Grand Total | B15: 1.0364398e+08

Sheet Spend Track (part)
A1: Product category | B1: RCS POD | C1: RCS DEVICE | D1: MODI | E1: HP | F1: MO | G1: Update date：2025/3/12
C2: 请确保和最新的2D 图纸一样，包括大小写. 字体请用Calibri， 10 号字体
A3: Project | B3: Product Category | C3: Part Name | D3: Part No. | E3: Supplier | F3: Commonality | G3: Commodity | H3: Year | I3: Month | J3: Data Submit Date | K3: Split | L3: Unit price w/o amortization | M3: Unit Price with Amortization | N3: Amortization Cost | O3: Blended Amortization Cost | P3: Usage in BOM | Q3: BOM cost | R3: Shipped Volume | S3: Cum Shipped Volume | T3: Total Capex Cost | U3: Remaining Capex Cost | V3: Material Type | W3: Color | X3: Material Usage/part (g) | Y3: Material Supplier | Z3: CMF Type | AA3: CMF Cost/part | AB3: Total Spend | AC3: Total CMF Cost | AD3: Total Material Usage (kg) | AE3: Remark
A4: Vega | B4: =VLOOKUP(A4,Sheet1!A:B,2,0) -> MODI | C4: Mouth Piece | D4: 310493191000 | E4: JEE | F4: unique | G4: Plastic | H4: 2023 | I4: 12 | J4: 45590 | K4: 0.5 | L4: 0.31352499 | M4: 0.33477499 | N4: =M4-L4 -> 0.02125 | O4: =N4*K4 -> 0.010625 | P4: 1 | Q4: =P4*L4 -> 0.31352499 | R4: 30954490 | S4: =R4 -> 30954490 | T4: 4760000 | U4: =T4-N4*S4 -> 4102217.1 | V4: PCTG TX1501HF | X4: 6.728 | Y4: Eastman | AA4: 0 | AB4: =M4*R4 -> 10362789 | AC4: =R4*AA4 -> 0 | AD4: =R4*X4/1000 -> 208261.81
A5: Vega | B5: =VLOOKUP(A5,Sheet1!A:B,2,0) -> MODI | C5: Top Plastic Bracket | D5: 310493192000 | E5: JEE | F5: unique | G5: Plastic | H5: 2023 | I5: 12 | J5: 45590 | K5: 0.5 | L5: 0.042153932 | M5: 0.056528932 | N5: =M5-L5 -> 0.014375 | O5: =N5*K5 -> 0.0071875 | P5: 1 | Q5: =P5*L5 -> 0.042153932 | R5: 27721346 | S5: =R5 -> 27721346 | T5: 3450000 | U5: =T5-N5*S5 -> 3051505.7 | V5: PCTG TX1501HF | X5: 0.87 | Y5: Eastman | AA5: 0 | AB5: =M5*R5 -> 1567058.1 | AC5: =R5*AA5 -> 0 | AD5: =R5*X5/1000 -> 24117.571
A6: Vega | B6: =VLOOKUP(A6,Sheet1!A:B,2,0) -> MODI | C6: Bottom Plastic Bracket | D6: 310493193000 | E6: JEE | F6: unique | G6: Plastic | H6: 2023 | I6: 12 | J6: 45590 | K6: 0.5 | L6: 0.072210435 | M6: 0.087793768 | N6: =M6-L6 -> 0.015583333 | O6: =N6*K6 -> 0.0077916667 | P6: 1 | Q6: =P6*L6 -> 0.072210435 | R6: 30135782 | S6: =R6 -> 30135782 | T6: 3740000 | U6: =T6-N6*S6 -> 3270384.1 | V6: PCTG TX1501HF | X6: 1.178 | Y6: Eastman | AA6: 0 | AB6: =M6*R6 -> 2645733.9 | AC6: =R6*AA6 -> 0 | AD6: =R6*X6/1000 -> 35499.951
A7: Vega | B7: =VLOOKUP(A7,Sheet1!A:B,2,0) -> MODI | C7: Bottom cap | D7: 310493194000 | E7: JEE | F7: unique | G7: Plastic | H7: 2023 | I7: 12 | J7: 45590 | K7: 0.5 | L7: 0.066190725 | M7: 0.080565725 | N7: =M7-L7 -> 0.014375 | O7: =N7*K7 -> 0.0071875 | P7: 1 | Q7: =P7*L7 -> 0.066190725 | R7: 15794015 | S7: =R7 -> 15794015 | T7: 3450000 | U7: =T7-N7*S7 -> 3222961 | V7: LUPOY ER1000MA | X7: 1.178 | Y7: Ruicheng | AA7: 0 | AB7: =M7*R7 -> 1272456.3 | AC7: =R7*AA7 -> 0 | AD7: =R7*X7/1000 -> 18605.35
A8: Vega | B8: =VLOOKUP(A8,Sheet1!A:B,2,0) -> MODI | C8: Air Flow slider | D8: 310493195000 | E8: JEE | F8: unique | G8: Plastic | H8: 2023 | I8: 12 | J8: 45590 | K8: 0.5 | L8: 0.038519575 | M8: 0.052686242 | N8: =M8-L8 -> 0.014166667 | O8: =N8*K8 -> 0.0070833333 | P8: 1 | Q8: =P8*L8 -> 0.038519575 | R8: 42312050 | S8: =R8 -> 42312050 | T8: 3400000 | U8: =T8-N8*S8 -> 2800579.3 | V8: LUPOY ER1000MA | X8: 0.134 | Y8: Ruicheng | AA8: 0 | AB8: =M8*R8 -> 2229262.9 | AC8: =R8*AA8 -> 0 | AD8: =R8*X8/1000 -> 5669.8147
A9: Vega | B9: =VLOOKUP(A9,Sheet1!A:B,2,0) -> MODI | C9: Mouth Piece | D9: 310493191000 | E9: JEE | F9: unique | G9: Plastic | H9: 2024 | I9: 1 | J9: 45590 | K9: 0.5 | L9: 0.31352499 | M9: 0.33477499 | N9: =M9-L9 -> 0.02125 | O9: =N9*K9 -> 0.010625 | P9: 1 | Q9: =P9*L9 -> 0.31352499 | R9: 2479038 | S9: =R9+S4 -> 33433528 | T9: 4760000 | U9: =T9-N9*S9 -> 4049537.5 | V9: PCTG TX1501HF | X9: 6.728 | Y9: Eastman | AA9: 0 | AB9: =M9*R9 -> 829919.91 | AC9: =R9*AA9 -> 0 | AD9: =R9*X9/1000 -> 16678.968
A10: Vega | B10: =VLOOKUP(A10,Sheet1!A:B,2,0) -> MODI | C10: Top Plastic Bracket | D10: 310493192000 | E10: JEE | F10: unique | G10: Plastic | H10: 2024 | I10: 1 | J10: 45590 | K10: 0.5 | L10: 0.042153932 | M10: 0.056528932 | N10: =M10-L10 -> 0.014375 | O10: =N10*K10 -> 0.0071875 | P10: 1 | Q10: =P10*L10 -> 0.042153932 | R10: 2530321 | S10: =R10+S5 -> 30251667 | T10: 3450000 | U10: =T10-N10*S10 -> 3015132.3 | V10: PCTG TX1501HF | X10: 0.87 | Y10: Eastman | AA10: 0 | AB10: =M10*R10 -> 143036.34 | AC10: =R10*AA10 -> 0 | AD10: =R10*X10/1000 -> 2201.3793
A11: Vega | B11: =VLOOKUP(A11,Sheet1!A:B,2,0) -> MODI | C11: Bottom Plastic Bracket | D11: 310493193000 | E11: JEE | F11: unique | G11: Plastic | H11: 2024 | I11: 1 | J11: 45590 | K11: 0.5 | L11: 0.072210435 | M11: 0.087793768 | N11: =M11-L11 -> 0.015583333 | O11: =N11*K11 -> 0.0077916667 | P11: 1 | Q11: =P11*L11 -> 0.072210435 | R11: 2184407 | S11: =R11+S6 -> 32320189 | T11: 3740000 | U11: =T11-N11*S11 -> 3236343.7 | V11: PCTG TX1501HF | X11: 1.178 | Y11: Eastman | AA11: 0 | AB11: =M11*R11 -> 191777.32 | AC11: =R11*AA11 -> 0 | AD11: =R11*X11/1000 -> 2573.2314
A12: Vega | B12: =VLOOKUP(A12,Sheet1!A:B,2,0) -> MODI | C12: Bottom cap | D12: 310493194000 | E12: JEE | F12: unique | G12: Plastic | H12: 2024 | I12: 1 | J12: 45590 | K12: 0.5 | L12: 0.066190725 | M12: 0.080565725 | N12: =M12-L12 -> 0.014375 | O12: =N12*K12 -> 0.0071875 | P12: 1 | Q12: =P12*L12 -> 0.066190725 | R12: 2258856 | S12: =R12+S7 -> 18052871 | T12: 3450000 | U12: =T12-N12*S12 -> 3190490 | V12: LUPOY ER1000MA | X12: 1.178 | Y12: Ruicheng | AA12: 0 | AB12: =M12*R12 -> 181986.37 | AC12: =R12*AA12 -> 0 | AD12: =R12*X12/1000 -> 2660.9324
A13: Vega | B13: =VLOOKUP(A13,Sheet1!A:B,2,0) -> MODI | C13: Air Flow slider | D13: 310493195000 | E13: JEE | F13: unique | G13: Plastic | H13: 2024 | I13: 1 | J13: 45590 | K13: 0.5 | L13: 0.038519575 | M13: 0.052686242 | N13: =M13-L13 -> 0.014166667 | O13: =N13*K13 -> 0.0070833333 | P13: 1 | Q13: =P13*L13 -> 0.038519575 | R13: 1792586 | S13: =R13+S8 -> 44104636 | T13: 3400000 | U13: =T13-N13*S13 -> 2775184.3 | V13: LUPOY ER1000MA | X13: 0.134 | Y13: Ruicheng | AA13: 0 | AB13: =M13*R13 -> 94444.619 | AC13: =R13*AA13 -> 0 | AD13: =R13*X13/1000 -> 240.20652
A14: Vega | B14: =VLOOKUP(A14,Sheet1!A:B,2,0) -> MODI | C14: Mouth Piece | D14: 310493191000 | E14: JEE | F14: unique | G14: Plastic | H14: 2024 | I14: 2 | J14: 45590 | K14: 0.5 | L14: 0.31352499 | M14: 0.33477499 | N14: =M14-L14 -> 0.02125 | O14: =N14*K14 -> 0.010625 | P14: 1 | Q14: =P14*L14 -> 0.31352499 | R14: 1002816 | S14: =R14+S9 -> 34436344 | T14: 4760000 | U14: =T14-N14*S14 -> 4028227.7 | V14: PCTG TX1501HF | X14: 6.728 | Y14: Eastman | AA14: 0 | AB14: =M14*R14 -> 335717.71 | AC14: =R14*AA14 -> 0 | AD14: =R14*X14/1000 -> 6746.946
A15: Vega | B15: =VLOOKUP(A15,Sheet1!A:B,2,0) -> MODI | C15: Top Plastic Bracket | D15: 310493192000 | E15: JEE | F15: unique | G15: Plastic | H15: 2024 | I15: 2 | J15: 45590 | K15: 0.5 | L15: 0.042153932 | M15: 0.056528932 | N15: =M15-L15 -> 0.014375 | O15: =N15*K15 -> 0.0071875 | P15: 1 | Q15: =P15*L15 -> 0.042153932 | R15: 1600000 | S15: =R15+S10 -> 31851667 | T15: 3450000 | U15: =T15-N15*S15 -> 2992132.3 | V15: PCTG TX1501HF | X15: 0.87 | Y15: Eastman | AA15: 0 | AB15: =M15*R15 -> 90446.291 | AC15: =R15*AA15 -> 0 | AD15: =R15*X15/1000 -> 1392
A16: Vega | B16: =VLOOKUP(A16,Sheet1!A:B,2,0) -> MODI | C16: Bottom Plastic Bracket | D16: 310493193000 | E16: JEE | F16: unique | G16: Plastic | H16: 2024 | I16: 2 | J16: 45590 | K16: 0.5 | L16: 0.072210435 | M16: 0.087793768 | N16: =M16-L16 -> 0.015583333 | O16: =N16*K16 -> 0.0077916667 | P16: 1 | Q16: =P16*L16 -> 0.072210435 | R16: 1332000 | S16: =R16+S11 -> 33652189 | T16: 3740000 | U16: =T16-N16*S16 -> 3215586.7 | V16: PCTG TX1501HF | X16: 1.178 | Y16: Eastman | AA16: 0 | AB16: =M16*R16 -> 116941.3 | AC16: =R16*AA16 -> 0 | AD16: =R16*X16/1000 -> 1569.096
A17: Vega | B17: =VLOOKUP(A17,Sheet1!A:B,2,0) -> MODI | C17: Bottom cap | D17: 310493194000 | E17: JEE | F17: unique | G17: Plastic | H17: 2024 | I17: 2 | J17: 45590 | K17: 0.5 | L17: 0.066190725 | M17: 0.080565725 | N17: =M17-L17 -> 0.014375 | O17: =N17*K17 -> 0.0071875 | P17: 1 | Q17: =P17*L17 -> 0.066190725 | R17: 1095430 | S17: =R17+S12 -> 19148301 | T17: 3450000 | U17: =T17-N17*S17 -> 3174743.2 | V17: LUPOY ER1000MA | X17: 1.178 | Y17: Ruicheng | AA17: 0 | AB17: =M17*R17 -> 88254.113 | AC17: =R17*AA17 -> 0 | AD17: =R17*X17/1000 -> 1290.4165
A18: Vega | B18: =VLOOKUP(A18,Sheet1!A:B,2,0) -> MODI | C18: Air Flow slider | D18: 310493195000 | E18: JEE | F18: unique | G18: Plastic | H18: 2024 | I18: 2 | J18: 45590 | K18: 0.5 | L18: 0.038519575 | M18: 0.052686242 | N18: =M18-L18 -> 0.014166667 | O18: =N18*K18 -> 0.0070833333 | P18: 1 | Q18: =P18*L18 -> 0.038519575 | R18: 1241998 | S18: =R18+S13 -> 45346634 | T18: 3400000 | U18: =T18-N18*S18 -> 2757589.4 | V18: LUPOY ER1000MA | X18: 0.134 | Y18: Ruicheng | AA18: 0 | AB18: =M18*R18 -> 65436.207 | AC18: =R18*AA18 -> 0 | AD18: =R18*X18/1000 -> 166.42773
A19: Vega | B19: =VLOOKUP(A19,Sheet1!A:B,2,0) -> MODI | C19: Mouth Piece | D19: 310493191000 | E19: JEE | F19: unique | G19: Plastic | H19: 2024 | I19: 3 | J19: 45590 | K19: 0.5 | L19: 0.31352499 | M19: 0.33477499 | N19: =M19-L19 -> 0.02125 | O19: =N19*K19 -> 0.010625 | P19: 1 | Q19: =P19*L19 -> 0.31352499 | R19: 3074296 | S19: =R19+S14 -> 37510640 | T19: 4760000 | U19: =T19-N19*S19 -> 3962898.9 | V19: PCTG TX1501HF | X19: 6.728 | Y19: Eastman | AA19: 0 | AB19: =M19*R19 -> 1029197.4 | AC19: =R19*AA19 -> 0 | AD19: =R19*X19/1000 -> 20683.863
A20: Vega | B20: =VLOOKUP(A20,Sheet1!A:B,2,0) -> MODI | C20: Top Plastic Bracket | D20: 310493192000 | E20: JEE | F20: unique | G20: Plastic | H20: 2024 | I20: 3 | J20: 45590 | K20: 0.5 | L20: 0.042153932 | M20: 0.056528932 | N20: =M20-L20 -> 0.014375 | O20: =N20*K20 -> 0.0071875 | P20: 1 | Q20: =P20*L20 -> 0.042153932 | R20: 1600000 | S20: =R20+S15 -> 33451667 | T20: 3450000 | U20: =T20-N20*S20 -> 2969132.3 | V20: PCTG TX1501HF | X20: 0.87 | Y20: Eastman | AA20: 0 | AB20: =M20*R20 -> 90446.291 | AC20: =R20*AA20 -> 0 | AD20: =R20*X20/1000 -> 1392
... A53: Vega | B53: =VLOOKUP(A53,Sheet1!A:B,2,0) -> MODI | C53: Air Flow slider | D53: 310493195000 | E53: JEE | F53: unique | G53: Plastic | H53: 2024 | I53: 9 | J53: 45590 | K53: 0.5 | L53: 0.038519575 | M53: 0.052686242 | N53: =M53-L53 -> 0.014166667 | O53: =N53*K53 -> 0.0070833333 | P53: 1 | Q53: =P53*L53 -> 0.038519575 | R53: 162943 | S53: =R53+S48 -> 56288362 | T53: 3400000 | U53: =T53-N53*S53 -> 2602581.5 | V53: LUPOY ER1000MA | X53: 0.134 | Y53: Ruicheng | AA53: 0 | AB53: =M53*R53 -> 8584.8543 | AC53: =R53*AA53 -> 0 | AD53: =R53*X53/1000 -> 21.834362
A54: KUMA E-Box NZ | B54: =VLOOKUP(A54,Sheet1!A:B,2,0) -> RCS DEVICE | C54: Top cover | D54: 130040670021260 | E54: JEE | F54: Unique | G54: Plastic | H54: 2023 | I54: 12 | J54: 45590 | K54: 1 | L54: 2.3583409 | M54: 2.3583409 | N54: =M54-L54 -> 0 | O54: =N54*K54 -> 0 | P54: 1 | Q54: =P54*L54 -> 2.3583409 | R54: 3350 | S54: =R54 -> 3350 | T54: 0 | U54: 0 | V54: LUPOY GP1000ML | X54: 16.26 | Y54: LG | Z54: Printing | AA54: 1.308 | AB54: =M54*R54 -> 7900.4419 | AC54: =R54*AA54 -> 4381.8 | AD54: =R54*X54/1000 -> 54.471
A55: KUMA E-Box NZ | B55: =VLOOKUP(A55,Sheet1!A:B,2,0) -> RCS DEVICE | C55: Bottom cover | D55: 130040670021261 | E55: JEE | F55: Unique | G55: Plastic | H55: 2023 | I55: 12 | J55: 45590 | K55: 1 | L55: 2.3165273 | M55: 2.3165273 | N55: =M55-L55 -> 0 | O55: =N55*K55 -> 0 | P55: 1 | Q55: =P55*L55 -> 2.3165273 | R55: 3794 | S55: =R55 -> 3794 | T55: 0 | U55: 0 | V55: LUPOY GP1000ML | X55: 8.302 | Y55: LG | Z55: Printing | AA55: 1.428 | AB55: =M55*R55 -> 8788.9045 | AC55: =R55*AA55 -> 5417.832 | AD55: =R55*X55/1000 -> 31.497788
A56: KUMA E-Box NZ | B56: =VLOOKUP(A56,Sheet1!A:B,2,0) -> RCS DEVICE | C56: Button | D56: 130040670021263 | E56: JEE | F56: Unique | G56: Plastic | H56: 2023 | I56: 12 | J56: 45590 | K56: 1 | L56: 0.37651638 | M56: 0.37651638 | N56: =M56-L56 -> 0 | O56: =N56*K56 -> 0 | P56: 1 | Q56: =P56*L56 -> 0.37651638 | R56: 4036 | S56: =R56 -> 4036 | T56: 0 | U56: 0 | V56: LUPOY GP1000ML | X56: 0.572 | Y56: LG | AA56: 0 | AB56: =M56*R56 -> 1519.6201 | AC56: =R56*AA56 -> 0 | AD56: =R56*X56/1000 -> 2.308592
A57: KUMA E-Box NZ | B57: =VLOOKUP(A57,Sheet1!A:B,2,0) -> RCS DEVICE | C57: PCB holder | D57: 130040670021262 | E57: JEE | F57: Unique | G57: Plastic | H57: 2023 | I57: 12 | J57: 45590 | K57: 1 | L57: 0.37927345 | M57: 0.37927345 | N57: =M57-L57 -> 0 | O57: =N57*K57 -> 0 | P57: 1 | Q57: =P57*L57 -> 0.37927345 | R57: 4000 | S57: =R57 -> 4000 | T57: 0 | U57: 0 | V57: PC Makrolon 2456 | X57: 1.87 | Y57: Makrolon | AA57: 0 | AB57: =M57*R57 -> 1517.0938 | AC57: =R57*AA57 -> 0 | AD57: =R57*X57/1000 -> 7.48
A58: KUMA E-Box NZ | B58: =VLOOKUP(A58,Sheet1!A:B,2,0) -> RCS DEVICE | C58: Top cover | D58: 130040670021260 | E58: JEE | F58: Unique | G58: Plastic | H58: 2024 | I58: 1 | J58: 45590 | K58: 1 | L58: 2.3583409 | M58: 2.3583409 | N58: =M58-L58 -> 0 | O58: =N58*K58 -> 0 | P58: 1 | Q58: =P58*L58 -> 2.3583409 | R58: 201800 | S58: =R58+S54 -> 205150 | T58: 0 | U58: 0 | V58: LUPOY GP1000ML | X58: 16.26 | Y58: LG | Z58: Printing | AA58: 1.308 | AB58: =M58*R58 -> 475913.19 | AC58: =R58*AA58 -> 263954.4 | AD58: =R58*X58/1000 -> 3281.268
A59: KUMA E-Box NZ | B59: =VLOOKUP(A59,Sheet1!A:B,2,0) -> RCS DEVICE | C59: Bottom cover | D59: 130040670021261 | E59: JEE | F59: Unique | G59: Plastic | H59: 2024 | I59: 1 | J59: 45590 | K59: 1 | L59: 2.3165273 | M59: 2.3165273 | N59: =M59-L59 -> 0 | O59: =N59*K59 -> 0 | P59: 1 | Q59: =P59*L59 -> 2.3165273 | R59: 182616 | S59: =R59+S55 -> 186410 | T59: 0 | U59: 0 | V59: LUPOY GP1000ML | X59: 8.302 | Y59: LG | Z59: Printing | AA59: 1.428 | AB59: =M59*R59 -> 423034.95 | AC59: =R59*AA59 -> 260775.65 | AD59: =R59*X59/1000 -> 1516.078
A60: KUMA E-Box NZ | B60: =VLOOKUP(A60,Sheet1!A:B,2,0) -> RCS DEVICE | C60: Button | D60: 130040670021263 | E60: JEE | F60: Unique | G60: Plastic | H60: 2024 | I60: 1 | J60: 45590 | K60: 1 | L60: 0.37651638 | M60: 0.37651638 | N60: =M60-L60 -> 0 | O60: =N60*K60 -> 0 | P60: 1 | Q60: =P60*L60 -> 0.37651638 | R60: 185032 | S60: =R60+S56 -> 189068 | T60: 0 | U60: 0 | V60: LUPOY GP1000ML | X60: 0.572 | Y60: LG | AA60: 0 | AB60: =M60*R60 -> 69667.579 | AC60: =R60*AA60 -> 0 | AD60: =R60*X60/1000 -> 105.8383
A61: KUMA E-Box NZ | B61: =VLOOKUP(A61,Sheet1!A:B,2,0) -> RCS DEVICE | C61: PCB holder | D61: 130040670021262 | E61: JEE | F61: Unique | G61: Plastic | H61: 2024 | I61: 1 | J61: 45590 | K61: 1 | L61: 0.37927345 | M61: 0.37927345 | N61: =M61-L61 -> 0 | O61: =N61*K61 -> 0 | P61: 1 | Q61: =P61*L61 -> 0.37927345 | R61: 286070 | S61: =R61+S57 -> 290070 | T61: 0 | U61: 0 | V61: PC Makrolon 2456 | X61: 1.87 | Y61: Makrolon | AA61: 0 | AB61: =M61*R61 -> 108498.76 | AC61: =R61*AA61 -> 0 | AD61: =R61*X61/1000 -> 534.9509
A62: KUMA E-Box NZ | B62: =VLOOKUP(A62,Sheet1!A:B,2,0) -> RCS DEVICE | C62: Top cover | D62: 130040670021260 | E62: JEE | F62: Unique | G62: Plastic | H62: 2024 | I62: 2 | J62: 45590 | K62: 1 | L62: 2.3583409 | M62: 2.3583409 | N62: =M62-L62 -> 0 | O62: =N62*K62 -> 0 | P62: 1 | Q62: =P62*L62 -> 2.3583409 | R62: 10445 | S62: =R62+S58 -> 215595 | T62: 0 | U62: 0 | V62: LUPOY GP1000ML | X62: 16.26 | Y62: LG | Z62: Printing | AA62: 1.308 | AB62: =M62*R62 -> 24632.87 | AC62: =R62*AA62 -> 13662.06 | AD62: =R62*X62/1000 -> 169.8357
A63: KUMA E-Box NZ | B63: =VLOOKUP(A63,Sheet1!A:B,2,0) -> RCS DEVICE | C63: Bottom cover | D63: 130040670021261 | E63: JEE | F63: Unique | G63: Plastic | H63: 2024 | I63: 2 | J63: 45590 | K63: 1 | L63: 2.3165273 | M63: 2.3165273 | N63: =M63-L63 -> 0 | O63: =N63*K63 -> 0 | P63: 1 | Q63: =P63*L63 -> 2.3165273 | R63: 110305 | S63: =R63+S59 -> 296715 | T63: 0 | U63: 0 | V63: LUPOY GP1000ML | X63: 8.302 | Y63: LG | Z63: Printing | AA63: 1.428 | AB63: =M63*R63 -> 255524.54 | AC63: =R63*AA63 -> 157515.54 | AD63: =R63*X63/1000 -> 915.75211
A64: KUMA E-Box NZ | B64: =VLOOKUP(A64,Sheet1!A:B,2,0) -> RCS DEVICE | C64: Button | D64: 130040670021263 | E64: JEE | F64: Unique | G64: Plastic | H64: 2024 | I64: 2 | J64: 45590 | K64: 1 | L64: 0.37651638 | M64: 0.37651638 | N64: =M64-L64 -> 0 | O64: =N64*K64 -> 0 | P64: 1 | Q64: =P64*L64 -> 0.37651638 | R64: 45462 | S64: =R64+S60 -> 234530 | T64: 0 | U64: 0 | V64: LUPOY GP1000ML | X64: 0.572 | Y64: LG | AA64: 0 | AB64: =M64*R64 -> 17117.188 | AC64: =R64*AA64 -> 0 | AD64: =R64*X64/1000 -> 26.004264
A65: KUMA E-Box NZ | B65: =VLOOKUP(A65,Sheet1!A:B,2,0) -> RCS DEVICE | C65: PCB holder | D65: 130040670021262 | E65: JEE | F65: Unique | G65: Plastic | H65: 2024 | I65: 2 | J65: 45590 | K65: 1 | L65: 0.37927345 | M65: 0.37927345 | N65: =M65-L65 -> 0 | O65: =N65*K65 -> 0 | P65: 1 | Q65: =P65*L65 -> 0.37927345 | R65: 33000 | S65: =R65+S61 -> 323070 | T65: 0 | U65: 0 | V65: PC Makrolon 2456 | X65: 1.87 | Y65: Makrolon | AA65: 0 | AB65: =M65*R65 -> 12516.024 | AC65: =R65*AA65 -> 0 | AD65: =R65*X65/1000 -> 61.71
A66: KUMA E-Box NZ | B66: =VLOOKUP(A66,Sheet1!A:B,2,0) -> RCS DEVICE | C66: Top cover | D66: 130040670021260 | E66: JEE | F66: Unique | G66: Plastic | H66: 2024 | I66: 3 | J66: 45590 | K66: 1 | L66: 2.3583409 | M66: 2.3583409 | N66: =M66-L66 -> 0 | O66: =N66*K66 -> 0 | P66: 1 | Q66: =P66*L66 -> 2.3583409 | R66: 88849 | S66: =R66+S62 -> 304444 | T66: 0 | U66: 0 | V66: LUPOY GP1000ML | X66: 16.26 | Y66: LG | Z66: Printing | AA66: 1.308 | AB66: =M66*R66 -> 209536.23 | AC66: =R66*AA66 -> 116214.49 | AD66: =R66*X66/1000 -> 1444.6847
A67: KUMA E-Box NZ | B67: =VLOOKUP(A67,Sheet1!A:B,2,0) -> RCS DEVICE | C67: Bottom cover | D67: 130040670021261 | E67: JEE | F67: Unique | G67: Plastic | H67: 2024 | I67: 3 | J67: 45590 | K67: 1 | L67: 2.3165273 | M67: 2.3165273 | N67: =M67-L67 -> 0 | O67: =N67*K67 -> 0 | P67: 1 | Q67: =P67*L67 -> 2.3165273 | R67: 23024 | S67: =R67+S63 -> 319739 | T67: 0 | U67: 0 | V67: LUPOY GP1000ML | X67: 8.302 | Y67: LG | Z67: Printing | AA67: 1.428 | AB67: =M67*R67 -> 53335.724 | AC67: =R67*AA67 -> 32878.272 | AD67: =R67*X67/1000 -> 191.14525
A68: KUMA E-Box NZ | B68: =VLOOKUP(A68,Sheet1!A:B,2,0) -> RCS DEVICE | C68: Button | D68: 130040670021263 | E68: JEE | F68: Unique | G68: Plastic | H68: 2024 | I68: 3 | J68: 45590 | K68: 1 | L68: 0.37651638 | M68: 0.37651638 | N68: =M68-L68 -> 0 | O68: =N68*K68 -> 0 | P68: 1 | Q68: =P68*L68 -> 0.37651638 | R68: 74845 | S68: =R68+S64 -> 309375 | T68: 0 | U68: 0 | V68: LUPOY GP1000ML | X68: 0.572 | Y68: LG | AA68: 0 | AB68: =M68*R68 -> 28180.368 | AC68: =R68*AA68 -> 0 | AD68: =R68*X68/1000 -> 42.81134
A69: KUMA E-Box NZ | B69: =VLOOKUP(A69,Sheet1!A:B,2,0) -> RCS DEVICE | C69: PCB holder | D69: 130040670021262 | E69: JEE | F69: Unique | G69: Plastic | H69: 2024 | I69: 3 | J69: 45590 | K69: 1 | L69: 0.37927345 | M69: 0.37927345 | N69: =M69-L69 -> 0 | O69: =N69*K69 -> 0 | P69: 1 | Q69: =P69*L69 -> 0.37927345 | R69: 0 | S69: =R69+S65 -> 323070 | T69: 0 | U69: 0 | V69: PC Makrolon 2456 | X69: 1.87 | Y69: Makrolon | AA69: 0 | AB69: =M69*R69 -> 0 | AC69: =R69*AA69 -> 0 | AD69: =R69*X69/1000 -> 0
A70: KUMA E-Box NZ | B70: =VLOOKUP(A70,Sheet1!A:B,2,0) -> RCS DEVICE | C70: Top cover | D70: 130040670021260 | E70: JEE | F70: Unique | G70: Plastic | H70: 2024 | I70: 4 | J70: 45590 | K70: 1 | L70: 2.3583409 | M70: 2.3583409 | N70: =M70-L70 -> 0 | O70: =N70*K70 -> 0 | P70: 1 | Q70: =P70*L70 -> 2.3583409 | R70: 0 | S70: =R70+S66 -> 304444 | T70: 0 | U70: 0 | V70: LUPOY GP1000ML | X70: 16.26 | Y70: LG | Z70: Printing | AA70: 1.308 | AB70: =M70*R70 -> 0 | AC70: =R70*AA70 -> 0 | AD70: =R70*X70/1000 -> 0
A71: KUMA E-Box NZ | B71: =VLOOKUP(A71,Sheet1!A:B,2,0) -> RCS DEVICE | C71: Bottom cover | D71: 130040670021261 | E71: JEE | F71: Unique | G71: Plastic | H71: 2024 | I71: 4 | J71: 45590 | K71: 1 | L71: 2.3165273 | M71: 2.3165273 | N71: =M71-L71 -> 0 | O71: =N71*K71 -> 0 | P71: 1 | Q71: =P71*L71 -> 2.3165273 | R71: 0 | S71: =R71+S67 -> 319739 | T71: 0 | U71: 0 | V71: LUPOY GP1000ML | X71: 8.302 | Y71: LG | Z71: Printing | AA71: 1.428 | AB71: =M71*R71 -> 0 | AC71: =R71*AA71 -> 0 | AD71: =R71*X71/1000 -> 0
A72: KUMA E-Box NZ | B72: =VLOOKUP(A72,Sheet1!A:B,2,0) -> RCS DEVICE | C72: Button | D72: 130040670021263 | E72: JEE | F72: Unique | G72: Plastic | H72: 2024 | I72: 4 | J72: 45590 | K72: 1 | L72: 0.37651638 | M72: 0.37651638 | N72: =M72-L72 -> 0 | O72: =N72*K72 -> 0 | P72: 1 | Q72: =P72*L72 -> 0.37651638 | R72: 0 | S72: =R72+S68 -> 309375 | T72: 0 | U72: 0 | V72: LUPOY GP1000ML | X72: 0.572 | Y72: LG | AA72: 0 | AB72: =M72*R72 -> 0 | AC72: =R72*AA72 -> 0 | AD72: =R72*X72/1000 -> 0
...

Sheet Capex tracker
A1: Tool type | B1: Soft tool | C1: Soft tool EC | D1: Hard tool | E1: Hard tool EC | G1: 45706
A2: Product category | B2: RCS POD | C2: RCS DEVICE | D2: MODI | E2: HP | F2: MO
A3: Project | B3: Product Category | C3: Part Name | D3: Part No. | E3: Supplier | F3: Year | G3: Month | H3: Stage | I3: Data Submit Date | J3: Cavity | K3: Tooling Capacity Per Month | L3: Total Capacity Per Month | M3: Tooling life | N3: Tool type | O3: Kick off date | P3: Tool Unit cost | Q3: Q'ty | R3: Total Tool cost | S3: Requested by Whom | T3: Approval Status | U3: Payment Status | V3: Remark
A4: VEGA | B4: =VLOOKUP(A4,Sheet1!A:B,2,0) -> MODI | C4: Mouth Piece | D4: 310493191000 | E4: JEE | F4: 2023 | G4: 3 | H4: MP | I4: 45590 | J4: 32 | K4: 1261807.7 | L4: =K4*Q4 -> 8832653.6 | M4: 1000000 | N4: Hard tool | O4: 45012 | P4: 680000 | Q4: 7 | R4: =P4*Q4 -> 4760000 | S4: Srikanth Naule | T4: Approved | U4: Yes
A5: VEGA | B5: =VLOOKUP(A5,Sheet1!A:B,2,0) -> MODI | C5: Top Plastic Bracket | D5: 310493192000 | E5: JEE | F5: 2023 | G5: 3 | H5: MP | I5: 45590 | J5: 48 | K5: 4447872 | L5: =K5*Q5 -> 22239360 | M5: 1000000 | N5: Hard tool | O5: 45012 | P5: 690000 | Q5: 5 | R5: =P5*Q5 -> 3450000 | S5: Srikanth Naule | T5: Approved | U5: Yes
A6: VEGA | B6: =VLOOKUP(A6,Sheet1!A:B,2,0) -> MODI | C6: Bottom Plastic Bracket | D6: 310493193000 | E6: JEE | F6: 2023 | G6: 3 | H6: MP | I6: 45590 | J6: 48 | K6: 2703873.6 | L6: =K6*Q6 -> 13519368 | M6: 1000000 | N6: Hard tool | O6: 45012 | P6: 748000 | Q6: 5 | R6: =P6*Q6 -> 3740000 | S6: Srikanth Naule | T6: Approved | U6: Yes
A7: VEGA | B7: =VLOOKUP(A7,Sheet1!A:B,2,0) -> MODI | C7: Bottom cap | D7: 310493194000 | E7: JEE | F7: 2023 | G7: 3 | H7: MP | I7: 45590 | J7: 48 | K7: 3706560 | L7: =K7*Q7 -> 18532800 | M7: 1000000 | N7: Hard tool | O7: 45012 | P7: 690000 | Q7: 5 | R7: =P7*Q7 -> 3450000 | S7: Srikanth Naule | T7: Approved | U7: Yes
A8: VEGA | B8: =VLOOKUP(A8,Sheet1!A:B,2,0) -> MODI | C8: Air Flow slider | D8: 310493195000 | E8: JEE | F8: 2023 | G8: 3 | H8: MP | I8: 45590 | J8: 48 | K8: 3801600 | L8: =K8*Q8 -> 19008000 | M8: 1000000 | N8: Hard tool | O8: 45012 | P8: 680000 | Q8: 5 | R8: =P8*Q8 -> 3400000 | S8: Srikanth Naule | T8: Approved | U8: Yes
A9: KUMA E-Box NZ | B9: =VLOOKUP(A9,Sheet1!A:B,2,0) -> RCS DEVICE | C9: Top cover | D9: 130040670021260 | E9: JEE | F9: 2024 | G9: 1 | H9: MP | I9: 45590 | J9: 4 | K9: 211822 | L9: =K9*Q9 -> 211822 | M9: 300000 | N9: Soft tool | O9: 45231 | P9: 160000 | Q9: 1 | R9: =P9*Q9 -> 160000 | S9: Chris | T9: Approved | U9: Yes
A10: KUMA E-Box NZ | B10: =VLOOKUP(A10,Sheet1!A:B,2,0) -> RCS DEVICE | C10: Bottom cover | D10: 130040670021261 | E10: JEE | F10: 2024 | G10: 1 | H10: MP | I10: 45590 | J10: 4 | K10: 211822 | L10: =K10*Q10 -> 211822 | M10: 300000 | N10: Soft tool | O10: 45231 | P10: 180000 | Q10: 1 | R10: =P10*Q10 -> 180000 | S10: Chris | T10: Approved | U10: Yes
A11: KUMA E-Box NZ | B11: =VLOOKUP(A11,Sheet1!A:B,2,0) -> RCS DEVICE | C11: Button | D11: 130040670021263 | E11: JEE | F11: 2024 | G11: 1 | H11: MP | I11: 45590 | J11: 4 | K11: 296530 | L11: =K11*Q11 -> 296530 | M11: 300000 | N11: Soft tool | O11: 45231 | P11: 140000 | Q11: 1 | R11: =P11*Q11 -> 140000 | S11: Chris | T11: Approved | U11: Yes
A12: KUMA E-Box NZ | B12: =VLOOKUP(A12,Sheet1!A:B,2,0) -> RCS DEVICE | C12: PCB holder | D12: 130040670021262 | E12: JEE | F12: 2024 | G12: 1 | H12: MP | I12: 45590 | J12: 4 | K12: 296530 | L12: =K12*Q12 -> 296530 | M12: 300000 | N12: Soft tool | O12: 45231 | P12: 180000 | Q12: 1 | R12: =P12*Q12 -> 180000 | S12: Chris | T12: Approved | U12: Yes
A13: KUMA E-Pen 1.0 ROW | B13: =VLOOKUP(A13,Sheet1!A:B,2,0) -> RCS DEVICE | C13: Battery tube | D13: 120020670031773 | E13: JEE | F13: 2024 | G13: 6 | H13: MP | I13: 45590 | J13: 8 | K13: 356448 | L13: =K13*Q13 -> 356448 | M13: 1000000 | N13: Hard tool | O13: 45383 | P13: 280000 | Q13: 1 | R13: =P13*Q13 -> 280000 | S13: Chris | T13: Approved | U13: No
A14: KUMA E-Pen 1.0 ROW | B14: =VLOOKUP(A14,Sheet1!A:B,2,0) -> RCS DEVICE | C14: Bottom cap | D14: 130020670031775 | E14: JEE | F14: 2024 | G14: 6 | H14: MP | I14: 45590 | J14: 16 | K14: 750432 | L14: =K14*Q14 -> 750432 | M14: 1000000 | N14: Hard tool | O14: 45383 | P14: 460000 | Q14: 1 | R14: =P14*Q14 -> 460000 | S14: Chris | T14: Approved | U14: No
A15: KUMA E-Pen 1.0 ROW | B15: =VLOOKUP(A15,Sheet1!A:B,2,0) -> RCS DEVICE | C15: Holder | D15: 130020670031776 | E15: JEE | F15: 2024 | G15: 6 | H15: MP | I15: 45590 | J15: 16 | K15: 893952 | L15: =K15*Q15 -> 893952 | M15: 1000000 | N15: Hard tool | O15: 45383 | P15: 420000 | Q15: 1 | R15: =P15*Q15 -> 420000 | S15: Chris | T15: Approved | U15: No
... A17: KUMA E-Pen 1.0 ROW | B17: =VLOOKUP(A17,Sheet1!A:B,2,0) -> RCS DEVICE | C17: Light guide | D17: 130020670035243 | E17: JEE | F17: 2024 | G17: 6 | H17: MP | I17: 45590 | J17: 16 | K17: 903168 | L17: =K17*Q17 -> 903168 | M17: 1000000 | N17: Hard tool | O17: 45383 | P17: 400000 | Q17: 1 | R17: =P17*Q17 -> 400000 | S17: Chris | T17: Approved | U17: No
A18: Alto Pod | B18: =VLOOKUP(A18,Sheet1!A:B,2,0) -> RCS POD | C18: Cartomizer tube | D18: 130010390000214 | E18: JEE | F18: 2022 | G18: 6 | H18: MP | I18: 45590 | J18: 16 | K18: 1185600 | L18: =K18*Q18 -> 23712000 | M18: 1000000 | N18: Hard tool | O18: 44713 | P18: =7.15*173199.447270021 -> 1238376 | Q18: 20 | R18: =P18*Q18 -> 24767521 | S18: Smoore | T18: Approved | U18: Yes
A19: Alto Pod | B19: =VLOOKUP(A19,Sheet1!A:B,2,0) -> RCS POD | C19: Heating holder | D19: 130010390000215 | E19: JEE | F19: 2022 | G19: 6 | H19: MP | I19: 45590 | J19: 32 | K19: 2695680 | L19: =K19*Q19 -> 21565440 | M19: 1000000 | N19: Hard tool | O19: 44713 | P19: =7.15*179728.993498461 -> 1285062.3 | Q19: 8 | R19: =P19*Q19 -> 10280498 | S19: Smoore | T19: Approved | U19: Yes
A20: Alto Pod | B20: =VLOOKUP(A20,Sheet1!A:B,2,0) -> RCS POD | C20: Heater top cover | D20: 130010390000216 | E20: JEE | F20: 2022 | G20: 6 | H20: MP | I20: 45590 | J20: 32 | K20: 2695680 | L20: =K20*Q20 -> 21565440 | M20: 1000000 | N20: Hard tool | O20: 44713 | P20: =7.15*180678.150274652 -> 1291848.8 | Q20: 8 | R20: =P20*Q20 -> 10334790 | S20: Smoore | T20: Approved | U20: Yes
A21: Alto Pod | B21: =VLOOKUP(A21,Sheet1!A:B,2,0) -> RCS POD | C21: Cartomizer holder tap | D21: 130010390000221 | E21: JEE | F21: 2022 | G21: 6 | H21: MP | I21: 45590 | J21: 32 | K21: 2526368 | L21: =K21*Q21 -> 20210944 | M21: 1000000 | N21: Hard tool | O21: 44713 | P21: =7.15*(585819/6.4305) -> 651365.5 | Q21: 8 | R21: =P21*Q21 -> 5210924 | S21: Smoore | T21: Approved | U21: Yes
A22: Prismatic Pod | B22: =VLOOKUP(A22,Sheet1!A:B,2,0) -> RCS POD | C22: Cartomizer tube | D22: 130010390000214 | E22: JEE | F22: 2023 | G22: 6 | H22: MP | I22: 45590 | J22: 16 | K22: 1185600 | L22: =K22*Q22 -> 1185600 | M22: 1000000 | N22: Hard tool | O22: 45078 | P22: =5424750.84955752-(2800000*30%) -> 4584750.8 | Q22: 1 | R22: =5424750.84955752-(2800000*30%) -> 4584750.8 | S22: Chris | T22: Approved | U22: No | V22: Indonesia
A23: Prismatic Pod | B23: =VLOOKUP(A23,Sheet1!A:B,2,0) -> RCS POD | C23: Cartomizer tube | D23: 130010390000214 | E23: JEE | F23: 2023 | G23: 6 | H23: MP | I23: 45590 | J23: 16 | K23: 1185600 | L23: =K23*Q23 -> 1185600 | M23: 1000000 | N23: Hard tool | O23: 45078 | P23: =5893456.35840708-(2800000*70%) -> 3933456.4 | Q23: 1 | R23: =5893456.35840708-(2800000*70%) -> 3933456.4 | S23: Chris | T23: Approved | U23: No | V23: Indonesia
A24: Prismatic Pod | B24: =VLOOKUP(A24,Sheet1!A:B,2,0) -> RCS POD | C24: Cartomizer tube | D24: 130010390000214 | E24: JEE | F24: 2023 | G24: 6 | H24: MP | I24: 45590 | J24: 16 | K24: 1185600 | L24: =K24*Q24 -> 1185600 | M24: 1000000 | N24: Soft tool | O24: 44927 | P24: 98000 | Q24: 1 | R24: =P24*Q24 -> 98000 | S24: Chris | T24: Approved | U24: No | V24: China
A25: Hyper Pro 2P | B25: =VLOOKUP(A25,Sheet1!A:B,2,0) -> HP | C25: Botton cover | D25: 22150202014 | E25: JEE | F25: 2023 | G25: 1 | H25: MP | I25: 45590 | J25: 16 | K25: 860860 | L25: =K25*Q25 -> 860860 | M25: 1000000 | N25: Hard tool | O25: 44927 | P25: 105000 | Q25: 1 | R25: =P25*Q25 -> 105000 | S25: Chris | T25: Approved | U25: Yes | V25: China
A26: Hyper Pro 2P | B26: =VLOOKUP(A26,Sheet1!A:B,2,0) -> HP | C26: Cleanout door | D26: 22150202015 | E26: JEE | F26: 2023 | G26: 1 | H26: MP | I26: 45590 | J26: 16 | K26: 531960 | L26: =K26*Q26 -> 531960 | M26: 1000000 | N26: Hard tool | O26: 44927 | P26: 376000 | Q26: 1 | R26: =P26*Q26 -> 376000 | S26: Chris | T26: Approved | U26: Yes | V26: China
A27: Hyper Pro 2P | B27: =VLOOKUP(A27,Sheet1!A:B,2,0) -> HP | C27: Button | D27: 22150202010 | E27: JEE | F27: 2023 | G27: 1 | H27: MP | I27: 45590 | J27: 16 | K27: 994136 | L27: =K27*Q27 -> 994136 | M27: 1000000 | N27: Hard tool | O27: 44927 | P27: 98350 | Q27: 1 | R27: =P27*Q27 -> 98350 | S27: Chris | T27: Approved | U27: Yes | V27: China
A28: Hyper Pro 2P | B28: =VLOOKUP(A28,Sheet1!A:B,2,0) -> HP | C28: Crown Support | D28: 22150202008 | E28: JEE | F28: 2023 | G28: 1 | H28: MP | I28: 45590 | J28: 16 | K28: 1129700 | L28: =K28*Q28 -> 1129700 | M28: 1000000 | N28: Hard tool | O28: 44927 | P28: 110600 | Q28: 1 | R28: =P28*Q28 -> 110600 | S28: Chris | T28: Approved | U28: Yes | V28: China
A29: Hyper Pro 2P | B29: =VLOOKUP(A29,Sheet1!A:B,2,0) -> HP | C29: Connector frame | D29: 22150202017 | E29: JEE | F29: 2023 | G29: 1 | H29: MP | I29: 45590 | J29: 16 | K29: 1141140 | L29: =K29*Q29 -> 1141140 | M29: 1000000 | N29: Hard tool | O29: 44927 | P29: 98000 | Q29: 1 | R29: =P29*Q29 -> 98000 | S29: Chris | T29: Approved | U29: Yes | V29: China
A30: Hyper Pro 2P | B30: =VLOOKUP(A30,Sheet1!A:B,2,0) -> HP | C30: Spin Wheel | D30: 22150202009 | E30: JEE | F30: 2023 | G30: 1 | H30: MP | I30: 45590 | J30: 16 | K30: 988416 | L30: =K30*Q30 -> 988416 | M30: 1000000 | N30: Hard tool | O30: 44927 | P30: 98000 | Q30: 1 | R30: =P30*Q30 -> 98000 | S30: Chris | T30: Approved | U30: Yes | V30: China
A31: Hyper Pro 2P | B31: =VLOOKUP(A31,Sheet1!A:B,2,0) -> HP | C31: Display bracket | D31: 22150202021 | E31: JEE | F31: 2023 | G31: 1 | H31: MP | I31: 45590 | J31: 16 | K31: 1251978 | L31: =K31*Q31 -> 1251978 | M31: 1000000 | N31: Hard tool | O31: 44927 | P31: 200100 | Q31: 1 | R31: =P31*Q31 -> 200100 | S31: Chris | T31: Approved | U31: Yes | V31: China
A32: Hyper Pro 2P | B32: =VLOOKUP(A32,Sheet1!A:B,2,0) -> HP | C32: PCBA Bracket | D32: 22150202018 | E32: JEE | F32: 2023 | G32: 1 | H32: MP | I32: 45590 | J32: 16 | K32: 1065064 | L32: =K32*Q32 -> 1065064 | M32: 1000000 | N32: Hard tool | O32: 44927 | P32: 98000 | Q32: 1 | R32: =P32*Q32 -> 98000 | S32: Chris | T32: Approved | U32: Yes | V32: China
A33: Hyper Pro 2P | B33: =VLOOKUP(A33,Sheet1!A:B,2,0) -> HP | C33: Shut Door | D33: 22150202007 | E33: JEE | F33: 2023 | G33: 1 | H33: MP | I33: 45590 | J33: 16 | K33: 1129700 | L33: =K33*Q33 -> 1129700 | M33: 1000000 | N33: Hard tool | O33: 44927 | P33: 130350 | Q33: 1 | R33: =P33*Q33 -> 130350 | S33: Chris | T33: Approved | U33: Yes | V33: China
A34: Hyper Core | B34: =VLOOKUP(A34,Sheet1!A:B,2,0) -> HP | C34: Crown Support | D34: 23590202001 | E34: JEE | F34: 2023 | G34: 1 | H34: MP | I34: 45590 | J34: 16 | K34: 50284 | L34: =K34*Q34 -> 50284 | M34: 1000000 | N34: Hard tool | O34: 44927 | P34: 98000 | Q34: 1 | R34: =P34*Q34 -> 98000 | S34: Chris | T34: Approved | U34: Yes | V34: China
A35: Hyper Core | B35: =VLOOKUP(A35,Sheet1!A:B,2,0) -> HP | C35: Connector frame | D35: 23480202015 | E35: JEE | F35: 2023 | G35: 1 | H35: MP | I35: 45590 | J35: 16 | K35: 1251978 | L35: =K35*Q35 -> 1251978 | M35: 1000000 | N35: Hard tool | O35: 44927 | P35: 188000 | Q35: 1 | R35: =P35*Q35 -> 188000 | S35: Chris | T35: Approved | U35: Yes | V35: China
A36: Hyper Core | B36: =VLOOKUP(A36,Sheet1!A:B,2,0) -> HP | C36: Battery carrier | D36: 23480202012 | E36: JEE | F36: 2023 | G36: 1 | H36: MP | I36: 45590 | J36: 4 | K36: 260832 | L36: =K36*Q36 -> 521664 | M36: 1000000 | N36: Hard tool | O36: 44927 | P36: 320000 | Q36: 2 | R36: =P36*Q36 -> 640000 | S36: Chris | T36: Approved | U36: No | V36: China
... A40: Hyper Core | B40: =VLOOKUP(A40,Sheet1!A:B,2,0) -> HP | C40: Light guide | D40: 23480202018 | E40: JEE | F40: 2023 | G40: 1 | H40: MP | I40: 45590 | J40: 16 | K40: 665808 | L40: =K40*Q40 -> 665808 | M40: 1000000 | N40: Hard tool | O40: 44927 | P40: 452729 | Q40: 1 | R40: =P40*Q40 -> 452729 | S40: Chris | T40: Approved | U40: No | V40: China
A41: Hyper Pro 2P | B41: =VLOOKUP(A41,Sheet1!A:B,2,0) -> HP | C41: Crown Support | D41: 22150202008 | E41: JEE | F41: 2023 | G41: 10 | H41: MP | I41: 45590 | L41: =K41*Q41 -> 0 | N41: Hard tool EC | O41: 45210 | P41: 12600 | Q41: 1 | R41: =P41*Q41 -> 12600 | S41: Chris | T41: Approved | U41: No | V41: China
A42: Hyper Core | B42: =VLOOKUP(A42,Sheet1!A:B,2,0) -> HP | C42: Light guide | D42: 23480202018 | E42: JEE | F42: 2023 | G42: 10 | H42: MP | I42: 45590 | L42: =K42*Q42 -> 0 | N42: Hard tool EC | O42: 45220 | P42: 53870 | Q42: 1 | R42: =P42*Q42 -> 53870 | S42: Chris | T42: Approved | U42: No | V42: China
A43: Hyper Core | B43: =VLOOKUP(A43,Sheet1!A:B,2,0) -> HP | C43: Shutter Door Support | D43: 23480202005 | E43: JEE | F43: 2023 | G43: 10 | H43: MP | I43: 45590 | L43: =K43*Q43 -> 0 | N43: Hard tool EC | O43: 45223 | P43: 35296 | Q43: 1 | R43: =P43*Q43 -> 35296 | S43: Chris | T43: Approved | U43: No | V43: China
A44: Hyper Core | B44: =VLOOKUP(A44,Sheet1!A:B,2,0) -> HP | C44: Button | D44: 23480202017 | E44: JEE | F44: 2023 | G44: 10 | H44: MP | I44: 45590 | L44: =K44*Q44 -> 0 | N44: Hard tool EC | O44: 45209 | P44: 207000 | Q44: 1 | R44: =P44*Q44 -> 207000 | S44: Chris | T44: Approved | U44: No | V44: China
...

Sheet Sheet1
A1: Project | B1: Product category
A2: Vega | B2: MODI | C2: Commodity | D2: Approval Status | E2: Payment Status | F2: Stage | G2: Tool type | H2: CMF Type | I2: Year | J2: Month | L2: Requested by Who | O2: Product Category
A3: Box 8000 1.0 | B3: MODI | C3: Plastic | D3: Approved | E3: Yes | F3: POP | G3: Soft tool | H3: Painting | I3: 2022 | J3: 1 | L3: Chris | O3: RCS POD
A4: DP1500 | B4: MODI | C4: Metal | D4: Not Approved | E4: No | F4: POA | G4: Soft tool EC | H4: Anodizing | I4: 2023 | J4: 2 | L4: Candy | O4: RCS DEVICE
A5: Pen 800 Default 2.0 | B5: MODI | C5: Silicone | F5: POC | G5: Hard tool | H5: Printing | I5: 2024 | J5: 3 | L5: Charlie | O5: MODI
A6: Pen 800 Full 2.0 | B6: MODI | C6: Die-cut | F6: DP-SP | G6: Hard tool EC | H6: Others | I6: 2025 | J6: 4 | O6: HP
A7: Box 800 Default 2.0 | B7: MODI | C7: Magnet | F7: MP | G7: Others | I7: 2026 | J7: 5 | O7: MO
A8: Box 800 Full 2.0 | B8: MODI | C8: Others | I8: 2027 | J8: 6
A9: Box 3000 Full 2.0 | B9: MODI | I9: 2028 | J9: 7
A10: Box 5000 Full 2.0 | B10: MODI | I10: 2029 | J10: 8
A11: Sensa 5K | B11: MODI | I11: 2030 | J11: 9
A12: Box 8000 Full 2.0 | B12: MODI | I12: 2031 | J12: 10
A13: Alto Pod | B13: RCS POD | I13: 2032 | J13: 11
A14: ePod/epod2 cartridge | B14: RCS POD | I14: 2033 | J14: 12
A15: Prismatic Pod | B15: RCS POD | C15: before | D15: after | I15: 2034
A16: Hyper Pro 2P | B16: HP | C16: Hyper Pro 2P | D16: X3 2P
A17: Hyper Core | B17: HP | C17: Hyper Core | D17: X3 Core
A18: Hyper Pro | B18: HP | C18: Hyper Pro | D18: X3 1P
A19: Artemis 1P | B19: HP
A20: Artemis 2P | B20: HP
A21: Artemis BRUSH | B21: HP
A22: Artemis 1.1 CORE | B22: HP
A23: Artemis 1.1 PRO | B23: HP
A24: Clyde POD | B24: HP
A25: Clyde RCS DEVICE | B25: HP
A26: Bacchus | B26: HP
A27: Adonis 1P | B27: HP
A28: Adonis 2P | B28: HP
A29: 1K BOX ESG | B29: MODI
A30: 1K BOX SEMI | B30: MODI
... A42: ePod 3+ | B42: RCS POD
A43: ePod2 Catridges
A44: ePod2 device(Wave1) | B44: RCS DEVICE
A45: ePod2+ device | B45: RCS DEVICE
A46: ePod 3 Device | B46: RCS DEVICE
A47: ePod 3 descope
A48: ePod 3+ Device | B48: RCS DEVICE
A49: KUMA E-Box NZ | B49: RCS DEVICE
A50: KUMA E-Box ROW | B50: RCS DEVICE
A51: KUMA E-Pen 1.0 ROW | B51: RCS DEVICE
...

Sheet Capex summary Dec 2024
B3: Column Labels
B4: Hard tool | C4: Hard tool EC | D4: Soft tool | E4: Soft tool EC | F4: Grand Total
A5: Sum of Total Tool cost | B5: 1.0124147e+08 | C5: 381309 | D5: 3479218.3 | E5: 2259022.3 | F5: 1.0736102e+08
