Workbook
Name \A: #REF!
Name \A: #REF!
Name \C: #REF!
Name \C: #REF!
Name \D: #REF!
Name \D: #REF!
Name \W: #REF!
Name \W: #REF!
Name _: #REF!
Name _: #REF!
Name __: #REF!
Name __: #REF!
Name ___: #REF!
Name ___: #REF!
Name ______0: #REF!
Name ______0: #REF!
Name ______0___0: #REF!
Name ______0___0: #REF!
Name ______4: "$"
Name ______5: "$"
Name ______6: "$"
Name __m72: {"傳各位表單.xls","Sheet1"}
Name __m72: {"傳各位表單.xls","Sheet1"}
Name __m72_1: {"傳各位表單.xls","Sheet1"}
Name __m72_1: {"傳各位表單.xls","Sheet1"}
Name __m72_2: {"傳各位表單.xls","Sheet1"}
Name __m72_2: {"傳各位表單.xls","Sheet1"}
Name __m72_3: {"傳各位表單.xls","Sheet1"}
Name __m72_3: {"傳各位表單.xls","Sheet1"}
Name __m72_4: {"傳各位表單.xls","Sheet1"}
Name __m72_4: {"傳各位表單.xls","Sheet1"}
Name _017: #REF!
Name _017: #REF!
Name _024: #REF!
Name _024: #REF!
Name _039: #REF!
Name _039: #REF!
Name _1.: #REF!
Name _1.: #REF!
Name _1_0: #REF!
Name _1_0: #REF!
Name _17__cycle_time: #REF!
Name _17__cycle_time: #REF!
Name _1A: #REF!
Name _1A: #REF!
Name _2_00: #REF!
Name _2_00: #REF!
Name _20__cycle_time: #REF!
Name _20__cycle_time: #REF!
Name _2C_: #REF!
Name _2C_: #REF!
Name _3_000: #REF!
Name _3_000: #REF!
Name _3D: #REF!
Name _3D: #REF!
Name _4W: #REF!
Name _4W: #REF!
Name _AB12: #REF!
Name _AB12: #REF!
Name _RMX1: #REF!

Sheet Pivot
B2: Liabilities Dashboard
B3: Summary
F5: Values
B6: Project | C6: Description Item | D6: Start Date | E6: End Date | F6: Sum of Investment (GBP) | G6: Sum of Balance (GBP) Nov'24
B7: Alto | C7: Addendum No.10 - Indonesia | D7: 44682 | F7: 33083222 | G7: 20218013
C8: Addendum No.10 - Indonesia Total | F8: 33083222 | G8: 20218013
C9: Alto Blister Reduction Capex | D9: 45588 | F9: 712555.8 | G9: 655272.72
C10: Alto Blister Reduction Capex Total | F10: 712555.8 | G10: 655272.72
C11: Alto Pod Investment fee for Inkjet printing | D11: 45344 | F11: 1624734.3
C12: Alto Pod Investment fee for Inkjet printing Total | F12: 1624734.3
C13: Alto tooling | D13: 44857 | F13: 7011014.5 | G13: 0
C14: Alto tooling Total | F14: 7011014.5 | G14: 0
C15: Alto tooling(IM tooling for 2p cost reduction) | D15: 44980 | F15: 4099802.5 | G15: 0
C16: Alto tooling(IM tooling for 2p cost reduction) Total | F16: 4099802.5 | G16: 0
C17: Device to Indo Equipment move cost | D17: 45345 | F17: 522701.32 | G17: 313714.88
C18: Device to Indo Equipment move cost Total | F18: 522701.32 | G18: 313714.88
C19: Prismastic China project capex | D19: - | F19: 177315.67
C20: Prismastic China project capex Total | F20: 177315.67
B21: Alto Total | F21: 47231346 | G21: 21187001
B22: Alto & Hestia & Epod | F22: 57899223 | G22: 17249276
B23: Aquila-US | F23: 168020.31 | G23: 168020.31
B24: BOX 1K | F24: 445583.44 | G24: 293264.27
B25: DP 1500 | F25: 850699.38 | G25: 172500.96
B26: epod 2 Device | F26: 61960.751 | G26: 0
B27: Epod 3 | F27: 92759.557 | G27: 0
B28: epod 3 Device | F28: 172492.38 | G28: 127582.86
B29: Epod 3+ | F29: 153994.03 | G29: 0
B30: epod 3+ Device | F30: 217261.05 | G30: 206107.17
B31: Epod&Modi | F31: 81025.598 | G31: 37497.213
B32: ePod2 POD | F32: 2669816.1 | G32: 0
... B37: Kuma | F37: 1239135.6 | G37: 1095337.6
B38: Kuma | F38: 0
B39: Kuma E 2.0 | F39: 1010585.6 | G39: 1010585.6
B40: Kuma E 2.0 Box | F40: 66034.728 | G40: 66034.728
B41: Kuma E 2.0 Pen NZ | F41: 81241.212 | G41: 81241.212
B42: Kuma E Max | F42: 78619.796 | G42: 78619.796
B43: Mimosa 1.0 | F43: 1177357 | G43: 1177357
B44: Mimosa Smart Box PB88 | F44: 192713.82 | G44: 192713.82
B45: Modi | F45: 327949.16 | G45: 309519.5
B46: Modi 2.0 | F46: 7928735.4 | G46: 6770218.6
...

Sheet By Project -Feb 2025
Q1: CNY | R1: GBP
C2: Investment/Liabilities Dashboard | Q2: =34746341 -> 34746341 | R2: =Q2/8.812 -> 3943070.9
C3: New Categories - Vapour | Q3: 24216741 | R3: =Q3/8.812 -> 2748154.9
R4: =SUM(R2:R3) -> 6691225.8
A5: USD-GBP | B5: 1.27818
A6: RMB-GBP | B6: 9.19774 | AS6: SC update
AA7: Tooling Capex | AB7: Tooling Capex | AC7: Tooling Capex | AD7: Tooling Capex | AE7: Actual Shipment Qty | AT7: Forecast (pls link tab'Summary') | BH7: BAT Demand Waterfall
A9: # | B9: Unique Ref Number | C9: Project | D9: Project Description | E9: Portfolio | F9: Platform | G9: Location | H9: Type | I9: Portfolio1 | J9: Tier | K9: Supplier | L9: Contracting Entity | M9: Start Date | N9: End Date | O9: Investment Quotation | P9: Investment Currency | Q9: Investment (GBP) | R9: Committed PO Volume | S9: Amortization per Unit | T9: Payment Type | U9: Amortization _x000D_ per Unit (GBP) | V9: Cumulative Vol. (from start date) | W9: % Finished | X9: Balance(Feb'25) | Y9: Balance1 | Z9: Status | AA9: % Finished | AB9: Total Paid Investment Currency | AC9: Balance2 | AD9: Remaining Vol required | AE9: Y2021 | AF9: Y2022 | AG9: Y2023 | AH9: 45292 | AI9: 45323 | AJ9: 45352 | AK9: 45383 | AL9: 45413 | AM9: 45444 | AN9: 45474 | AO9: 45505 | AP9: 45536 | AQ9: 45566 | AR9: 45597 | AS9: 45627 | AT9: 45658 | AU9: 45689 | AV9: 45717 | AW9: 45748 | AX9: 45778 | AY9: 45809 | AZ9: 45839 | BA9: 45870 | BB9: 45901 | BC9: 45931 | BD9: 45962 | BE9: 45992 | BF9: YTG 2025 | BH9: T2 Product | BI9: Version | BJ9: Customer | BK9: SOP Date | BL9: Product | BM9: 2021 | BN9: 2022 | BO9: 2023 | BP9: 2024 | BQ9: 44197 | BR9: 44228 | BS9: 44256 | BT9: 44287 | BU9: 44317 | BV9: 44348 | BW9: 44378 | BX9: 44409 | BY9: 44440 | BZ9: 44470 | CA9: 44501 | CB9: 44531 | CD9: 44562 | CE9: 44593 | CF9: 44621 | CG9: 44652 | CH9: 44682 | CI9: 44713 | CJ9: 44743 | CK9: 44774 | CL9: 44805 | CM9: 44835 | CN9: 44866 | CO9: 44896 | CP9: 44927 | CQ9: 44958 | CR9: 44986 | CS9: 45017 | CT9: 45047 | CU9: 45078 | CV9: 45108 | CW9: 45139 | CX9: 45170 | CY9: 45200 | CZ9: 45231 | DA9: 45261 | DB9: 45292 | DC9: 45323 | DD9: 45352 | DE9: 45383 | DF9: 45413 | DG9: 45444 | DH9: 45474 | DI9: 45505 | DJ9: 45536 | DK9: 45566 | DL9: 45597 | DM9: 45627 | DN9: 45658 | DO9: 45689 | DP9: 45717 | DQ9: 45748 | DR9: 45778 | DS9: 45809 | DT9: 45839 | DU9: 45870 | DV9: 45901 | DW9: 45931 | DX9: 45962 | DY9: 45992
A10: 1 | B10: RF001_Alto &ePod | C10: Alto & ePod | D10: APA - Automation Production Agreement | E10: Pod | F10: Pod | G10: Indo | H10: Pod Automation (initial Investment) | I10: RCS | J10: T1 | K10: Smoore T1 | L10: Reynolds | M10: 44197 | N10: 46722 | O10: 72000000 | P10: USD | Q10: =IF(P10="RMB",O10/$B$6,IF(P10="GBP",O10,O10/$B$5)) -> 56330094 | R10: 2570000000 | S10: Volume | T10: By Volume | U10: =IF(T10="By Unit", IF(P10="RMB",S10/$B$6,IF(P10="GBP",S10,S10/$B$5)),T10) -> By Volume | V10: =SUM(AE10:AU10) -> 1940686118 | W10: =IF($T10="By Volume",V10/$R10,V10*$U10/$Q10) -> 0.75513079 | X10: =IFERROR($Q10*(1-W10),"") -> 13793506 | Y10: =IF(X10>0,X10,0) -> 13793506 | Z10: Under Amortization | AD10: =IF(U10="By Volume",(1-W10)*R10,X10/U10) -> 629313882 | AE10: 523716080 | AF10: 471530346 | AG10: 404870290 | AH10: 34094250 | AI10: 27982380 | AJ10: 35881250 | AK10: 33715264 | AL10: 49761762 | AM10: 49968522 | AN10: 46294918 | AO10: 57860634 | AP10: 36903554 | AQ10: 32308514 | AR10: 34612990 | AS10: 28195840 | AT10: ='By Project -Feb 2025'!DN10+'By Project -Feb 2025'!DN11+'By Project -Feb 2025'!DN22+'By Project -Feb 2025'!DN34+'By Project -Feb 2025'!DN59+'By Project -Feb 2025'!DN62 -> 48220474 | AU10: ='By Project -Feb 2025'!DO10+'By Project -Feb 2025'!DO11+'By Project -Feb 2025'!DO22+'By Project -Feb 2025'!DO34+'By Project -Feb 2025'!DO59+'By Project -Feb 2025'!DO62 -> 24769050 | AV10: ='By Project -Feb 2025'!DP10+'By Project -Feb 2025'!DP11+'By Project -Feb 2025'!DP22+'By Project -Feb 2025'!DP34+'By Project -Feb 2025'!DP59+'By Project -Feb 2025'!DP62 -> 67126382 | AW10: ='By Project -Feb 2025'!DQ10+'By Project -Feb 2025'!DQ11+'By Project -Feb 2025'!DQ22+'By Project -Feb 2025'!DQ34+'By Project -Feb 2025'!DQ59+'By Project -Feb 2025'!DQ62 -> 61797920 | AX10: ='By Project -Feb 2025'!DR10+'By Project -Feb 2025'!DR11+'By Project -Feb 2025'!DR22+'By Project -Feb 2025'!DR34+'By Project -Feb 2025'!DR59+'By Project -Feb 2025'!DR62 -> 42129688 | AY10: ='By Project -Feb 2025'!DS10+'By Project -Feb 2025'!DS11+'By Project -Feb 2025'!DS22+'By Project -Feb 2025'!DS34+'By Project -Feb 2025'!DS59+'By Project -Feb 2025'!DS62 -> 42064888 | AZ10: ='By Project -Feb 2025'!DT10+'By Project -Feb 2025'!DT11+'By Project -Feb 2025'!DT22+'By Project -Feb 2025'!DT34+'By Project -Feb 2025'!DT59+'By Project -Feb 2025'!DT62 -> 45832074 | BA10: ='By Project -Feb 2025'!DU10+'By Project -Feb 2025'!DU11+'By Project -Feb 2025'!DU22+'By Project -Feb 2025'!DU34+'By Project -Feb 2025'!DU59+'By Project -Feb 2025'!DU62 -> 50460345 | ... BE10: ='By Project -Feb 2025'!DY10+'By Project -Feb 2025'!DY11+'By Project -Feb 2025'!DY22+'By Project -Feb 2025'!DY34+'By Project -Feb 2025'!DY59+'By Project -Feb 2025'!DY62 -> 46771803 | BF10: =SUM(AV10:BE10) -> 4.9956899e+08 | BH10: epod2 pod | BI10: SOP01.0 | BJ10: BAT | BK10: 45698 | BL10: ePod2 Cartridges | BM10: 150444920 | BN10: 202559713 | BO10: 91785440 | BP10: 12656900 | BQ10: 9366300 | BR10: 5088060 | BS10: 10606320 | BT10: 9598860 | BU10: 14671980 | BV10: 14349580 | BW10: 12979220 | BX10: 15256580 | BY10: 15964420 | BZ10: 12569000 | CA10: 15497160 | CB10: 14497440 | CD10: 15559440 | CE10: 12012360 | CF10: 18465130 | CG10: 19798430 | CH10: 20944920 | CI10: 17632262 | CJ10: 15720521 | CK10: 13104480 | CL10: 29618660 | CM10: 11285460 | CN10: 13803750 | CO10: 14614300 | CP10: 8764100 | CQ10: 8606700 | CR10: 16334000 | CS10: 12069960 | CT10: 7439980 | CU10: 7699880 | CV10: 3856460 | CW10: 4664000 | CX10: 6591860 | CY10: 4137070 | CZ10: 7758370 | DA10: 3863060 | DB10: 4132280 | DC10: 2737600 | DD10: 3241380 | DE10: 839240 | DF10: 607680 | DG10: 543780 | DH10: 136620 | DI10: 20160 | DJ10: 20160 | DK10: 0 | DL10: 216720 | DM10: 161280 | DN10: 0 | DO10: 15120 | DP10: 20160 | DQ10: 65520 | DR10: 0 | DS10: 0 | DT10: 0 | DU10: 0 | DV10: 0 | DW10: 0 | DX10: 0 | DY10: 0 | EA10: APA - Automation Production Agreement
A11: 2 | B11: RF002_Alto | C11: Alto | D11: Addendum No.10 - Indonesia | E11: Pod | F11: Pod | G11: Indo | H11: Indo Facility | I11: RCS | J11: T1 | K11: Smoore T1 | L11: Reynolds | M11: 44682 | N11: 46722 | O11: 41140309 | P11: USD | Q11: =IF(P11="RMB",O11/$B$6,IF(P11="GBP",O11,O11/$B$5)) -> 32186632 | R11: 2340000000 | S11: 0.0152 | T11: By Unit | U11: =IF(T11="By Unit", IF(P11="RMB",S11/$B$6,IF(P11="GBP",S11,S11/$B$5)),T11) -> 0.011891909 | V11: =SUM(AE11:AU11) -> 750520050 | W11: =((328822613*0.0321)+(V11-328822613)*S11)/O11 -> 0.41236945 | X11: =IFERROR(Q11*(1-W11),"") -> 18913848 | Y11: =IF(X11>0,X11,0) -> 18913848 | Z11: Under Amortization | AD11: =IF(U11="By Volume",(1-W11)*R11,X11/U11) -> 1.5904804e+09 | AF11: 195500900 | AG11: 255515000 | AH11: 22785000 | AI11: 22092200 | AJ11: 25589000 | AK11: 18498600 | AL11: 30742700 | AM11: 18494250 | AN11: 25532300 | AO11: 28932600 | AP11: 11088600 | AQ11: 14612550 | AR11: 17543850 | AS11: 18060400 | AT11: =DN59+DN62 -> 29540200 | AU11: =DO59+DO62 -> 15991900 | AV11: =DP59+DP62 -> 46417950 | AW11: =DQ59+DQ62 -> 39955200 | AX11: =DR59+DR62 -> 25506950 | AY11: =DS59+DS62 -> 21583600 | AZ11: =DT59+DT62 -> 27502550 | BA11: =DU59+DU62 -> 22651600 | ... BE11: =DY59+DY62 -> 25626000 | BF11: =SUM(AV11:BE11) -> 276304400 | BH11: ePod 3 Pod | BI11: SOP01.0 | BJ11: BAT | BK11: 45698 | BL11: ePod3 Cartridges | BM11: 0 | BN11: 0 | BO11: 49538050 | BP11: 52288270 | CD11: 0 | CE11: 0 | CF11: 0 | CG11: 0 | CH11: 0 | CI11: 0 | CJ11: 0 | CK11: 0 | CL11: 0 | CM11: 0 | CN11: 0 | CO11: 0 | CP11: 0 | CQ11: 0 | CR11: 136620 | CS11: 1201500 | CT11: 2856870 | CU11: 5365530 | CV11: 6736500 | CW11: 6646410 | CX11: 9393120 | CY11: 8034750 | CZ11: 6721830 | DA11: 2444920 | DB11: 7133770 | DC11: 3013380 | DD11: 6978870 | DE11: 4888410 | DF11: 4624920 | DG11: 6254730 | DH11: 5871600 | DI11: 5959710 | DJ11: 5151780 | DK11: 2354220 | DL11: 56880 | DM11: 0 | DN11: 196560 | DO11: 0 | DP11: 0 | DQ11: 0 | DR11: 0 | DS11: 0 | DT11: 0 | DU11: 0 | DV11: 0 | DW11: 0 | DX11: 0 | DY11: 0 | EA11: APA - Automation Production Agreement
A12: 4 | B12: RF003_Alto | C12: Alto | D12: Alto Pod Investment fee for Inkjet printing | E12: Pod | F12: Pod | G12: Indo | H12: Asset - Others | I12: RCS | J12: T1 | K12: Smoore T1 | L12: Reynolds | M12: 45344 | N12: - | O12: 2020422.1 | P12: USD | Q12: =IF(P12="RMB",O12/$B$6,IF(P12="GBP",O12,O12/$B$5)) -> 1580702.4 | R12: 0 | S12: n/a | U12: =IF(T12="By Unit", IF(P12="RMB",S12/$B$6,IF(P12="GBP",S12,S12/$B$5)),T12) -> 0 | V12: =SUM(AE12:AS12) -> 0 | W12: =1-X12/Q12 -> 1 | X12: 0 | Y12: 0 | Z12: Paid-off | BF12: =SUM(AV12:BE12) -> 0 | BH12: Hestia 1.0 | BI12: SOP01.0 | BJ12: BAT | BK12: 45698 | BL12: Hestia | BM12: 0 | BN12: 0 | BO12: 0 | BP12: 119534880 | CD12: 0 | CE12: 0 | CF12: 0 | CG12: 0 | CH12: 0 | CI12: 0 | CJ12: 0 | CK12: 0 | CL12: 0 | CM12: 0 | CN12: 0 | CO12: 0 | CP12: 0 | CQ12: 0 | CR12: 0 | CS12: 0 | CT12: 0 | CU12: 0 | CV12: 0 | CW12: 0 | CX12: 0 | CY12: 0 | CZ12: 0 | DA12: 0 | DB12: 0 | DC12: 0 | DD12: 0 | DE12: 4141170 | DF12: 10303470 | DG12: 18112860 | DH12: 12666060 | DI12: 17188320 | DJ12: 15151590 | DK12: 12838860 | DL12: 13199850 | DM12: 15932700 | DN12: 17350470 | DO12: 7948260 | DP12: 19106540 | DQ12: 20397590 | DR12: 14871760 | DS12: 18739530 | DT12: 17118810 | DU12: 26215830 | DV12: 23149370 | DW12: 21619420 | DX12: 27275260 | DY12: 19757020 | EA12: Hestia 1.0 Automation Lines Modification (Modified from ePod3 to Hestia1.0) (1-4 line)
A13: 5 | B13: RF004_Alto | C13: Alto | D13: Device to Indo Equipment move cost | E13: RCS | F13: Vuse Device( US Alto) | G13: Indo | H13: Asset - RCS Device line | I13: RCS | J13: T1 | K13: Smoore T1 | L13: Reynolds | M13: 45345 | N13: 46722 | O13: 650000 | P13: USD | Q13: =IF(P13="RMB",O13/$B$6,IF(P13="GBP",O13,O13/$B$5)) -> 508535.57 | R13: 20000000 | S13: 0.032288552 | T13: By Unit | U13: =IF(T13="By Unit", IF(P13="RMB",S13/$B$6,IF(P13="GBP",S13,S13/$B$5)),T13) -> 0.02526135 | V13: =SUM(AE13:AU13) -> 11689500 | W13: =IF(T13="By Volume",V13/R13,V13*U13/Q13) -> 0.58067235 | X13: =IFERROR(Q13*(1-W13),"") -> 213243.03 | Y13: =IF(X13>0,X13,0) -> 213243.03 | Z13: Under Amortization | AD13: =IF(U13="By Volume",(1-W13)*R13,X13/U13) -> 8441474 | AI13: 816200 | AJ13: 663600 | AK13: 138600 | AL13: 662000 | AM13: 213750 | AN13: 845900 | AO13: 950400 | AP13: 1489800 | AQ13: 1329750 | AR13: 886650 | AS13: 1550250 | AT13: ='By Project -Feb 2025'!DN57+'By Project -Feb 2025'!DN58 -> 1243800 | AU13: ='By Project -Feb 2025'!DO57+'By Project -Feb 2025'!DO58 -> 898800 | AV13: ='By Project -Feb 2025'!DP57+'By Project -Feb 2025'!DP58 -> 924150 | AW13: ='By Project -Feb 2025'!DQ57+'By Project -Feb 2025'!DQ58 -> 466200 | AX13: ='By Project -Feb 2025'!DR57+'By Project -Feb 2025'!DR58 -> 1068350 | AY13: ='By Project -Feb 2025'!DS57+'By Project -Feb 2025'!DS58 -> 721000 | AZ13: ='By Project -Feb 2025'!DT57+'By Project -Feb 2025'!DT58 -> 869750 | BA13: ='By Project -Feb 2025'!DU57+'By Project -Feb 2025'!DU58 -> 750400 | ... BE13: ='By Project -Feb 2025'!DY57+'By Project -Feb 2025'!DY58 -> 802200 | BF13: =SUM(AV13:BE13) -> 8017400 | BH13: Hestia 1.1 | BI13: SOP01.0 | BJ13: BAT | BK13: 45698 | BL13: Hestia 1.1 | BM13: 0 | BN13: 0 | BO13: 0 | BP13: 0 | DB13: 0 | DC13: 0 | DD13: 0 | DE13: 0 | DF13: 0 | DG13: 0 | DH13: 0 | DI13: 0 | DJ13: 0 | DK13: 0 | DL13: 0 | DM13: 0 | DN13: 0 | DO13: 0 | DP13: 0 | DQ13: 0 | DR13: 0 | DS13: 0 | DT13: 0 | DU13: 0 | DV13: 0 | DW13: 0 | DX13: 0 | DY13: 0
A14: 6 | B14: RF005_Alto | C14: Alto | D14: Alto Blister Reduction Capex | E14: Pod | F14: Pod | G14: Indo | H14: Asset - Others | I14: RCS | J14: T1 | K14: Smoore T1 | L14: Reynolds | M14: 45597 | N14: 46722 | O14: 886091.64 | P14: USD | Q14: =IF(P14="RMB",O14/$B$6,IF(P14="GBP",O14,O14/$B$5)) -> 693244.8 | R14: 400000000 | S14: =O14/R14 -> 0.0022152291 | T14: By Unit | U14: =IF(T14="By Unit", IF(P14="RMB",S14/$B$6,IF(P14="GBP",S14,S14/$B$5)),T14) -> 0.001733112 | V14: =SUM(AE14:AU14) -> 76591800 | W14: =IF(T14="By Volume",V14/R14,V14*U14/Q14) -> 0.1914795 | X14: =IFERROR(Q14*(1-W14),"") -> 560502.63 | Y14: =IF(X14>0,X14,0) -> 560502.63 | Z14: Under Amortization | AD14: =IF(U14="By Volume",(1-W14)*R14,X14/U14) -> 3.234082e+08 | AR14: 16056000 | AS14: 13005000 | AT14: 30684600 | AU14: 16846200 | AV14: ='By Project -Feb 2025'!DP59*98% -> 45442551 | AW14: ='By Project -Feb 2025'!DQ59*98% -> 39156096 | AX14: ='By Project -Feb 2025'!DR59*98% -> 24996811 | AY14: ='By Project -Feb 2025'!DS59*98% -> 21151928 | AZ14: ='By Project -Feb 2025'!DT59*98% -> 26787859 | BA14: ='By Project -Feb 2025'!DU59*98% -> 22033928 | BB14: ='By Project -Feb 2025'!DV59*98% -> 20502139 | BC14: ='By Project -Feb 2025'!DW59*98% -> 24815952 | ... BE14: ='By Project -Feb 2025'!DY59*98% -> 24784200 | BF14: =SUM(AV14:BE14) -> 269216584 | BH14: Hestia 1.1 Premium | BI14: SOP01.0 | BJ14: BAT | BK14: 45698 | BL14: Hestia 1.1 Premium | BM14: 0 | BN14: 0 | BO14: 0 | BP14: 0 | DB14: 0 | DC14: 0 | DD14: 0 | DE14: 0 | DF14: 0 | DG14: 0 | DH14: 0 | DI14: 0 | DJ14: 0 | DK14: 0 | DL14: 0 | DM14: 0 | DN14: 0 | DO14: 29970 | DP14: 576000 | DQ14: 811150 | DR14: 1104660 | DS14: 817540 | DT14: 476460 | DU14: 606300 | DV14: 610230 | DW14: 481710 | DX14: 582030 | DY14: 613260
A15: 7 | B15: RF006_Alto | C15: Prismatic Pod | D15: Prismastic China project capex | E15: Pod | F15: Pod | G15: Indo | H15: Asset - Others | I15: RCS | J15: T1 | K15: Smoore T1 | L15: Reynolds | M15: - | N15: - | O15: 1562511 | P15: RMB | Q15: =IF(P15="RMB",O15/$B$6,IF(P15="GBP",O15,O15/$B$5)) -> 169879.88 | S15: Volume | T15: By Volume | U15: =IF(T15="By Unit", IF(P15="RMB",S15/$B$6,IF(P15="GBP",S15,S15/$B$5)),T15) -> By Volume | W15: =1-X15/Q15 -> 1 | X15: 0 | Y15: 0 | Z15: Paid-off | BF15: =SUM(AV15:BE15) -> 0 | BH15: KUMA E-Box ROW | BI15: SOP01.0 | BJ15: BAT | BK15: 45698 | BL15: Kuma 1K | BM15: 0 | BN15: 0 | BO15: 0 | BP15: 4452220 | CD15: 0 | CE15: 0 | CF15: 0 | CG15: 0 | CH15: 0 | CI15: 0 | CJ15: 0 | CK15: 0 | CL15: 0 | CM15: 0 | CN15: 0 | CO15: 0 | CP15: 0 | CQ15: 0 | CR15: 0 | CS15: 0 | CT15: 0 | CU15: 0 | CV15: 0 | CW15: 0 | CX15: 0 | CY15: 0 | CZ15: 0 | DA15: 0 | DB15: 0 | DC15: 0 | DD15: 0 | DE15: 146304 | DF15: 793652 | DG15: 1209610 | DH15: 417742 | DI15: 338164 | DJ15: 665900 | DK15: 479376 | DL15: 184320 | DM15: 217152 | DN15: 522432 | DO15: 149760 | DP15: 207792 | DQ15: 87840 | DR15: 66240 | DS15: 111600 | DT15: 65520 | DU15: 60480 | DV15: 40320 | DW15: 40320 | DX15: 65520 | DY15: 35280 | EA15: KUMA E-ROW Ultra Sonic Machine
A16: 8 | B16: RF007_Epod&Modi | C16: Epod&Modi | D16: Tax Stamp(Pod2+ePod3 Czech,Germany,Poland&Italy) | E16: RCS | F16: Vuse device(ROW) | G16: CN | H16: Asset - Others | I16: RCS | J16: T1 | K16: Smoore T1 | L16: NVT | M16: 45261 | N16: 46722 | O16: 714000 | P16: RMB | Q16: =IF(P16="RMB",O16/$B$6,IF(P16="GBP",O16,O16/$B$5)) -> 77627.765 | R16: 8572763 | S16: 0.083287034 | T16: By Unit | U16: =IF(T16="By Unit", IF(P16="RMB",S16/$B$6,IF(P16="GBP",S16,S16/$B$5)),T16) -> 0.0090551629 | V16: =SUM(AE16:AU16) -> 4614480 | W16: =IF(T16="By Volume",V16/R16,V16*U16/Q16) -> 0.5382722 | X16: =IFERROR(Q16*(1-W16),"") -> 35842.897 | Y16: =IF(X16>0,X16,0) -> 35842.897 | Z16: Under Amortization | AD16: =IF(U16="By Volume",(1-W16)*R16,X16/U16) -> 3958283 | AG16: 25920 | AH16: 322380 | AI16: 336240 | AJ16: 1478340 | AK16: 229680 | AL16: 1008810 | AM16: 993150 | AO16: 36540 | AP16: 178380 | AQ16: 5040 | AT16: 0 | AU16: 0 | AV16: 0 | AW16: 0 | AX16: 0 | AY16: 0 | AZ16: 0 | BA16: 0 | BB16: 0 | BC16: 0 | BD16: 0 | BE16: 0 | BF16: =SUM(AV16:BE16) -> 0 | BH16: KUMA E-Box NZ | BI16: SOP01.0 | BJ16: BAT | BK16: 45698 | BL16: Kuma 950 | BM16: 0 | BN16: 0 | BO16: 0 | BP16: 622560 | CD16: 0 | CE16: 0 | CF16: 0 | CG16: 0 | CH16: 0 | CI16: 0 | CJ16: 0 | CK16: 0 | CL16: 0 | CM16: 0 | CN16: 0 | CO16: 0 | CP16: 0 | CQ16: 0 | CR16: 0 | CS16: 0 | CT16: 0 | CU16: 0 | CV16: 0 | CW16: 0 | CX16: 0 | CY16: 0 | CZ16: 0 | DA16: 0 | DB16: 0 | DC16: 150000 | DD16: 115200 | DE16: 24000 | DF16: 0 | DG16: 222480 | DH16: 45360 | DI16: 65520 | DJ16: 0 | DK16: 0 | DL16: 0 | DM16: 0 | DN16: 0 | DO16: 0 | DP16: 0 | DQ16: 0 | DR16: 0 | DS16: 0 | DT16: 0 | DU16: 0 | DV16: 0 | DW16: 0 | DX16: 0 | DY16: 0
A17: 9 | B17: RF008_Modi2.0 | C17: Modi 2.0 | D17: Automation Flexible Line for Modi 2.0 Platform 1K PEN Default/Full and 1k BOX Full | E17: MD | F17: MD 2.0 | G17: CN | H17: Asset - Modi Line | I17: MoDi | J17: T1 | K17: Smoore T1 | L17: NVT | M17: 45505 | N17: 46235 | O17: 4912380 | P17: RMB | Q17: =IF(P17="RMB",O17/$B$6,IF(P17="GBP",O17,O17/$B$5)) -> 534085.55 | R17: =Q17/0.007 -> 76297935 | S17: =0.007*8.81203 -> 0.06168421 | T17: By Unit | U17: =IF(T17="By Unit", IF(P17="RMB",S17/$B$6,IF(P17="GBP",S17,S17/$B$5)),T17) -> 0.0067064529 | V17: =SUM(AE17:AU17) -> 23870660 | W17: =IF(T17="By Volume",V17/R17,V17*U17/Q17) -> 0.29974123 | X17: =IFERROR(Q17*(1-W17),"") -> 373998.09 | Y17: =IF(X17>0,X17,0) -> 373998.09 | Z17: Under Amortization | AD17: =IF(U17="By Volume",(1-W17)*R17,X17/U17) -> 55766900 | AP17: 705120 | AQ17: 8166540 | AR17: 7083240 | AS17: 2347320 | AT17: ='By Project -Feb 2025'!DN44+'By Project -Feb 2025'!DN45+'By Project -Feb 2025'!DN46 -> 3342680 | AU17: ='By Project -Feb 2025'!DO44+'By Project -Feb 2025'!DO45+'By Project -Feb 2025'!DO46 -> 2225760 | AV17: ='By Project -Feb 2025'!DP44+'By Project -Feb 2025'!DP45+'By Project -Feb 2025'!DP46 -> 5941992 | AW17: ='By Project -Feb 2025'!DQ44+'By Project -Feb 2025'!DQ45+'By Project -Feb 2025'!DQ46 -> 5851740 | AX17: ='By Project -Feb 2025'!DR44+'By Project -Feb 2025'!DR45+'By Project -Feb 2025'!DR46 -> 3951300 | AY17: ='By Project -Feb 2025'!DS44+'By Project -Feb 2025'!DS45+'By Project -Feb 2025'!DS46 -> 4293600 | AZ17: ='By Project -Feb 2025'!DT44+'By Project -Feb 2025'!DT45+'By Project -Feb 2025'!DT46 -> 3621000 | BA17: ='By Project -Feb 2025'!DU44+'By Project -Feb 2025'!DU45+'By Project -Feb 2025'!DU46 -> 5416620 | ... BE17: ='By Project -Feb 2025'!DY44+'By Project -Feb 2025'!DY45+'By Project -Feb 2025'!DY46 -> 5507580 | BF17: =SUM(AV17:BE17) -> 53381412 | BH17: Kuma Box 2.0 | BI17: SOP01.0 | BJ17: BAT | BK17: 45698 | BL17: Kuma Box 2.0 | BP17: 0 | DB17: 0 | DC17: 0 | DD17: 0 | DE17: 0 | DF17: 0 | DG17: 0 | DH17: 0 | DI17: 0 | DJ17: 0 | DK17: 0 | DL17: 0 | DM17: 0 | DN17: 0 | DO17: 0 | DP17: 0 | DQ17: 155360 | DR17: 294600 | DS17: 250560 | DT17: 142560 | DU17: 289405.95 | DV17: 173563.25 | DW17: 172374.76 | DX17: 244507.11 | DY17: 191572.99
A18: 10 | B18: RF009_Hestia1.0 | C18: Hestia 1.0 | D18: Hestia 1.0 Automation Lines Modification (Modified from ePod3 to Hestia1.0) (1-4 line) | E18: Pod | F18: Pod | G18: CN | H18: Pod Automation (Line Upgrade) | I18: RCS | J18: T1 | K18: Smoore T1 | L18: NVT | M18: 45406 | N18: 46113 | O18: 34746341 | P18: RMB | Q18: =IF(P18="RMB",O18/$B$6,IF(P18="GBP",O18,O18/$B$5)) -> 3777704.2 | R18: 246400000 | S18: =O18/R18 -> 0.14101599 | T18: By Unit | U18: =IF(T18="By Unit", IF(P18="RMB",S18/$B$6,IF(P18="GBP",S18,S18/$B$5)),T18) -> 0.015331592 | V18: =SUM(AE18:AU18) -> 139845360 | W18: =IF(T18="By Volume",V18/R18,V18*U18/Q18) -> 0.56755422 | X18: =IFERROR(Q18*(1-W18),"") -> 1633652.2 | Y18: =IF(X18>0,X18,0) -> 1633652.2 | Z18: Under Amortization | AD18: =IF(U18="By Volume",(1-W18)*R18,X18/U18) -> 1.0655464e+08 | AK18: 4374450 | AL18: 10070190 | AM18: 20708100 | AN18: 10070820 | AO18: 17188320 | AP18: 15151590 | AQ18: 12838860 | AR18: 15197040 | AS18: 8947260 | AT18: ='By Project -Feb 2025'!DN12 -> 17350470 | AU18: ='By Project -Feb 2025'!DO12 -> 7948260 | AV18: ='By Project -Feb 2025'!DP12 -> 19106540 | AW18: ='By Project -Feb 2025'!DQ12 -> 20397590 | AX18: ='By Project -Feb 2025'!DR12 -> 14871760 | AY18: ='By Project -Feb 2025'!DS12 -> 18739530 | AZ18: ='By Project -Feb 2025'!DT12 -> 17118810 | BA18: ='By Project -Feb 2025'!DU12 -> 26215830 | ... BE18: ='By Project -Feb 2025'!DY12 -> 19757020 | BF18: =SUM(AV18:BE18) -> 208251130 | BH18: KUMA E-Pen 1.0 ROW | BI18: SOP01.0 | BJ18: BAT | BK18: 45698 | BL18: Kuma Pen 1K | BM18: 0 | BN18: 0 | BO18: 0 | BP18: 1741320 | CD18: 0 | CE18: 0 | CF18: 0 | CG18: 0 | CH18: 0 | CI18: 0 | CJ18: 0 | CK18: 0 | CL18: 0 | CM18: 0 | CN18: 0 | CO18: 0 | CP18: 0 | CQ18: 0 | CR18: 0 | CS18: 0 | CT18: 0 | CU18: 0 | CV18: 0 | CW18: 0 | CX18: 0 | CY18: 0 | CZ18: 0 | DA18: 0 | DB18: 0 | DC18: 0 | DD18: 0 | DE18: 0 | DF18: 0 | DG18: 0 | DH18: 39600 | DI18: 31860 | DJ18: 532440 | DK18: 709740 | DL18: 275220 | DM18: 152460 | DN18: 0 | DO18: 0 | DP18: 0 | DQ18: 0 | DR18: 0 | DS18: 0 | DT18: 0 | DU18: 0 | DV18: 0 | DW18: 0 | DX18: 0 | DY18: 0 | EA18: KUMA E-Pen Laser welding machine & Kuma E-Pen 1.0 air tightness test machine
A19: 11 | B19: RF010_Hestia1.0 | C19: Hestia 1.0 | D19: Hestia1.0 Manual line capex | E19: Pod | F19: Pod | G19: CN | H19: Asset - Others | I19: RCS | J19: T1 | K19: Smoore T1 | L19: NVT | M19: 45406 | N19: 45505 | O19: - | P19: RMB | Q19: 0 | R19: 0 | S19: 0.036 | T19: By Unit | U19: =IF(T19="By Unit", IF(P19="RMB",S19/$B$6,IF(P19="GBP",S19,S19/$B$5)),T19) -> 0.003914005 | V19: 0 | W19: =IFERROR(IF(T19="By Volume",V19/R19,V19*U19/Q19),0) -> 0 | X19: =IFERROR(Q19*(1-W19),"") -> 0 | Y19: 0 | Z19: Not Applicable | BF19: =SUM(AV19:BE19) -> 0 | BH19: Kuma Pen 2.0 | BI19: SOP01.0 | BJ19: BAT | BK19: 45698 | BL19: Kuma Pen 2.0 | BM19: 0 | BN19: 0 | BO19: 0 | BP19: 107460 | CD19: 0 | CE19: 0 | CF19: 0 | CG19: 0 | CH19: 0 | CI19: 0 | CJ19: 0 | CK19: 0 | CL19: 0 | CM19: 0 | CN19: 0 | CO19: 0 | CP19: 0 | CQ19: 0 | CR19: 0 | CS19: 0 | CT19: 0 | CU19: 0 | CV19: 0 | CW19: 0 | CX19: 0 | CY19: 0 | CZ19: 0 | DA19: 0 | DB19: 0 | DC19: 0 | DD19: 0 | DE19: 0 | DF19: 0 | DG19: 0 | DH19: 0 | DI19: 0 | DJ19: 0 | DK19: 0 | DL19: 50040 | DM19: 57420 | DN19: 25200 | DO19: 440 | DP19: 171720 | DQ19: 208800 | DR19: 170818 | DS19: 382597.62 | DT19: 356973.74 | DU19: 489469.07 | DV19: 481795.02 | DW19: 459653.18 | DX19: 540842.01 | DY19: 405790.38
A20: 12 | B20: RF011_ePod2Pod | C20: ePod2 Pod | D20: ePod Packer - Included in Hestia | E20: Pod | F20: Pod | G20: CN | H20: Automation - Packing | I20: RCS | J20: T1 | K20: Smoore T1 | L20: NVT | M20: 44197 | N20: 46357 | O20: 2660000 | P20: USD | Q20: =IF(P20="RMB",O20/$B$6,IF(P20="GBP",O20,O20/$B$5)) -> 2081084 | R20: 175000000 | S20: Volume | T20: By Volume | U20: =IF(T20="By Unit", IF(P20="RMB",S20/$B$6,IF(P20="GBP",S20,S20/$B$5)),T20) -> By Volume | V20: =SUM(AE20:AU20) -> 144866505 | W20: 1 | X20: =IFERROR(Q20*(1-W20),"") -> 0 | Y20: =IF(X20>0,X20,0) -> 0 | Z20: Paid-off | AD20: =IF(U20="By Volume",(1-W20)*R20,X20/U20) -> 0 | AE20: 845920 | AF20: 72773897 | AG20: 63660929 | AH20: 5439052 | AI20: 806095 | AJ20: 321239 | AK20: 481119 | AL20: 497616 | AM20: 40638 | AT20: 0 | BF20: =SUM(AV20:BE20) -> 0 | BH20: KUMA E-Pen 1.0 ROW | BI20: SOP01.0 | BJ20: BAT | BK20: 45698 | BL20: Kuma Pen 950 | BM20: 0 | BN20: 0 | BO20: 0 | BP20: 3020760 | CD20: 0 | CE20: 0 | CF20: 0 | CG20: 0 | CH20: 0 | CI20: 0 | CJ20: 0 | CK20: 0 | CL20: 0 | CM20: 0 | CN20: 0 | CO20: 0 | CP20: 0 | CQ20: 0 | CR20: 0 | CS20: 0 | CT20: 0 | CU20: 0 | CV20: 0 | CW20: 0 | CX20: 0 | CY20: 0 | CZ20: 0 | DA20: 0 | DB20: 0 | DC20: 0 | DD20: 0 | DE20: 0 | DF20: 0 | DG20: 0 | DH20: 0 | DI20: 862920 | DJ20: 623880 | DK20: 567720 | DL20: 660240 | DM20: 306000 | DN20: 574020 | DO20: 633600 | DP20: 626220 | DQ20: 116460 | DR20: 114660 | DS20: 179460 | DT20: 169200 | DU20: 147260 | DV20: 143160 | DW20: 128580 | DX20: 116680 | DY20: 142880 | EA20: KUMA E-Pen Laser welding machine & Kuma E-Pen 1.0 air tightness test machine
A21: 13 | B21: RF012_ePod3Pod | C21: ePod3 Pod | D21: ePod 3 Automation Modification Capex Amortization (1P) Modified from ePod2 to ePod3 | E21: Pod | F21: Pod | G21: CN | H21: Pod Automation (Line Upgrade) | I21: RCS | J21: T1 | K21: Smoore T1 | L21: NVT | M21: 44980 | N21: 45689 | O21: 1503259 | P21: RMB | Q21: =IF(P21="RMB",O21/$B$6,IF(P21="GBP",O21,O21/$B$5)) -> 163437.87 | R21: =6430000*4/(0.01*8.87287) -> 2.8987239e+08 | S21: 0.0887284 | T21: By Unit | U21: =IF(T21="By Unit", IF(P21="RMB",S21/$B$6,IF(P21="GBP",S21,S21/$B$5)),T21) -> 0.0096467611 | V21: =Q21/U21 -> 16942253 | W21: =IF(T21="By Volume",V21/R21,V21*U21/Q21) -> 1 | X21: =IFERROR(Q21*(1-W21),"")*0 -> 0 | Y21: 0 | Z21: Amortization Completed | AG21: 12285257 | AH21: 1074798 | AI21: 65733 | AJ21: 894985 | AK21: 906260 | AL21: 1097616 | AM21: 617546 | AN21: 612910 | AO21: 277678 | AP21: 193824 | BF21: =SUM(AV21:BE21) -> 0 | BI21: SOP01.0 | BJ21: BAT | BK21: 45698 | BL21: Kuma Pen NZ | BP21: 0 | DB21: 0 | DC21: 0 | DD21: 0 | DE21: 0 | DF21: 0 | DG21: 0 | DH21: 0 | DI21: 0 | DJ21: 0 | DK21: 0 | DL21: 0 | DM21: 0 | DN21: 0 | DO21: 0 | DP21: 0 | DQ21: 0 | DR21: 0 | DS21: 0 | DT21: 0 | DU21: 0 | DV21: 0 | DW21: 0 | DX21: 0 | DY21: 0
A22: 14 | B22: RF013_Kuma | C22: Kuma 1.0 | D22: KUMA E-ROW Ultra Sonic Machine | E22: RCS | F22: Vuse device(ROW) | G22: CN | H22: Asset - RCS Device line | I22: RCS | J22: T1 | K22: Smoore T1 | L22: NVT | M22: 45383 | N22: 46113 | O22: 640000 | P22: RMB | Q22: =IF(P22="RMB",O22/$B$6,IF(P22="GBP",O22,O22/$B$5)) -> 69582.31 | R22: =O22/S22 -> 11034483 | S22: 0.058 | T22: By Unit | U22: =IF(T22="By Unit", IF(P22="RMB",S22/$B$6,IF(P22="GBP",S22,S22/$B$5)),T22) -> 0.0063058969 | V22: =SUM(AE22:AU22) -> 5022892 | W22: =IF(T22="By Volume",V22/R22,V22*U22/Q22) -> 0.45519959 | X22: =IFERROR(Q22*(1-W22),"") -> 37908.471 | Y22: =IF(X22>0,X22,0) -> 37908.471 | Z22: Under Amortization | AD22: =IF(U22="By Volume",(1-W22)*R22,X22/U22) -> 6011590.8 | AK22: 146304 | AL22: 793652 | AM22: 1209610 | AN22: 417742 | AO22: 338164 | AP22: 665900 | AQ22: 479376 | AR22: 160272 | AS22: 139680 | AT22: ='By Project -Feb 2025'!DN15 -> 522432 | AU22: ='By Project -Feb 2025'!DO15 -> 149760 | AV22: ='By Project -Feb 2025'!DP15 -> 207792 | AW22: ='By Project -Feb 2025'!DQ15 -> 87840 | AX22: ='By Project -Feb 2025'!DR15 -> 66240 | AY22: ='By Project -Feb 2025'!DS15 -> 111600 | AZ22: ='By Project -Feb 2025'!DT15 -> 65520 | BA22: ='By Project -Feb 2025'!DU15 -> 60480 | ... BE22: ='By Project -Feb 2025'!DY15 -> 35280 | BF22: =SUM(AV22:BE22) -> 780912 | BH22: Hestia total（include Kuma） | BI22: SOP01.0 | BJ22: BAT | BK22: 45698 | BL22: Hestia total（include Kuma） | BM22: 0 | BN22: 0 | BO22: 0 | BP22: 128856640 | BQ22: 0 | BR22: 0 | BS22: 0 | BT22: 0 | BU22: 0 | BV22: 0 | BW22: 0 | BX22: 0 | BY22: 0 | BZ22: 0 | CA22: 0 | CB22: 0 | CD22: 0 | CE22: 0 | CF22: 0 | CG22: 0 | CH22: 0 | CI22: 0 | CJ22: 0 | CK22: 0 | CL22: 0 | CM22: 0 | CN22: 0 | CO22: 0 | CP22: 0 | CQ22: 0 | CR22: 0 | CS22: 0 | CT22: 0 | CU22: 0 | CV22: 0 | CW22: 0 | CX22: 0 | CY22: 0 | CZ22: 0 | DA22: 0 | DB22: 0 | DC22: 0 | DD22: 0 | DE22: 4287474 | DF22: 11097122 | DG22: 19322470 | DH22: 13123402 | DI22: 18421264 | DJ22: 16973810 | DK22: 14595696 | DL22: 14369670 | DM22: 16665732 | DN22: 18472122 | DO22: 8762030 | DP22: 20688272 | DQ22: 21777200 | DR22: 16622738 | DS22: 20481288 | DT22: 18329524 | DU22: 27808745 | DV22: 24598438 | DW22: 22902058 | DX22: 28824839 | DY22: 21145803 | EA22: APA - Automation Production Agreement
A23: 15 | B23: RF014_Kuma | C23: Kuma 1.0 | D23: KUMA E-Pen Laser welding machine & Kuma E-Pen 1.0 air tightness test machine | E23: RCS | F23: Vuse device(ROW) | G23: CN | H23: Asset - RCS Device line | I23: RCS | J23: T1 | K23: Smoore T1 | L23: NVT | M23: 45505 | N23: 46235 | O23: =708000+72300 -> 780300 | P23: RMB | Q23: =IF(P23="RMB",O23/$B$6,IF(P23="GBP",O23,O23/$B$5)) -> 84836.058 | S23: 0.094674863 | T23: By Unit | U23: =IF(T23="By Unit", IF(P23="RMB",S23/$B$6,IF(P23="GBP",S23,S23/$B$5)),T23) -> 0.010293275 | V23: =SUM(AE23:AU23) -> 5979960 | W23: =IF(T23="By Volume",V23/R23,V23*U23/Q23) -> 0.7255567 | X23: =IFERROR(Q23*(1-W23),"")*0 -> 0 | Y23: 0 | Z23: Under Amortization | AD23: =IF(U23="By Volume",(1-W23)*R23,X23/U23) -> 0 | AN23: 39600 | AO23: 894780 | AP23: 1156320 | AQ23: 1277460 | AR23: 950580 | AS23: 453600 | AT23: ='By Project -Feb 2025'!DN18+'By Project -Feb 2025'!DN20 -> 574020 | AU23: ='By Project -Feb 2025'!DO18+'By Project -Feb 2025'!DO20 -> 633600 | AV23: ='By Project -Feb 2025'!DP18+'By Project -Feb 2025'!DP20 -> 626220 | AW23: ='By Project -Feb 2025'!DQ18+'By Project -Feb 2025'!DQ20 -> 116460 | AX23: ='By Project -Feb 2025'!DR18+'By Project -Feb 2025'!DR20 -> 114660 | AY23: ='By Project -Feb 2025'!DS18+'By Project -Feb 2025'!DS20 -> 179460 | AZ23: ='By Project -Feb 2025'!DT18+'By Project -Feb 2025'!DT20 -> 169200 | BA23: ='By Project -Feb 2025'!DU18+'By Project -Feb 2025'!DU20 -> 147260 | ... BE23: ='By Project -Feb 2025'!DY18+'By Project -Feb 2025'!DY20 -> 142880 | BF23: =SUM(AV23:BE23) -> 1884560 | BH23: Mimosa | BI23: SOP01.0 | BJ23: BAT | BK23: 45698 | BL23: Mimosa | BM23: 0 | BN23: 0 | BO23: 0 | BP23: 0 | CD23: 0 | CE23: 0 | CF23: 0 | CG23: 0 | CH23: 0 | CI23: 0 | CJ23: 0 | CK23: 0 | CL23: 0 | CM23: 0 | CN23: 0 | CO23: 0 | CP23: 0 | CQ23: 0 | CR23: 0 | CS23: 0 | CT23: 0 | CU23: 0 | CV23: 0 | CW23: 0 | CX23: 0 | CY23: 0 | CZ23: 0 | DA23: 0 | DB23: 0 | DC23: 0 | DD23: 0 | DE23: 0 | DF23: 0 | DG23: 0 | DH23: 0 | DI23: 0 | DJ23: 0 | DK23: 0 | DL23: 0 | DM23: 0 | DN23: 0 | DO23: 3744 | DP23: 72000 | DQ23: 153000 | DR23: 99000 | DS23: 18000 | DT23: 36336 | DU23: 56016 | DV23: 38736 | DW23: 46032 | DX23: 44928 | DY23: 43776
A24: 16 | B24: RF015_Modi&RCS | C24: Modi & RCS | D24: CCD&Tax Stamp Machine MD2.0 1K PEN Default Czech/Germany/Poland/Italy/BUL (Machines can be cross-used by both Modi & RCS) | E24: MD | F24: MD 2.0 | G24: CN | H24: Asset - Others | I24: Modi | J24: T1 | K24: Smoore T1 | L24: NVT | M24: 45505 | N24: 46966 | O24: 1210000 | P24: RMB | Q24: =IF(P24="RMB",O24/$B$6,IF(P24="GBP",O24,O24/$B$5)) -> 131554.06 | R24: 29491560 | S24: 0.041028688 | T24: By Unit | U24: =IF(T24="By Unit", IF(P24="RMB",S24/$B$6,IF(P24="GBP",S24,S24/$B$5)),T24) -> 0.0044607357 | V24: =SUM(AE24:AU24) -> 9825420 | W24: =IF(T24="By Volume",V24/R24,V24*U24/Q24) -> 0.3331604 | X24: =IFERROR(Q24*(1-W24),"") -> 87725.454 | Y24: =IF(X24>0,X24,0) -> 87725.454 | Z24: Under Amortization | AD24: =IF(U24="By Volume",(1-W24)*R24,X24/U24) -> 19666140 | AP24: 36060 | AQ24: 4722360 | AR24: 3286440 | AS24: 398760 | AT24: 1150380 | AU24: 231420 | AV24: 1771920 | AW24: 3593400 | AX24: 1748640 | AY24: 752880 | AZ24: 1156800 | BA24: 1870560 | BB24: 1795920 | BC24: 2130480 | BD24: 3526800 | BE24: 2150400 | BF24: =SUM(AV24:BE24) -> 20497800 | BH24: ePod 2 Device(Wave 1) | BI24: SOP01.0 | BJ24: BAT | BK24: 45698 | BL24: ePod2 | BM24: 6919526 | BN24: 6734445 | BO24: 973700 | BP24: 301000 | BQ24: 355400 | BR24: 376900 | BS24: 329800 | BT24: 514000 | BU24: 392100 | BV24: 672345 | BW24: 790600 | BX24: 581700 | BY24: 493100 | BZ24: 766581 | CA24: 791000 | CB24: 856000 | CD24: 617400 | CE24: 565400 | CF24: 918400 | CG24: 1007400 | CH24: 723600 | CI24: 752700 | CJ24: 589200 | CK24: 591300 | CL24: 636055 | CM24: 45000 | CN24: 163790 | CO24: 124200 | CP24: 95000 | CQ24: 309300 | CR24: 98600 | CS24: 18000 | CT24: 41000 | CU24: 16000 | CV24: 30000 | CW24: 43800 | CX24: 72900 | CY24: 75600 | CZ24: 48400 | DA24: 125100 | DB24: 19300 | DC24: 72900 | DD24: 30200 | DE24: 21700 | DF24: 24900 | DG24: 19800 | DH24: 0 | DI24: 0 | DJ24: 0 | DK24: 69000 | DL24: 43200 | DM24: 0 | DN24: 0 | DO24: 0 | DP24: 0 | DQ24: 0 | DR24: 0 | DS24: 0 | DT24: 0 | DU24: 0 | DV24: 0 | DW24: 0 | DX24: 0 | DY24: 0
A25: 17 | B25: RF016_Sensa | C25: Sensa | D25: Sensa Manual Line Capex | E25: MD | F25: MD 2.0 | G25: CN | H25: Asset - Others | I25: Modi | J25: T1 | K25: Smoore T1 | L25: NVT | M25: 45474 | N25: 45992 | O25: 903370.28 | P25: RMB | Q25: =IF(P25="RMB",O25/$B$6,IF(P25="GBP",O25,O25/$B$5)) -> 98216.549 | R25: 8895000 | S25: =0.0115*8.81203 -> 0.10133834 | T25: By Unit | U25: =IF(T25="By Unit", IF(P25="RMB",S25/$B$6,IF(P25="GBP",S25,S25/$B$5)),T25) -> 0.011017744 | V25: =SUM(AE25:AU25) -> 0 | W25: =IF(T25="By Volume",V25/R25,V25*U25/Q25) -> 0 | X25: =IFERROR(Q25*(1-W25),"") -> 98216.549 | Y25: =IF(X25>0,X25,0) -> 98216.549 | Z25: Under Amortization | AD25: =IF(U25="By Volume",(1-W25)*R25,X25/U25) -> 8914397.4 | BF25: =SUM(AV25:BE25) -> 0 | BI25: SOP12.1 | BJ25: BAT | BK25: 0 | BL25: ePod2 | BM25: 6503406 | BN25: 7074939 | BO25: 0 | BP25: 0 | BQ25: 355400 | BR25: 376900 | BS25: 329800 | BT25: 514000 | BU25: 392100 | BV25: 672345 | BW25: 790600 | BX25: 581700 | BY25: 493100 | BZ25: 766581 | CA25: 695680 | CB25: 535200 | CD25: 845094 | CE25: 464000 | CF25: 918400 | CG25: 1206700 | CH25: 786300 | CI25: 752700 | CJ25: 589200 | CK25: 543500 | CL25: 636055 | CM25: 45000 | CN25: 163790 | CO25: 124200 | CP25: 0 | CQ25: 0 | CR25: 0 | CS25: 0 | CT25: 0 | CU25: 0 | CV25: 0 | CW25: 0 | CX25: 0 | CY25: 0 | CZ25: 0 | DA25: 0 | DB25: 0 | DC25: 0 | DD25: 0 | DE25: 0 | DF25: 0 | DG25: 0 | DH25: 0 | DI25: 0 | DJ25: 0 | DK25: 0 | DL25: 0 | DM25: 0 | DN25: 0 | DO25: 0 | DP25: 0 | DQ25: 0 | DR25: 0 | DS25: 0 | DT25: 0 | DU25: 0 | DV25: 0 | DW25: 0 | DX25: 0 | DY25: 0
A26: 18 | B26: RF017_Sensa | C26: Sensa | D26: Sensa Semi-Auto Line Capex | E26: MD | F26: MD 2.0 | G26: CN | H26: Asset - Modi Line | I26: Modi | J26: T1 | K26: Smoore T1 | L26: NVT | M26: 45536 | N26: 45992 | O26: 6018424 | P26: RMB | Q26: =IF(P26="RMB",O26/$B$6,IF(P26="GBP",O26,O26/$B$5)) -> 654337.26 | R26: 12960000 | S26: =0.0527*8.81203 -> 0.46439398 | T26: By Unit | U26: =IF(T26="By Unit", IF(P26="RMB",S26/$B$6,IF(P26="GBP",S26,S26/$B$5)),T26) -> 0.05049001 | V26: =SUM(AE26:AU26) -> 0 | W26: =IF(T26="By Volume",V26/R26,V26*U26/Q26) -> 0 | X26: =IFERROR(Q26*(1-W26),"") -> 654337.26 | Y26: =IF(X26>0,X26,0) -> 654337.26 | Z26: Under Amortization | AD26: =IF(U26="By Volume",(1-W26)*R26,X26/U26) -> 12959737 | BF26: =SUM(AV26:BE26) -> 0 | BI26: 0 | BJ26: BAT | BK26: 0 | BL26: ePod2 | BM26: 6503406 | BN26: 6529023 | BO26: 0 | BP26: 0 | BQ26: 355400 | BR26: 376900 | BS26: 329800 | BT26: 514000 | BU26: 392100 | BV26: 672345 | BW26: 790600 | BX26: 581700 | BY26: 493100 | BZ26: 766581 | CA26: 695680 | CB26: 535200 | CD26: 845094 | CE26: 464000 | CF26: 884050 | CG26: 1206700 | CH26: 484575 | CI26: 935984 | CJ26: 432680 | CK26: 306895 | CL26: 636055 | CM26: 45000 | CN26: 163790 | CO26: 124200 | CP26: 0 | CQ26: 0 | CR26: 0 | CS26: 0 | CT26: 0 | CU26: 0 | CV26: 0 | CW26: 0 | CX26: 0 | CY26: 0 | CZ26: 0 | DA26: 0 | DB26: 0 | DC26: 0 | DD26: 0 | DE26: 0 | DF26: 0 | DG26: 0 | DH26: 0 | DI26: 0 | DJ26: 0 | DK26: 0 | DL26: 0 | DM26: 0 | DN26: 0 | DO26: 0 | DP26: 0 | DQ26: 0 | DR26: 0 | DS26: 0 | DT26: 0 | DU26: 0 | DV26: 0 | DW26: 0 | DX26: 0 | DY26: 0
A27: 19 | B27: RF018_Modi | C27: Modi | D27: T&T longterm solution cost Amortize at Uzbekistan TX500 and DP1500（UZB—乌兹别克斯坦） | E27: MD | F27: MD1.0 | G27: CN | H27: Asset - Others | I27: Modi | J27: T1 | K27: Smoore T1 | L27: NVT | M27: 44986 | N27: 46447 | O27: 1363867.4 | P27: RMB | Q27: =IF(P27="RMB",O27/$B$6,IF(P27="GBP",O27,O27/$B$5)) -> 148282.88 | R27: 4682003 | S27: =O27/R27 -> 0.29129998 | T27: By Unit | U27: =IF(T27="By Unit", IF(P27="RMB",S27/$B$6,IF(P27="GBP",S27,S27/$B$5)),T27) -> 0.031670821 | V27: =SUM(AE27:AU27) -> 552000 | W27: =IF(T27="By Volume",V27/R27,V27*U27/Q27) -> 0.11789826 | X27: =IFERROR(Q27*(1-W27),"") -> 130800.59 | Y27: =IF(X27>0,X27,0) -> 130800.59 | Z27: Under Amortization | AD27: =IF(U27="By Volume",(1-W27)*R27,X27/U27) -> 4130003 | AG27: 549000 | AH27: 3000 | AT27: 0 | AU27: 0 | AV27: 0 | AW27: 0 | AX27: 0 | AY27: 0 | AZ27: 0 | BA27: 0 | BB27: 0 | BC27: 0 | BD27: 0 | BE27: 0 | BF27: =SUM(AV27:BE27) -> 0 | BI27: 0 | BJ27: BAT | BK27: SOP7-2022/8/2 | BL27: ETMI | BM27: 45200 | BN27: 21040 | BO27: 32160 | BP27: 0 | BR27: 17760 | BT27: 14320 | BV27: 4400 | BW27: 8720 | CD27: 6000 | CF27: 3000 | CG27: 0 | CH27: 4000 | CI27: 0 | CJ27: 5040 | CK27: 3000 | CL27: 0 | CM27: 0 | CN27: 0 | CO27: 0 | CP27: 0 | CQ27: 3000 | CR27: 5040 | CS27: 0 | CT27: 3000 | CU27: 5040 | CV27: 0 | CW27: 0 | CX27: 8040 | CY27: 0 | CZ27: 0 | DA27: 8040
A28: 20 | B28: RF019_Modi | C28: Modi | D28: KZ MODI testing / support for T&T Amortize at KAZ TX500 and DP1500（KZ—哈萨克斯坦） | E28: MD | F28: MD1.0 | G28: CN | H28: Asset - Others | I28: Modi | J28: T1 | K28: Smoore T1 | L28: NVT | M28: 45108 | N28: 46569 | O28: 130573.98 | P28: RMB | Q28: =IF(P28="RMB",O28/$B$6,IF(P28="GBP",O28,O28/$B$5)) -> 14196.311 | R28: 1020000 | S28: =O28/R28 -> 0.12801371 | T28: By Unit | U28: =IF(T28="By Unit", IF(P28="RMB",S28/$B$6,IF(P28="GBP",S28,S28/$B$5)),T28) -> 0.013917952 | V28: =SUM(AE28:AU28) -> 0 | W28: =IF(T28="By Volume",V28/R28,V28*U28/Q28) -> 0 | X28: =IFERROR(Q28*(1-W28),"") -> 14196.311 | Y28: =IF(X28>0,X28,0) -> 14196.311 | Z28: Under Amortization | AD28: =IF(U28="By Volume",(1-W28)*R28,X28/U28) -> 1020000 | AT28: 0 | AU28: 0 | AV28: 0 | AW28: 0 | AX28: 0 | AY28: 0 | AZ28: 0 | BA28: 0 | BB28: 0 | BC28: 0 | BD28: 0 | BE28: 0 | BF28: =SUM(AV28:BE28) -> 0 | BI28: SOP7-2022/8/2 | BJ28: BAT | BK28: 44805 | BL28: Atomiser | BM28: 511000 | BN28: 40500 | BO28: 0 | BP28: 0 | BR28: 181500 | BT28: 77000 | BV28: 85000 | BW28: 167500 | CD28: 3000 | CF28: 0 | CG28: 0 | CI28: 0 | CJ28: 12500 | CK28: 0 | CL28: 0 | CM28: 12500 | CN28: 12500
A29: 21 | B29: RF020_Modi | C29: Modi | D29: T&T Interim programme of Azerbaijan Amortize at Azerbaijan 1k/3k/5k product（AZB—阿塞拜疆） | E29: MD | F29: MD1.0 | G29: CN | H29: Asset - Others | I29: Modi | J29: T1 | K29: Smoore T1 | L29: NVT | M29: 45017 | N29: 46478 | O29: 95728.992 | P29: RMB | Q29: =IF(P29="RMB",O29/$B$6,IF(P29="GBP",O29,O29/$B$5)) -> 10407.882 | T29: By Unit | U29: =IF(T29="By Unit", IF(P29="RMB",S29/$B$6,IF(P29="GBP",S29,S29/$B$5)),T29) -> 0 | V29: =SUM(AE29:AU29) -> 4680 | W29: =IF(T29="By Volume",V29/R29,V29*U29/Q29) -> 0 | X29: =IFERROR(Q29*(1-W29),"") -> 10407.882 | Y29: =IF(X29>0,X29,0) -> 10407.882 | Z29: Under Amortization | AT29: 0 | AU29: 4680 | AV29: 72000 | AW29: 0 | AX29: 0 | AY29: 0 | AZ29: 0 | BA29: 0 | BB29: 0 | BC29: 0 | BD29: 0 | BE29: 0 | BF29: =SUM(AV29:BE29) -> 72000 | BI29: 44805 | BJ29: BAT | BK29: SOP10-12/6 236M | BL29: ePod2+ | BM29: 0 | BN29: 1724245.5 | BO29: 650254.5 | BP29: 0 | CD29: 135000 | CE29: 135000 | CF29: 136696.5 | CG29: 108378 | CH29: 181110 | CI29: 121848 | CJ29: 156642 | CK29: 131443.5 | CL29: 186801 | CM29: 203887.5 | CN29: 157320 | CO29: 70119 | CP29: 75019.5 | CQ29: 79714.5 | CR29: 164461.5 | CS29: 165529.5 | CT29: 165529.5
A30: 22 | B30: RF021_Modi | C30: Modi | D30: T&T for Pre-Dispatch Advice --add extra function（UZB—乌兹别克斯坦 KZ—哈萨克斯坦） | E30: MD | F30: MD1.0 | G30: CN | H30: Asset - Others | I30: Modi | J30: T1 | K30: Smoore T1 | L30: NVT | M30: 45017 | N30: 46478 | O30: 706075.2 | P30: RMB | Q30: =IF(P30="RMB",O30/$B$6,IF(P30="GBP",O30,O30/$B$5)) -> 76766.162 | T30: By Unit | U30: =IF(T30="By Unit", IF(P30="RMB",S30/$B$6,IF(P30="GBP",S30,S30/$B$5)),T30) -> 0 | V30: =SUM(AE30:AU30) -> 0 | W30: =IF(T30="By Volume",V30/R30,V30*U30/Q30) -> 0 | X30: =IFERROR(Q30*(1-W30),"") -> 76766.162 | Y30: =IF(X30>0,X30,0) -> 76766.162 | Z30: Under Amortization | AT30: 0 | AU30: 0 | AV30: 0 | AW30: 0 | AX30: 0 | AY30: 0 | AZ30: 0 | BA30: 0 | BB30: 0 | BC30: 0 | BD30: 0 | BE30: 0 | BF30: =SUM(AV30:BE30) -> 0 | BI30: SOP10-12/6 236M | BJ30: BAT | BK30: 2023/1/31Core | BL30: ePod2+ | BM30: 0 | BN30: 1541050 | BO30: 235000 | BP30: 0 | CD30: 0 | CE30: 64549 | CF30: 127048 | CG30: 181303 | CH30: 24200 | CI30: 254800 | CJ30: 211000 | CK30: 214000 | CL30: 215000 | CM30: 81000 | CN30: 48150 | CO30: 120000 | CP30: 175000 | CQ30: 60000 | CR30: 0 | CS30: 0 | CT30: 0 | CU30: 0 | CV30: 0 | CW30: 0 | CX30: 0 | CY30: 0 | CZ30: 0 | DA30: 0
A31: 23 | B31: RF022_Modi | C31: Modi | D31: KZ MODI testing / support for T&T Amortize at BOX3K&5K KAZ&UZB market（KZ—哈萨克斯坦） | E31: MD | F31: MD1.0 | G31: CN | H31: Asset - Others | I31: Modi | J31: T1 | K31: Smoore T1 | L31: NVT | M31: 45108 | N31: 46569 | O31: 46448.488 | P31: RMB | Q31: =IF(P31="RMB",O31/$B$6,IF(P31="GBP",O31,O31/$B$5)) -> 5049.9892 | R31: 3976000 | S31: 0.011682215 | T31: By Unit | U31: =IF(T31="By Unit", IF(P31="RMB",S31/$B$6,IF(P31="GBP",S31,S31/$B$5)),T31) -> 0.001270118 | V31: =SUM(AE31:AU31) -> 137400 | W31: =IF(T31="By Volume",V31/R31,V31*U31/Q31) -> 0.034557344 | X31: =IFERROR(Q31*(1-W31),"") -> 4875.475 | Y31: =IF(X31>0,X31,0) -> 4875.475 | Z31: Under Amortization | AD31: =IF(U31="By Volume",(1-W31)*R31,X31/U31) -> 3838600 | AG31: 116160 | AH31: 15840 | AK31: 5400 | AT31: 0 | AU31: 0 | AV31: 0 | AW31: 0 | AX31: 0 | AY31: 0 | AZ31: 0 | BA31: 0 | BB31: 0 | BC31: 0 | BD31: 0 | BE31: 0 | BF31: =SUM(AV31:BE31) -> 0 | BI31: SOP2 | BJ31: BAT | BK31: 2023/1/31-Core+Sensitivity | BL31: ePod2+ | BM31: 0 | BN31: 1650011 | BO31: 235000 | BP31: 0 | BQ31: 0 | BR31: 0 | BS31: 0 | BT31: 0 | BU31: 0 | BV31: 0 | BW31: 0 | BX31: 0 | BY31: 0 | BZ31: 0 | CA31: 0 | CB31: 0 | CD31: 0 | CE31: 80000 | CF31: 148648 | CG31: 181303 | CH31: 24200 | CI31: 326710 | CJ31: 211000 | CK31: 214000 | CL31: 215000 | CM31: 81000 | CN31: 48150 | CO31: 120000 | CP31: 175000 | CQ31: 60000 | CR31: 0 | CS31: 0 | CT31: 0 | CU31: 0 | CV31: 0 | CW31: 0 | CX31: 0 | CY31: 0 | CZ31: 0 | DA31: 0
A32: 24 | B32: RF023_Modi | C32: Modi | D32: AZB T&T longterm solution cost for TX500&DP1500&BOX1K&3K&5K for AZB Market（AZB—阿塞拜疆） | E32: MD | F32: MD1.0 | G32: CN | H32: Asset - Others | I32: Modi | J32: T1 | K32: Smoore T1 | L32: NVT | M32: 45017 | N32: 46478 | O32: 466929.08 | P32: RMB | Q32: =IF(P32="RMB",O32/$B$6,IF(P32="GBP",O32,O32/$B$5)) -> 50765.632 | T32: By Unit | U32: =IF(T32="By Unit", IF(P32="RMB",S32/$B$6,IF(P32="GBP",S32,S32/$B$5)),T32) -> 0 | V32: =SUM(AE32:AU32) -> 4680 | W32: =IF(T32="By Volume",V32/R32,V32*U32/Q32) -> 0 | X32: =IFERROR(Q32*(1-W32),"") -> 50765.632 | Y32: =IF(X32>0,X32,0) -> 50765.632 | Z32: Under Amortization | AT32: 0 | AU32: 4680 | AV32: 72000 | AW32: 0 | AX32: 0 | AY32: 0 | AZ32: 0 | BA32: 0 | BB32: 0 | BC32: 0 | BD32: 0 | BE32: 0 | BF32: =SUM(AV32:BE32) -> 72000 | BI32: 2023/1/31-Core+Sensitivity | BJ32: BAT | BK32: 2023/1/31-PO+Production | BL32: ePod2+ | BM32: 0 | BN32: 1542297 | BO32: 235000 | BP32: 0 | CE32: 69349 | CF32: 148648 | CG32: 160000 | CH32: 20000 | CI32: 326710 | CJ32: 139440 | CK32: 214000 | CL32: 215000 | CM32: 81000 | CN32: 48150 | CO32: 120000 | CP32: 175000 | CQ32: 60000 | CR32: 0 | CS32: 0 | CT32: 0 | CU32: 0 | CV32: 0 | CW32: 0 | CX32: 0 | CY32: 0 | CZ32: 0 | DA32: 0
A33: 25 | B33: RF024_Modi | C33: Modi | D33: Custom development BAT CMO INEXTRACK GS1 Novarator removal CR for AZB regulation（AZB—阿塞拜疆） | E33: MD | F33: MD1.0 | G33: CN | H33: Asset - Others | I33: Modi | J33: T1 | K33: Smoore T1 | L33: NVT | M33: 45108 | N33: 46569 | O33: 80274.71 | P33: RMB | Q33: =IF(P33="RMB",O33/$B$6,IF(P33="GBP",O33,O33/$B$5)) -> 8727.6559 | T33: By Unit | U33: =IF(T33="By Unit", IF(P33="RMB",S33/$B$6,IF(P33="GBP",S33,S33/$B$5)),T33) -> 0 | V33: =SUM(AE33:AU33) -> 4680 | W33: =IF(T33="By Volume",V33/R33,V33*U33/Q33) -> 0 | X33: =IFERROR(Q33*(1-W33),"") -> 8727.6559 | Y33: =IF(X33>0,X33,0) -> 8727.6559 | Z33: Under Amortization | AT33: 0 | AU33: 4680 | AV33: 72000 | AW33: 0 | AX33: 0 | AY33: 0 | AZ33: 0 | BA33: 0 | BB33: 0 | BC33: 0 | BD33: 0 | BE33: 0 | BF33: =SUM(AV33:BE33) -> 72000 | BH33: ePod 3+ Device | BI33: SOP01.0 | BJ33: BAT | BK33: 45698 | BL33: ePod3+ | BM33: 0 | BN33: 0 | BO33: 283400 | BP33: 540400 | CD33: 0 | CE33: 0 | CF33: 0 | CG33: 0 | CH33: 0 | CI33: 0 | CJ33: 0 | CK33: 0 | CL33: 0 | CM33: 0 | CN33: 0 | CO33: 0 | CP33: 0 | CQ33: 0 | CR33: 0 | CS33: 0 | CT33: 61500 | CU33: 95000 | CV33: 0 | CW33: 0 | CX33: 54300 | CY33: 29900 | CZ33: 3600 | DA33: 39100 | DB33: 101800 | DC33: 40000 | DD33: 56600 | DE33: 163900 | DF33: 57700 | DG33: 37200 | DH33: 4000 | DI33: 12200 | DJ33: 38200 | DK33: 20800 | DL33: 0 | DM33: 8000 | DN33: 27600 | DO33: 17000 | DP33: 11000 | DQ33: 18200 | DR33: 14400 | DS33: 32400 | DT33: 12300 | DU33: 17300 | DV33: 28200 | DW33: 21100 | DX33: 24800 | DY33: 24800
A34: 27 | B34: RF025_Hestia1.1 | C34: Hestia 1.0 | D34: epod2 to Hestia1.1 non-smart | E34: RCS | F34: Pod | G34: CN | H34: Pod Automation (Line Upgrade) | I34: RCS | J34: T1 | K34: Smoore T1 | L34: NVT | O34: 5756300 | P34: RMB | Q34: =IF(P34="RMB",O34/$B$6,IF(P34="GBP",O34,O34/$B$5)) -> 625838.52 | T34: By Unit | U34: =IF(T34="By Unit", IF(P34="RMB",S34/$B$6,IF(P34="GBP",S34,S34/$B$5)),T34) -> 0 | W34: =IF(T34="By Volume",V34/R34,V34*U34/Q34) -> 0 | X34: =IFERROR(Q34*(1-W34),"") -> 625838.52 | Y34: 0 | Z34: Project Cancelled | BF34: =SUM(AV34:BE34) -> 0 | BH34: Epod Starter Kit | BI34: SOP01.0 | BJ34: BAT | BK34: 45698 | BL34: Starter Kit | BM34: 0 | BN34: 0 | BO34: 319800 | BP34: 617536 | CD34: 0 | CE34: 0 | CF34: 0 | CG34: 0 | CH34: 0 | CI34: 0 | CJ34: 0 | CK34: 0 | CL34: 0 | CM34: 0 | CN34: 0 | CO34: 0 | CP34: 0 | CQ34: 0 | CR34: 0 | CS34: 0 | CT34: 0 | CU34: 0 | CV34: 0 | CW34: 0 | CX34: 0 | CY34: 0 | CZ34: 110800 | DA34: 209000 | DB34: 43200 | DC34: 7200 | DD34: 10800 | DE34: 147920 | DF34: 44600 | DG34: 19440 | DH34: 295576 | DI34: 28640 | DJ34: 20160 | DK34: 0 | DL34: 0 | DM34: 0 | DN34: 11592 | DO34: 0 | DP34: 0 | DQ34: 0 | DR34: 0 | DS34: 0 | DT34: 0 | DU34: 0 | DV34: 0 | DW34: 0 | DX34: 0 | DY34: 0 | EA34: APA - Automation Production Agreement
A35: 26 | B35: RF026_Hestia1.1 | C35: Hestia 1.1 | D35: epod2 to Hestia1.1 smart | E35: RCS | F35: Pod | G35: CN | H35: Pod Automation (Line Upgrade) | I35: RCS | J35: T1 | K35: Smoore T1 | L35: NVT | M35: 45777 | N35: 46507 | O35: 12518185 | P35: RMB | Q35: =IF(P35="RMB",O35/$B$6,IF(P35="GBP",O35,O35/$B$5)) -> 1361006.6 | R35: TBC | S35: TBC | T35: By Unit | U35: =IF(T35="By Unit", IF(P35="RMB",S35/$B$6,IF(P35="GBP",S35,S35/$B$5)),T35) -> #VALUE! | W35: =IFERROR(IF(T35="By Volume",V35/R35,V35*U35/Q35),0) -> 0 | X35: =IFERROR(Q35*(1-W35),"") -> 1361006.6 | Y35: 0 | Z35: NPD | BF35: =SUM(AV35:BE35) -> 0 | BH35: ePod 3 Device | BI35: SOP01.0 | BJ35: BAT | BK35: 45698 | BL35: ePod3 descope | BM35: 0 | BN35: 0 | BO35: 2085900 | BP35: 1135900 | CD35: 0 | CE35: 0 | CF35: 0 | CG35: 0 | CH35: 0 | CI35: 0 | CJ35: 0 | CK35: 0 | CL35: 0 | CM35: 0 | CN35: 0 | CO35: 0 | CP35: 0 | CQ35: 0 | CR35: 21600 | CS35: 227600 | CT35: 447400 | CU35: 285400 | CV35: 200900 | CW35: 353700 | CX35: 307000 | CY35: 121200 | CZ35: 77500 | DA35: 43600 | DB35: 46800 | DC35: 29400 | DD35: 229500 | DE35: 111600 | DF35: 154900 | DG35: 79300 | DH35: 21600 | DI35: 105200 | DJ35: 52400 | DK35: 91800 | DL35: 75600 | DM35: 137800 | DN35: 77900 | DO35: 36900 | DP35: 51000 | DQ35: 42100 | DR35: 32600 | DS35: 49400 | DT35: 40000 | DU35: 48800 | DV35: 48400 | DW35: 34700 | DX35: 23800 | DY35: 25200
A36: 28 | B36: RF027_Hestia1.0 | C36: Hestia 1.0 | D36: epod2 to Hestia1.0 (5th line) | E36: RCS | F36: Pod | G36: CN | H36: Pod Automation (Line Upgrade) | I36: RCS | J36: T1 | K36: Smoore T1 | L36: NVT | M36: TBC | N36: TBC | O36: 6590000 | P36: RMB | Q36: =IF(P36="RMB",O36/$B$6,IF(P36="GBP",O36,O36/$B$5)) -> 716480.35 | T36: By Unit | U36: =IF(T36="By Unit", IF(P36="RMB",S36/$B$6,IF(P36="GBP",S36,S36/$B$5)),T36) -> 0 | W36: =IF(T36="By Volume",V36/R36,V36*U36/Q36) -> 0 | X36: =IFERROR(Q36*(1-W36),"") -> 716480.35 | Y36: 0 | Z36: NPD | BF36: =SUM(AV36:BE36) -> 0 | BH36: TX500 | BI36: SOP12.1 | BJ36: BAT | BK36: 45635 | BL36: TX500 | BM36: 0 | BN36: 81177917 | BO36: 45566346 | BP36: 12000 | BQ36: 0 | BR36: 0 | BS36: 0 | BT36: 0 | BU36: 0 | BV36: 0 | BW36: 0 | BX36: 0 | BY36: 0 | BZ36: 0 | CA36: 0 | CB36: 0 | CD36: 0 | CE36: 0 | CF36: 0 | CG36: 932000 | CH36: 2904000 | CI36: 6345360 | CJ36: 12084000 | CK36: 12364000 | CL36: 14666000 | CM36: 7120798 | CN36: 16391759 | CO36: 8370000 | CP36: 7091800 | CQ36: 7861600 | CR36: 8626600 | CS36: 11847400 | CT36: 4344600 | CU36: 2568000 | CV36: 972000 | CW36: 905946 | CX36: 912200 | CY36: 252000 | CZ36: 48000 | DA36: 136200 | DB36: 12000 | DC36: 0 | DD36: 0 | DE36: 0 | DF36: 0 | DG36: 0 | DH36: 0 | DI36: 0 | DJ36: 0 | DK36: 0 | DL36: 0 | DM36: 0 | DN36: 0 | DO36: 0 | DP36: 0 | DQ36: 0 | DR36: 0 | DS36: 0 | DT36: 0 | DU36: 0 | DV36: 0 | DW36: 0 | DX36: 0 | DY36: 0
A37: 29 | B37: RF028_Kuma | C37: Kuma E 2.0 Pen | D37: semi-auto for Kuma E 2.0 Pen | E37: RCS | F37: Device | G37: CN | H37: Asset - RCS Device line | I37: RCS | J37: T1 | K37: Smoore T1 | L37: NVT | M37: 45747 | N37: 46477 | O37: 2126778 | P37: RMB | Q37: =IF(P37="RMB",O37/$B$6,IF(P37="GBP",O37,O37/$B$5)) -> 231228.32 | R37: 5400000 | S37: 0.3938 | T37: By Unit | U37: =IF(T37="By Unit", IF(P37="RMB",S37/$B$6,IF(P37="GBP",S37,S37/$B$5)),T37) -> 0.042814865 | V37: =SUM(AV37:AV37) -> 171720 | W37: =IF(T37="By Volume",V37/R37,V37*U37/Q37) -> 0.031796142 | X37: =IFERROR(Q37*(1-W37),"") -> 223876.15 | Y37: 0 | Z37: Under Amortization | AD37: =IF(U37="By Volume",(1-W37)*R37,X37/U37) -> 5228935.2 | AT37: =DN19 -> 25200 | AU37: =DO19 -> 440 | AV37: =DP19 -> 171720 | AW37: =DQ19 -> 208800 | AX37: =DR19 -> 170818 | AY37: =DS19 -> 382597.62 | AZ37: =DT19 -> 356973.74 | BA37: =DU19 -> 489469.07 | ... BE37: =DY19 -> 405790.38 | BF37: =SUM(AV37:BE37) -> 3668459 | BI37: SOP12.1 | BJ37: BAT | BK37: 0 | BL37: TX500 | BM37: 0 | BN37: 81177917 | BO37: 0 | BP37: 0 | CG37: 932000 | CH37: 2904000 | CI37: 6345360 | CJ37: 12084000 | CK37: 12364000 | CL37: 14666000 | CM37: 7120798 | CN37: 16391759 | CO37: 8370000 | CP37: 0 | CQ37: 0 | CR37: 0 | CS37: 0 | CT37: 0 | CU37: 0 | CV37: 0 | CW37: 0 | CX37: 0 | CY37: 0 | CZ37: 0 | DA37: 0 | DB37: 0 | DC37: 0 | DD37: 0 | DE37: 0 | DF37: 0 | DG37: 0 | DH37: 0 | DI37: 0 | DJ37: 0 | DK37: 0 | DL37: 0 | DM37: 0 | DN37: 0 | DO37: 0 | DP37: 0 | DQ37: 0 | DR37: 0 | DS37: 0 | DT37: 0 | DU37: 0 | DV37: 0 | DW37: 0 | DX37: 0 | DY37: 0
A38: 30 | B38: RF029_Kuma | C38: Kuma E 2.0 Box | D38: semi-auto for Kuma E 2.0 Box | E38: RCS | F38: Device | G38: CN | H38: Asset - RCS Device line | I38: RCS | J38: T1 | K38: Smoore T1 | L38: NVT | M38: 45761 | N38: 46491 | O38: 1682778 | P38: RMB | Q38: =IF(P38="RMB",O38/$B$6,IF(P38="GBP",O38,O38/$B$5)) -> 182955.6 | R38: 5400000 | S38: 0.3084 | T38: By Unit | U38: =IF(T38="By Unit", IF(P38="RMB",S38/$B$6,IF(P38="GBP",S38,S38/$B$5)),T38) -> 0.033529976 | W38: =IF(T38="By Volume",V38/R38,V38*U38/Q38) -> 0 | X38: =IFERROR(Q38*(1-W38),"") -> 182955.6 | Y38: 0 | Z38: NPD | BF38: =SUM(AV38:BE38) -> 0 | BI38: 0 | BJ38: BAT | BK38: 0 | BL38: TX500 | BM38: 0 | BN38: 78480075 | BO38: 0 | BP38: 0 | CF38: 0 | CG38: 932000 | CH38: 2904000 | CI38: 6344000 | CJ38: 10214553 | CK38: 11960620 | CL38: 14242345 | CM38: 7120798 | CN38: 16391759 | CO38: 8370000 | CP38: 0 | CQ38: 0 | CR38: 0 | CS38: 0 | CT38: 0 | CU38: 0 | CV38: 0 | CW38: 0 | CX38: 0 | CY38: 0 | CZ38: 0 | DA38: 0 | DB38: 0 | DC38: 0 | DD38: 0 | DE38: 0 | DF38: 0 | DG38: 0 | DH38: 0 | DI38: 0 | DJ38: 0 | DK38: 0 | DL38: 0 | DM38: 0 | DN38: 0 | DO38: 0 | DP38: 0 | DQ38: 0 | DR38: 0 | DS38: 0 | DT38: 0 | DU38: 0 | DV38: 0 | DW38: 0 | DX38: 0 | DY38: 0
A39: 31 | B39: RF030_Mimosa | C39: Mimosa | D39: semi-auto for Mimosa1.0 + 2 Glue Machine | E39: RCS | F39: Device | G39: CN | H39: Asset - RCS Device line | I39: RCS | J39: T1 | K39: Smoore T1 | L39: NVT | M39: 45689 | N39: 46411 | O39: 4352000 | P39: RMB | Q39: =IF(P39="RMB",O39/$B$6,IF(P39="GBP",O39,O39/$B$5)) -> 473159.71 | R39: 4800000 | S39: 0.91 | T39: By Unit | U39: =IF(T39="By Unit", IF(P39="RMB",S39/$B$6,IF(P39="GBP",S39,S39/$B$5)),T39) -> 0.098937348 | V39: =SUM(AU39) -> 3744 | W39: =IF(T39="By Volume",V39/R39,V39*U39/Q39) -> 0.00078286765 | X39: =IFERROR(Q39*(1-W39),"") -> 472789.29 | Y39: 0 | Z39: Under Amortization | AD39: =IF(U39="By Volume",(1-W39)*R39,X39/U39) -> 4778673.6 | AT39: 0 | AU39: 3744 | AV39: 72000 | AW39: 153000 | AX39: 99000 | AY39: 18000 | AZ39: 36336 | BA39: 56016 | BB39: 38736 | BC39: 46032 | BD39: 44928 | BE39: 43776 | BF39: =SUM(AV39:BE39) -> 607824 | BH39: DP1500 | BI39: 0 | BJ39: BAT | BK39: 45635 | BL39: DP1500 | BM39: 0 | BN39: 5012030 | BO39: 13033000 | BP39: 3795000 | BQ39: 0 | BR39: 0 | BS39: 0 | BT39: 0 | BU39: 0 | BV39: 0 | BW39: 0 | BX39: 0 | BY39: 0 | BZ39: 0 | CA39: 0 | CB39: 0 | CD39: 0 | CE39: 0 | CF39: 0 | CG39: 0 | CH39: 0 | CI39: 0 | CJ39: 0 | CK39: 0 | CL39: 0 | CM39: 0 | CN39: 1812030 | CO39: 3200000 | CP39: 1984000 | CQ39: 576000 | CR39: 1716000 | CS39: 1409000 | CT39: 636000 | CU39: 1406600 | CV39: 1608000 | CW39: 840000 | CX39: 1418400 | CY39: 647000 | CZ39: 420000 | DA39: 372000 | DB39: 204000 | DC39: 279000 | DD39: 324000 | DE39: 984000 | DF39: 276000 | DG39: 862000 | DH39: 60000 | DI39: 264000 | DJ39: 242000 | DK39: 180000 | DL39: 24000 | DM39: 96000 | DN39: 96000 | DO39: 0 | DP39: 0 | DQ39: 0 | DR39: 0 | DS39: 0 | DT39: 0 | DU39: 0 | DV39: 0 | DW39: 0 | DX39: 0 | DY39: 0
A40: 32 | B40: RF031_Hestia1.0 | C40: Hestia 1.0 | D40: Tax stamp and CCD capex amortization | E40: RCS | F40: Pod | G40: CN | H40: Asset - Others | I40: RCS | J40: T1 | K40: Smoore T1 | L40: NVT | M40: 45566 | N40: 48122 | O40: 760000 | P40: RMB | Q40: =IF(P40="RMB",O40/$B$6,IF(P40="GBP",O40,O40/$B$5)) -> 82628.994 | S40: 0.028896174 | T40: By Unit | U40: =IF(T40="By Unit", IF(P40="RMB",S40/$B$6,IF(P40="GBP",S40,S40/$B$5)),T40) -> 0.0031416602 | V40: =SUM(AE40:AU40) -> 5988600 | W40: =IF(T40="By Volume",V40/R40,V40*U40/Q40) -> 0.22769425 | X40: =IFERROR(Q40*(1-W40),"") -> 63814.847 | Y40: =IF(X40>0,X40,0) -> 63814.847 | Z40: Under Amortization | AD40: =IF(U40="By Volume",(1-W40)*R40,X40/U40) -> 20312460 | AR40: 252540 | AS40: 208440 | AT40: 2761020 | AU40: 2766600 | AV40: 3869820 | AW40: =1762020+2693340 -> 4455360 | AX40: 2013300 | AY40: 2991600 | AZ40: 2957040 | BA40: 3942180 | BB40: 3335760 | BC40: 3791340 | BD40: 5151240 | BE40: 3408300 | BF40: =SUM(AV40:BE40) -> 35915940 | BI40: SOP12.1 | BJ40: BAT | BK40: 2022/2/3-Core+Sensitivity | BL40: DP1500 | BM40: 0 | BN40: 5012030 | BO40: 0 | BP40: 0 | CF40: 0 | CK40: 0 | CL40: 0 | CN40: 1812030 | CO40: 3200000 | CP40: 0 | CQ40: 0 | CR40: 0 | CS40: 0 | CT40: 0 | CU40: 0 | CV40: 0 | CW40: 0 | CX40: 0 | CY40: 0 | CZ40: 0 | DA40: 0 | DB40: 0 | DC40: 0 | DD40: 0 | DE40: 0 | DF40: 0 | DG40: 0 | DH40: 0 | DI40: 0 | DJ40: 0 | DK40: 0 | DL40: 0 | DM40: 0 | DN40: 0 | DO40: 0 | DP40: 0 | DQ40: 0 | DR40: 0 | DS40: 0 | DT40: 0 | DU40: 0 | DV40: 0 | DW40: 0 | DX40: 0 | DY40: 0
A41: 33 | B41: RF032_Alto | C41: Alto | D41: Alto tooling(IM tooling for 2p cost reduction) | E41: Pod | F41: Pod | G41: Indo | H41: Tooling | I41: RCS | J41: T2 | K41: Smoore T2 | L41: Reynolds | M41: 44980 | N41: 46722 | O41: 5098268.4 | P41: USD | Q41: =IF(P41="RMB",O41/$B$6,IF(P41="GBP",O41,O41/$B$5)) -> 3988693.6 | R41: 480000000 | S41: 0.0106 | T41: By Unit | U41: =IF(T41="By Unit", IF(P41="RMB",S41/$B$6,IF(P41="GBP",S41,S41/$B$5)),T41) -> 0.0082930417 | V41: =SUM(AE41:AU41) -> 523629650 | W41: =IF(T41="By Volume",V41/R41,V41*U41/Q41) -> 1.0886979 | X41: 0 | Y41: 0 | Z41: Amortization Completed | AG41: 224601000 | AH41: 22785000 | AI41: 22092200 | AJ41: 25589000 | AK41: 18498600 | AL41: 30742700 | AM41: 18494250 | AN41: 25532300 | AO41: 28932600 | AP41: 11088600 | AQ41: 14612550 | AR41: 17543850 | AS41: 18060400 | AT41: ='By Project -Feb 2025'!DN59 -> 29540200 | AU41: ='By Project -Feb 2025'!DO59 -> 15516400 | AV41: ='By Project -Feb 2025'!DP59 -> 46369950 | AW41: ='By Project -Feb 2025'!DQ59 -> 39955200 | AX41: ='By Project -Feb 2025'!DR59 -> 25506950 | AY41: ='By Project -Feb 2025'!DS59 -> 21583600 | AZ41: ='By Project -Feb 2025'!DT59 -> 27334550 | BA41: ='By Project -Feb 2025'!DU59 -> 22483600 | ... BE41: ='By Project -Feb 2025'!DY59 -> 25290000 | BF41: =SUM(AV41:BE41) -> 274710800 | BI41: 2022/2/3-Core+Sensitivity | BJ41: BAT | BK41: 2022/2/3-PO+Production | BL41: DP1500 | BM41: 0 | BN41: 5012030 | BO41: 0 | BP41: 0 | CF41: 0 | CK41: 0 | CL41: 0 | CN41: 1812030 | CO41: 3200000 | CP41: 0 | CQ41: 0 | CR41: 0 | CS41: 0 | CT41: 0 | CU41: 0 | CV41: 0 | CW41: 0 | CX41: 0 | CY41: 0 | CZ41: 0 | DA41: 0 | DB41: 0 | DC41: 0 | DD41: 0 | DE41: 0 | DF41: 0 | DG41: 0 | DH41: 0 | DI41: 0 | DJ41: 0 | DK41: 0 | DL41: 0 | DM41: 0 | DN41: 0 | DO41: 0 | DP41: 0 | DQ41: 0 | DR41: 0 | DS41: 0 | DT41: 0 | DU41: 0 | DV41: 0 | DW41: 0 | DX41: 0 | DY41: 0
...

Sheet ME Capex 
A1: Project | B1: Project | C1: Product Category | D1: Part Name | E1: Part No. | F1: Supplier | G1: Commonality | H1: Commodity | I1: Year | J1: Month | K1: Data Submit Date | L1: Split | M1: Unit price w/o amortization | N1: Unit Price with Amortization | O1: Amortization Cost | P1: Blended Amortization Cost | Q1: Usage in BOM | R1: BOM cost | S1: Shipped Volume | T1: Cum Shipped Volume | U1: Total Capex Cost | V1: Remaining Capex Cost (RMB) | W1: Remaining Capex Cost (GBP) | X1: TOTAL VOLUME TO PAY INESTMENT OFF | Z1: Total PAID
