Workbook
Name \A: #REF!
Name \A: #REF!
Name \A: #REF!
Name \C: #REF!
Name \C: #REF!
Name \C: #REF!
Name \D: #REF!
Name \D: #REF!
Name \D: #REF!
Name \W: #REF!
Name \W: #REF!
Name \W: #REF!
Name _: #REF!
Name _: #REF!
Name _: #REF!
Name __: #REF!
Name __: #REF!
Name __: #REF!
Name ___: #REF!
Name ___: #REF!
Name ___: #REF!
Name ______0: #REF!
Name ______0: #REF!
Name ______0: #REF!
Name ______0___0: #REF!
Name ______0___0: #REF!
Name ______0___0: #REF!
Name ______4: "$"
Name ______5: "$"
Name ______6: "$"
Name __m72: {"傳各位表單.xls","Sheet1"}
Name __m72: {"傳各位表單.xls","Sheet1"}
Name __m72: {"傳各位表單.xls","Sheet1"}
Name __m72_1: {"傳各位表單.xls","Sheet1"}
Name __m72_1: {"傳各位表單.xls","Sheet1"}
Name __m72_1: {"傳各位表單.xls","Sheet1"}
Name __m72_2: {"傳各位表單.xls","Sheet1"}
Name __m72_2: {"傳各位表單.xls","Sheet1"}
Name __m72_2: {"傳各位表單.xls","Sheet1"}
Name __m72_3: {"傳各位表單.xls","Sheet1"}
Name __m72_3: {"傳各位表單.xls","Sheet1"}
Name __m72_3: {"傳各位表單.xls","Sheet1"}
Name __m72_4: {"傳各位表單.xls","Sheet1"}
Name __m72_4: {"傳各位表單.xls","Sheet1"}
Name __m72_4: {"傳各位表單.xls","Sheet1"}
Name _017: #REF!
Name _017: #REF!
Name _017: #REF!
Name _024: #REF!
Name _024: #REF!
Name _024: #REF!
Name _039: #REF!
Name _039: #REF!
Name _039: #REF!
Name _1.: #REF!
Name _1.: #REF!
Name _1.: #REF!
Name _1_0: #REF!
Name _1_0: #REF!
Name _1_0: #REF!

Sheet Capex
S1: CNY | T1: GBP
C2: Investment/Liabilities Dashboard | S2: =34746341 -> 34746341 | T2: =S2/8.812 -> 3943070.9
C3: New Categories - Vapour | S3: 24216741 | T3: =S3/8.812 -> 2748154.9
T4: =SUM(T2:T3) -> 6691225.8
A5: USD-GBP | B5: 1.27818
A6: RMB-GBP | B6: 9.19774 | C6: 0.025813404
B7: Prpcurement/Finance
A9: # | B9: Unique Ref Number | C9: Project | D9: Project Description | E9: SC Owner | F9: Procurement Owner | G9: Portfolio | H9: Platform | I9: Location | J9: Type | K9: Portfolio1 | L9: Tier | M9: Supplier | N9: Contracting Entity | O9: Start Date | P9: End Date | Q9: Investment Quotation | R9: Investment Currency | S9: Investment (GBP) | T9: Committed PO Volume | U9: Amortization per Unit | V9: Amortization per Unit (GBP)
A10: 1 | B10: RF001_Alto &ePod | C10: Alto & ePod | D10: APA - Automation Production Agreement | E10: Angie Huang | F10: Reggie Zhu | G10: Pod | H10: Pod | I10: Indo | J10: Pod Automation (initial Investment) | K10: RCS | L10: T1 | M10: Smoore T1 | N10: Reynolds | O10: 44197 | P10: 46722 | Q10: 72000000 | R10: USD | S10: =IF(R10="RMB",Q10/$B$6,IF(R10="GBP",Q10,Q10/$B$5)) -> 56330094 | T10: 2570000000 | U10: Volume
A11: 2 | B11: RF002_Alto | C11: Alto | D11: Addendum No.10 - Indonesia | E11: Angie Huang | F11: Reggie Zhu | G11: Pod | H11: Pod | I11: Indo | J11: Indo Facility | K11: RCS | L11: T1 | M11: Smoore T1 | N11: Reynolds | O11: 44682 | P11: 46722 | Q11: 41140309 | R11: USD | S11: =IF(R11="RMB",Q11/$B$6,IF(R11="GBP",Q11,Q11/$B$5)) -> 32186632 | T11: 2340000000 | U11: 0.0152 | V11: =IF(R11="RMB",U11/$B$6,IF(R11="GBP",U11,U11/$B$5)) -> 0.011891909
A12: 4 | B12: RF003_Alto | C12: Alto | D12: Alto Pod Investment fee for Inkjet printing | E12: Angie Huang | F12: Reggie Zhu | G12: Pod | H12: Pod | I12: Indo | J12: Asset - Others | K12: RCS | L12: T1 | M12: Smoore T1 | N12: Reynolds | O12: 45344 | P12: - | Q12: 2020422.1 | R12: USD | S12: =IF(R12="RMB",Q12/$B$6,IF(R12="GBP",Q12,Q12/$B$5)) -> 1580702.4 | T12: 0 | U12: n/a
A13: 5 | B13: RF004_Alto | C13: Alto | D13: Device to Indo Equipment move cost | E13: Angie Huang | F13: Reggie Zhu | G13: RCS | H13: Vuse Device( US Alto) | I13: Indo | J13: Asset - RCS Device line | K13: RCS | L13: T1 | M13: Smoore T1 | N13: Reynolds | O13: 45345 | P13: 46722 | Q13: 650000 | R13: USD | S13: =IF(R13="RMB",Q13/$B$6,IF(R13="GBP",Q13,Q13/$B$5)) -> 508535.57 | T13: 20000000 | U13: 0.032288552 | V13: =IF(R13="RMB",U13/$B$6,IF(R13="GBP",U13,U13/$B$5)) -> 0.02526135
A14: 6 | B14: RF005_Alto | C14: Alto | D14: Alto Blister Reduction Capex | E14: Angie Huang | F14: Reggie Zhu | G14: Pod | H14: Pod | I14: Indo | J14: Asset - Others | K14: RCS | L14: T1 | M14: Smoore T1 | N14: Reynolds | O14: 45597 | P14: 46722 | Q14: 886091.64 | R14: USD | S14: =IF(R14="RMB",Q14/$B$6,IF(R14="GBP",Q14,Q14/$B$5)) -> 693244.8 | T14: 400000000 | U14: =Q14/T14 -> 0.0022152291 | V14: =IF(R14="RMB",U14/$B$6,IF(R14="GBP",U14,U14/$B$5)) -> 0.001733112
A15: 7 | B15: RF006_Alto | C15: Prismatic Pod | D15: Prismastic China project capex | E15: Angie Huang | F15: Reggie Zhu | G15: Pod | H15: Pod | I15: Indo | J15: Asset - Others | K15: RCS | L15: T1 | M15: Smoore T1 | N15: Reynolds | O15: - | P15: - | Q15: 1562511 | R15: RMB | S15: =IF(R15="RMB",Q15/$B$6,IF(R15="GBP",Q15,Q15/$B$5)) -> 169879.88 | U15: Volume
A16: 8 | B16: RF007_Epod&Modi | C16: Epod&Modi | D16: Tax Stamp(Pod2+ePod3 Czech,Germany,Poland&Italy) | E16: Susie Su | F16: Reggie Zhu | G16: RCS | H16: Vuse device(ROW) | I16: CN | J16: Asset - Others | K16: RCS | L16: T1 | M16: Smoore T1 | N16: NVT | O16: 45261 | P16: 46722 | Q16: 714000 | R16: RMB | S16: =IF(R16="RMB",Q16/$B$6,IF(R16="GBP",Q16,Q16/$B$5)) -> 77627.765 | T16: 8572763 | U16: 0.083287034 | V16: =IF(R16="RMB",U16/$B$6,IF(R16="GBP",U16,U16/$B$5)) -> 0.0090551629
A17: 9 | B17: RF008_Modi2.0 | C17: Modi 2.0 | D17: Automation Flexible Line for Modi 2.0 Platform 1K PEN Default/Full and 1k BOX Full | E17: Allan Liang | F17: Cailine Huang | G17: MD | H17: MD 2.0 | I17: CN | J17: Asset - Modi Line | K17: MoDi | L17: T1 | M17: Smoore T1 | N17: NVT | O17: 45505 | P17: 46235 | Q17: 4912380 | R17: RMB | S17: =IF(R17="RMB",Q17/$B$6,IF(R17="GBP",Q17,Q17/$B$5)) -> 534085.55 | T17: =S17/0.007 -> 76297935 | U17: =0.007*8.81203 -> 0.06168421 | V17: =IF(R17="RMB",U17/$B$6,IF(R17="GBP",U17,U17/$B$5)) -> 0.0067064529
A18: 10 | B18: RF009_Hestia1.0 | C18: Hestia 1.0 | D18: Hestia 1.0 Automation Lines Modification (Modified from ePod3 to Hestia1.0) (1-4 line) | E18: Susie Su | F18: Daisy Cai | G18: Pod | H18: Pod | I18: CN | J18: Pod Automation (Line Upgrade) | K18: RCS | L18: T1 | M18: Smoore T1 | N18: NVT | O18: 45406 | P18: 46113 | Q18: 34746341 | R18: RMB | S18: =IF(R18="RMB",Q18/$B$6,IF(R18="GBP",Q18,Q18/$B$5)) -> 3777704.2 | T18: 246400000 | U18: =Q18/T18 -> 0.14101599 | V18: =IF(R18="RMB",U18/$B$6,IF(R18="GBP",U18,U18/$B$5)) -> 0.015331592
A19: 11 | B19: RF010_Hestia1.0 | C19: Hestia 1.0 | D19: Hestia1.0 Manual line capex | E19: Susie Su | F19: Daisy Cai | G19: Pod | H19: Pod | I19: CN | J19: Asset - Others | K19: RCS | L19: T1 | M19: Smoore T1 | N19: NVT | O19: 45406 | P19: 45505 | Q19: - | R19: RMB | S19: 0 | T19: 0 | U19: 0.036 | V19: =IF(R19="RMB",U19/$B$6,IF(R19="GBP",U19,U19/$B$5)) -> 0.003914005
A20: 12 | B20: RF011_ePod2Pod | C20: ePod2 Pod | D20: ePod Packer - Included in Hestia | E20: Susie Su | F20: Daisy Cai | G20: Pod | H20: Pod | I20: CN | J20: Automation - Packing | K20: RCS | L20: T1 | M20: Smoore T1 | N20: NVT | O20: 44197 | P20: 46357 | Q20: 2660000 | R20: USD | S20: =IF(R20="RMB",Q20/$B$6,IF(R20="GBP",Q20,Q20/$B$5)) -> 2081084 | T20: 175000000 | U20: Volume
A21: 13 | B21: RF012_ePod3Pod | C21: ePod3 Pod | D21: ePod 3 Automation Modification Capex Amortization (1P) Modified from ePod2 to ePod3 | E21: Susie Su | F21: Daisy Cai | G21: Pod | H21: Pod | I21: CN | J21: Pod Automation (Line Upgrade) | K21: RCS | L21: T1 | M21: Smoore T1 | N21: NVT | O21: 44980 | P21: 45689 | Q21: 1503259 | R21: RMB | S21: =IF(R21="RMB",Q21/$B$6,IF(R21="GBP",Q21,Q21/$B$5)) -> 163437.87 | T21: =6430000*4/(0.01*8.87287) -> 2.8987239e+08 | U21: 0.0887284 | V21: =IF(R21="RMB",U21/$B$6,IF(R21="GBP",U21,U21/$B$5)) -> 0.0096467611
A22: 14 | B22: RF013_Kuma | C22: Kuma 1.0 | D22: KUMA E-ROW Ultra Sonic Machine | E22: Lyn Wu | F22: Daisy Cai | G22: RCS | H22: Vuse device(ROW) | I22: CN | J22: Asset - RCS Device line | K22: RCS | L22: T1 | M22: Smoore T1 | N22: NVT | O22: 45383 | P22: 46113 | Q22: 640000 | R22: RMB | S22: =IF(R22="RMB",Q22/$B$6,IF(R22="GBP",Q22,Q22/$B$5)) -> 69582.31 | T22: =Q22/U22 -> 11034483 | U22: 0.058 | V22: =IF(R22="RMB",U22/$B$6,IF(R22="GBP",U22,U22/$B$5)) -> 0.0063058969
A23: 15 | B23: RF014_Kuma | C23: Kuma 1.0 | D23: KUMA E-Pen Laser welding machine & Kuma E-Pen 1.0 air tightness test machine | E23: Lyn Wu | F23: Daisy Cai | G23: RCS | H23: Vuse device(ROW) | I23: CN | J23: Asset - RCS Device line | K23: RCS | L23: T1 | M23: Smoore T1 | N23: NVT | O23: 45505 | P23: 46235 | Q23: =708000+72300 -> 780300 | R23: RMB | S23: =IF(R23="RMB",Q23/$B$6,IF(R23="GBP",Q23,Q23/$B$5)) -> 84836.058 | U23: 0.094674863 | V23: =IF(R23="RMB",U23/$B$6,IF(R23="GBP",U23,U23/$B$5)) -> 0.010293275
A24: 16 | B24: RF015_Modi&RCS | C24: Modi & RCS | D24: CCD&Tax Stamp Machine MD2.0 1K PEN Default Czech/Germany/Poland/Italy/BUL (Machines can be cross-used by both Modi & RCS) | E24: Allan Liang | F24: Cailine Huang | G24: MD | H24: MD 2.0 | I24: CN | J24: Asset - Others | K24: Modi | L24: T1 | M24: Smoore T1 | N24: NVT | O24: 45505 | P24: 46966 | Q24: 1210000 | R24: RMB | S24: =IF(R24="RMB",Q24/$B$6,IF(R24="GBP",Q24,Q24/$B$5)) -> 131554.06 | T24: 29491560 | U24: 0.041028688 | V24: =IF(R24="RMB",U24/$B$6,IF(R24="GBP",U24,U24/$B$5)) -> 0.0044607357
A25: 17 | B25: RF016_Sensa | C25: Sensa | D25: Sensa Manual Line Capex | E25: Frank Lin | F25: Cailine Huang | G25: MD | H25: MD 2.0 | I25: CN | J25: Asset - Others | K25: Modi | L25: T1 | M25: Smoore T1 | N25: NVT | O25: 45474 | P25: 45992 | Q25: 903370.28 | R25: RMB | S25: =IF(R25="RMB",Q25/$B$6,IF(R25="GBP",Q25,Q25/$B$5)) -> 98216.549 | T25: 8895000 | U25: =0.0115*8.81203 -> 0.10133834 | V25: =IF(R25="RMB",U25/$B$6,IF(R25="GBP",U25,U25/$B$5)) -> 0.011017744
A26: 18 | B26: RF017_Sensa | C26: Sensa | D26: Sensa Semi-Auto Line Capex | E26: Frank Lin | F26: Cailine Huang | G26: MD | H26: MD 2.0 | I26: CN | J26: Asset - Modi Line | K26: Modi | L26: T1 | M26: Smoore T1 | N26: NVT | O26: 45536 | P26: 45992 | Q26: 6018424 | R26: RMB | S26: =IF(R26="RMB",Q26/$B$6,IF(R26="GBP",Q26,Q26/$B$5)) -> 654337.26 | T26: 12960000 | U26: =0.0527*8.81203 -> 0.46439398 | V26: =IF(R26="RMB",U26/$B$6,IF(R26="GBP",U26,U26/$B$5)) -> 0.05049001
A27: 19 | B27: RF018_Modi | C27: Modi | D27: T&T longterm solution cost Amortize at Uzbekistan TX500 and DP1500（UZB—乌兹别克斯坦） | E27: Allan Liang | F27: Cailine Huang | G27: MD | H27: MD1.0 | I27: CN | J27: Asset - Others | K27: Modi | L27: T1 | M27: Smoore T1 | N27: NVT | O27: 44986 | P27: 46447 | Q27: 1363867.4 | R27: RMB | S27: =IF(R27="RMB",Q27/$B$6,IF(R27="GBP",Q27,Q27/$B$5)) -> 148282.88 | T27: 4682003 | U27: =Q27/T27 -> 0.29129998 | V27: =IF(R27="RMB",U27/$B$6,IF(R27="GBP",U27,U27/$B$5)) -> 0.031670821
A28: 20 | B28: RF019_Modi | C28: Modi | D28: KZ MODI testing / support for T&T Amortize at KAZ TX500 and DP1500（KZ—哈萨克斯坦） | E28: Allan Liang | F28: Cailine Huang | G28: MD | H28: MD1.0 | I28: CN | J28: Asset - Others | K28: Modi | L28: T1 | M28: Smoore T1 | N28: NVT | O28: 45108 | P28: 46569 | Q28: 130573.98 | R28: RMB | S28: =IF(R28="RMB",Q28/$B$6,IF(R28="GBP",Q28,Q28/$B$5)) -> 14196.311 | T28: 1020000 | U28: =Q28/T28 -> 0.12801371 | V28: =IF(R28="RMB",U28/$B$6,IF(R28="GBP",U28,U28/$B$5)) -> 0.013917952
A29: 21 | B29: RF020_Modi | C29: Modi | D29: T&T Interim programme of Azerbaijan Amortize at Azerbaijan 1k/3k/5k product（AZB—阿塞拜疆） | E29: Allan Liang | F29: Cailine Huang | G29: MD | H29: MD1.0 | I29: CN | J29: Asset - Others | K29: Modi | L29: T1 | M29: Smoore T1 | N29: NVT | O29: 45017 | P29: 46478 | Q29: 95728.992 | R29: RMB | S29: =IF(R29="RMB",Q29/$B$6,IF(R29="GBP",Q29,Q29/$B$5)) -> 10407.882 | V29: =IF(R29="RMB",U29/$B$6,IF(R29="GBP",U29,U29/$B$5)) -> 0
A30: 22 | B30: RF021_Modi | C30: Modi | D30: T&T for Pre-Dispatch Advice --add extra function（UZB—乌兹别克斯坦 KZ—哈萨克斯坦） | E30: Allan Liang | F30: Cailine Huang | G30: MD | H30: MD1.0 | I30: CN | J30: Asset - Others | K30: Modi | L30: T1 | M30: Smoore T1 | N30: NVT | O30: 45017 | P30: 46478 | Q30: 706075.2 | R30: RMB | S30: =IF(R30="RMB",Q30/$B$6,IF(R30="GBP",Q30,Q30/$B$5)) -> 76766.162 | V30: =IF(R30="RMB",U30/$B$6,IF(R30="GBP",U30,U30/$B$5)) -> 0
A31: 23 | B31: RF022_Modi | C31: Modi | D31: KZ MODI testing / support for T&T Amortize at BOX3K&5K KAZ&UZB market（KZ—哈萨克斯坦） | E31: Allan Liang | F31: Cailine Huang | G31: MD | H31: MD1.0 | I31: CN | J31: Asset - Others | K31: Modi | L31: T1 | M31: Smoore T1 | N31: NVT | O31: 45108 | P31: 46569 | Q31: 46448.488 | R31: RMB | S31: =IF(R31="RMB",Q31/$B$6,IF(R31="GBP",Q31,Q31/$B$5)) -> 5049.9892 | T31: 3976000 | U31: 0.011682215 | V31: =IF(R31="RMB",U31/$B$6,IF(R31="GBP",U31,U31/$B$5)) -> 0.001270118
A32: 24 | B32: RF023_Modi | C32: Modi | D32: AZB T&T longterm solution cost for TX500&DP1500&BOX1K&3K&5K for AZB Market（AZB—阿塞拜疆） | E32: Allan Liang | F32: Cailine Huang | G32: MD | H32: MD1.0 | I32: CN | J32: Asset - Others | K32: Modi | L32: T1 | M32: Smoore T1 | N32: NVT | O32: 45017 | P32: 46478 | Q32: 466929.08 | R32: RMB | S32: =IF(R32="RMB",Q32/$B$6,IF(R32="GBP",Q32,Q32/$B$5)) -> 50765.632 | V32: =IF(R32="RMB",U32/$B$6,IF(R32="GBP",U32,U32/$B$5)) -> 0
A33: 25 | B33: RF024_Modi | C33: Modi | D33: Custom development BAT CMO INEXTRACK GS1 Novarator removal CR for AZB regulation（AZB—阿塞拜疆） | E33: Allan Liang | F33: Cailine Huang | G33: MD | H33: MD1.0 | I33: CN | J33: Asset - Others | K33: Modi | L33: T1 | M33: Smoore T1 | N33: NVT | O33: 45108 | P33: 46569 | Q33: 80274.71 | R33: RMB | S33: =IF(R33="RMB",Q33/$B$6,IF(R33="GBP",Q33,Q33/$B$5)) -> 8727.6559 | V33: =IF(R33="RMB",U33/$B$6,IF(R33="GBP",U33,U33/$B$5)) -> 0
A34: 27 | B34: RF025_Hestia1.1 | C34: Hestia 1.0 | D34: epod2 to Hestia1.1 non-smart | E34: Susie Su | F34: Daisy Cai | G34: RCS | H34: Pod | I34: CN | J34: Pod Automation (Line Upgrade) | K34: RCS | L34: T1 | M34: Smoore T1 | N34: NVT | Q34: 5756300 | R34: RMB | S34: =IF(R34="RMB",Q34/$B$6,IF(R34="GBP",Q34,Q34/$B$5)) -> 625838.52 | V34: =IF(R34="RMB",U34/$B$6,IF(R34="GBP",U34,U34/$B$5)) -> 0
A35: 26 | B35: RF026_Hestia1.1 | C35: Hestia 1.1 | D35: epod2 to Hestia1.1 smart | E35: Susie Su | F35: Daisy Cai | G35: RCS | H35: Pod | I35: CN | J35: Pod Automation (Line Upgrade) | K35: RCS | L35: T1 | M35: Smoore T1 | N35: NVT | O35: 45777 | P35: 46507 | Q35: 12518185 | R35: RMB | S35: =IF(R35="RMB",Q35/$B$6,IF(R35="GBP",Q35,Q35/$B$5)) -> 1361006.6 | T35: TBC | U35: TBC
A36: 28 | B36: RF027_Hestia1.0 | C36: Hestia 1.0 | D36: epod2 to Hestia1.0 (5th line) | E36: Susie Su | F36: Daisy Cai | G36: RCS | H36: Pod | I36: CN | J36: Pod Automation (Line Upgrade) | K36: RCS | L36: T1 | M36: Smoore T1 | N36: NVT | O36: TBC | P36: TBC | Q36: 6590000 | R36: RMB | S36: =IF(R36="RMB",Q36/$B$6,IF(R36="GBP",Q36,Q36/$B$5)) -> 716480.35 | V36: =IF(R36="RMB",U36/$B$6,IF(R36="GBP",U36,U36/$B$5)) -> 0
A37: 29 | B37: RF028_Kuma | C37: Kuma E 2.0 Pen | D37: semi-auto for Kuma E 2.0 Pen | E37: Lyn Wu | F37: Daisy Cai | G37: RCS | H37: Device | I37: CN | J37: Asset - RCS Device line | K37: RCS | L37: T1 | M37: Smoore T1 | N37: NVT | O37: 45747 | P37: 46477 | Q37: 2126778 | R37: RMB | S37: =IF(R37="RMB",Q37/$B$6,IF(R37="GBP",Q37,Q37/$B$5)) -> 231228.32 | T37: 5400000 | U37: 0.3938 | V37: =IF(R37="RMB",U37/$B$6,IF(R37="GBP",U37,U37/$B$5)) -> 0.042814865
A38: 30 | B38: RF029_Kuma | C38: Kuma E 2.0 Box | D38: semi-auto for Kuma E 2.0 Box | E38: Lyn Wu | F38: Daisy Cai | G38: RCS | H38: Device | I38: CN | J38: Asset - RCS Device line | K38: RCS | L38: T1 | M38: Smoore T1 | N38: NVT | O38: 45761 | P38: 46491 | Q38: 1682778 | R38: RMB | S38: =IF(R38="RMB",Q38/$B$6,IF(R38="GBP",Q38,Q38/$B$5)) -> 182955.6 | T38: 5400000 | U38: 0.3084 | V38: =IF(R38="RMB",U38/$B$6,IF(R38="GBP",U38,U38/$B$5)) -> 0.033529976
A39: 31 | B39: RF030_Mimosa | C39: Mimosa | D39: semi-auto for Mimosa1.0 + 2 Glue Machine | E39: Allan Liang | F39: Daisy Cai | G39: RCS | H39: Device | I39: CN | J39: Asset - RCS Device line | K39: RCS | L39: T1 | M39: Smoore T1 | N39: NVT | O39: 45689 | P39: 46411 | Q39: 4352000 | R39: RMB | S39: =IF(R39="RMB",Q39/$B$6,IF(R39="GBP",Q39,Q39/$B$5)) -> 473159.71 | T39: 4800000 | U39: 0.91 | V39: =IF(R39="RMB",U39/$B$6,IF(R39="GBP",U39,U39/$B$5)) -> 0.098937348
A40: 32 | B40: RF031_Hestia1.0 | C40: Hestia 1.0 | D40: Tax stamp and CCD capex amortization | E40: Susie Su | F40: Daisy Cai | G40: RCS | H40: Pod | I40: CN | J40: Asset - Others | K40: RCS | L40: T1 | M40: Smoore T1 | N40: NVT | O40: 45566 | P40: 48122 | Q40: 760000 | R40: RMB | S40: =IF(R40="RMB",Q40/$B$6,IF(R40="GBP",Q40,Q40/$B$5)) -> 82628.994 | U40: 0.028896174 | V40: =IF(R40="RMB",U40/$B$6,IF(R40="GBP",U40,U40/$B$5)) -> 0.0031416602
A41: 33 | B41: RF032_Alto | C41: Alto | D41: Alto tooling(IM tooling for 2p cost reduction) | E41: Angie Huang | F41: Candy Zhang | G41: Pod | H41: Pod | I41: Indo | J41: Tooling | K41: RCS | L41: T2 | M41: Smoore T2 | N41: Reynolds | O41: 44980 | P41: 46722 | Q41: 5098268.4 | R41: USD | S41: =IF(R41="RMB",Q41/$B$6,IF(R41="GBP",Q41,Q41/$B$5)) -> 3988693.6 | T41: 480000000 | U41: 0.0106 | V41: =IF(R41="RMB",U41/$B$6,IF(R41="GBP",U41,U41/$B$5)) -> 0.0082930417
...

Sheet Volume
C2: Investment/Liabilities Dashboard
C3: New Categories - Vapour
A5: USD-GBP | B5: 1.27818
A6: RMB-GBP | B6: 9.19774 | C6: 0.025813404 | S6: SC update
B7: Prpcurement/Finance | E7: Actual Shipment Qty | T7: Forecast (pls link tab'Summary') | AH7: BAT Demand Waterfall
A9: # | B9: Unique Ref Number | C9: Project | D9: Project Description | E9: Y2021 | F9: Y2022 | G9: Y2023 | H9: 45292 | I9: 45323 | J9: 45352 | K9: 45383 | L9: 45413 | M9: 45444 | N9: 45474 | O9: 45505 | P9: 45536 | Q9: 45566 | R9: 45597 | S9: 45627 | T9: 45658 | U9: 45689 | V9: 45717 | W9: 45748 | X9: 45778 | Y9: 45809 | Z9: 45839 | AA9: 45870 | AB9: 45901 | AC9: 45931 | AD9: 45962 | AE9: 45992 | AF9: YTG 2025 | AH9: T2 Product | AI9: Version | AJ9: Customer | AK9: SOP Date | AL9: Product | AM9: 2021 | AN9: 2022 | AO9: 2023 | AP9: 2024 | AQ9: 44197 | AR9: 44228 | AS9: 44256 | AT9: 44287 | AU9: 44317 | AV9: 44348 | AW9: 44378 | AX9: 44409 | AY9: 44440 | AZ9: 44470 | BA9: 44501 | BB9: 44531 | BD9: 44562 | BE9: 44593 | BF9: 44621 | BG9: 44652 | BH9: 44682 | BI9: 44713 | BJ9: 44743 | BK9: 44774 | BL9: 44805 | BM9: 44835 | BN9: 44866 | BO9: 44896 | BP9: 44927 | BQ9: 44958 | BR9: 44986 | BS9: 45017 | BT9: 45047 | BU9: 45078 | BV9: 45108 | BW9: 45139 | BX9: 45170 | BY9: 45200 | BZ9: 45231 | CA9: 45261 | CB9: 45292 | CC9: 45323 | CD9: 45352 | CE9: 45383 | CF9: 45413 | CG9: 45444 | CH9: 45474 | CI9: 45505 | CJ9: 45536 | CK9: 45566 | CL9: 45597 | CM9: 45627 | CN9: 45658 | CO9: 45689 | CP9: 45717 | CQ9: 45748 | CR9: 45778 | CS9: 45809 | CT9: 45839 | CU9: 45870 | CV9: 45901 | CW9: 45931 | CX9: 45962 | CY9: 45992
A10: 1 | B10: RF001_Alto &ePod | C10: Alto & ePod | D10: APA - Automation Production Agreement | E10: 523716080 | F10: 471530346 | G10: 404870290 | H10: 34094250 | I10: 27982380 | J10: 35881250 | K10: 33715264 | L10: 49761762 | M10: 49968522 | N10: 46294918 | O10: 57860634 | P10: 36903554 | Q10: 32308514 | R10: 34612990 | S10: 28195840 | T10: =Volume!CN10+Volume!CN11+Volume!CN22+Volume!CN34+Volume!CN59+Volume!CN62 -> 48220474 | U10: =Volume!CO10+Volume!CO11+Volume!CO22+Volume!CO34+Volume!CO59+Volume!CO62 -> 24769050 | V10: =Volume!CP10+Volume!CP11+Volume!CP22+Volume!CP34+Volume!CP59+Volume!CP62 -> 67126382 | W10: =Volume!CQ10+Volume!CQ11+Volume!CQ22+Volume!CQ34+Volume!CQ59+Volume!CQ62 -> 61797920 | X10: =Volume!CR10+Volume!CR11+Volume!CR22+Volume!CR34+Volume!CR59+Volume!CR62 -> 42129688 | Y10: =Volume!CS10+Volume!CS11+Volume!CS22+Volume!CS34+Volume!CS59+Volume!CS62 -> 42064888 | Z10: =Volume!CT10+Volume!CT11+Volume!CT22+Volume!CT34+Volume!CT59+Volume!CT62 -> 45832074 | AA10: =Volume!CU10+Volume!CU11+Volume!CU22+Volume!CU34+Volume!CU59+Volume!CU62 -> 50460345 | ... AE10: =Volume!CY10+Volume!CY11+Volume!CY22+Volume!CY34+Volume!CY59+Volume!CY62 -> 46771803 | AF10: =SUM(V10:AE10) -> 4.9956899e+08 | AH10: epod2 pod | AI10: SOP01.0 | AJ10: BAT | AK10: 45698 | AL10: ePod2 Cartridges | AM10: 150444920 | AN10: 202559713 | AO10: 91785440 | AP10: 12656900 | AQ10: 9366300 | AR10: 5088060 | AS10: 10606320 | AT10: 9598860 | AU10: 14671980 | AV10: 14349580 | AW10: 12979220 | AX10: 15256580 | AY10: 15964420 | AZ10: 12569000 | BA10: 15497160 | BB10: 14497440 | BD10: 15559440 | BE10: 12012360 | BF10: 18465130 | BG10: 19798430 | BH10: 20944920 | BI10: 17632262 | BJ10: 15720521 | BK10: 13104480 | BL10: 29618660 | BM10: 11285460 | BN10: 13803750 | BO10: 14614300 | BP10: 8764100 | BQ10: 8606700 | BR10: 16334000 | BS10: 12069960 | BT10: 7439980 | BU10: 7699880 | BV10: 3856460 | BW10: 4664000 | BX10: 6591860 | BY10: 4137070 | BZ10: 7758370 | CA10: 3863060 | CB10: 4132280 | CC10: 2737600 | CD10: 3241380 | CE10: 839240 | CF10: 607680 | CG10: 543780 | CH10: 136620 | CI10: 20160 | CJ10: 20160 | CK10: 0 | CL10: 216720 | CM10: 161280 | CN10: 0 | CO10: 15120 | CP10: 20160 | CQ10: 65520 | CR10: 0 | CS10: 0 | CT10: 0 | CU10: 0 | CV10: 0 | CW10: 0 | CX10: 0 | CY10: 0
A11: 2 | B11: RF002_Alto | C11: Alto | D11: Addendum No.10 - Indonesia | F11: 195500900 | G11: 255515000 | H11: 22785000 | I11: 22092200 | J11: 25589000 | K11: 18498600 | L11: 30742700 | M11: 18494250 | N11: 25532300 | O11: 28932600 | P11: 11088600 | Q11: 14612550 | R11: 17543850 | S11: 18060400 | T11: =CN59+CN62 -> 29540200 | U11: =CO59+CO62 -> 15991900 | V11: =CP59+CP62 -> 46417950 | W11: =CQ59+CQ62 -> 39955200 | X11: =CR59+CR62 -> 25506950 | Y11: =CS59+CS62 -> 21583600 | Z11: =CT59+CT62 -> 27502550 | AA11: =CU59+CU62 -> 22651600 | ... AE11: =CY59+CY62 -> 25626000 | AF11: =SUM(V11:AE11) -> 276304400 | AH11: ePod 3 Pod | AI11: SOP01.0 | AJ11: BAT | AK11: 45698 | AL11: ePod3 Cartridges | AM11: 0 | AN11: 0 | AO11: 49538050 | AP11: 52288270 | BD11: 0 | BE11: 0 | BF11: 0 | BG11: 0 | BH11: 0 | BI11: 0 | BJ11: 0 | BK11: 0 | BL11: 0 | BM11: 0 | BN11: 0 | BO11: 0 | BP11: 0 | BQ11: 0 | BR11: 136620 | BS11: 1201500 | BT11: 2856870 | BU11: 5365530 | BV11: 6736500 | BW11: 6646410 | BX11: 9393120 | BY11: 8034750 | BZ11: 6721830 | CA11: 2444920 | CB11: 7133770 | CC11: 3013380 | CD11: 6978870 | CE11: 4888410 | CF11: 4624920 | CG11: 6254730 | CH11: 5871600 | CI11: 5959710 | CJ11: 5151780 | CK11: 2354220 | CL11: 56880 | CM11: 0 | CN11: 196560 | CO11: 0 | CP11: 0 | CQ11: 0 | CR11: 0 | CS11: 0 | CT11: 0 | CU11: 0 | CV11: 0 | CW11: 0 | CX11: 0 | CY11: 0
A12: 4 | B12: RF003_Alto | C12: Alto | D12: Alto Pod Investment fee for Inkjet printing | AF12: =SUM(V12:AE12) -> 0 | AH12: Hestia 1.0 | AI12: SOP01.0 | AJ12: BAT | AK12: 45698 | AL12: Hestia | AM12: 0 | AN12: 0 | AO12: 0 | AP12: 119534880 | BD12: 0 | BE12: 0 | BF12: 0 | BG12: 0 | BH12: 0 | BI12: 0 | BJ12: 0 | BK12: 0 | BL12: 0 | BM12: 0 | BN12: 0 | BO12: 0 | BP12: 0 | BQ12: 0 | BR12: 0 | BS12: 0 | BT12: 0 | BU12: 0 | BV12: 0 | BW12: 0 | BX12: 0 | BY12: 0 | BZ12: 0 | CA12: 0 | CB12: 0 | CC12: 0 | CD12: 0 | CE12: 4141170 | CF12: 10303470 | CG12: 18112860 | CH12: 12666060 | CI12: 17188320 | CJ12: 15151590 | CK12: 12838860 | CL12: 13199850 | CM12: 15932700 | CN12: 17350470 | CO12: 7948260 | CP12: 19106540 | CQ12: 20397590 | CR12: 14871760 | CS12: 18739530 | CT12: 17118810 | CU12: 26215830 | CV12: 23149370 | CW12: 21619420 | CX12: 27275260 | CY12: 19757020
A13: 5 | B13: RF004_Alto | C13: Alto | D13: Device to Indo Equipment move cost | I13: 816200 | J13: 663600 | K13: 138600 | L13: 662000 | M13: 213750 | N13: 845900 | O13: 950400 | P13: 1489800 | Q13: 1329750 | R13: 886650 | S13: 1550250 | T13: =Volume!CN57+Volume!CN58 -> 1243800 | U13: =Volume!CO57+Volume!CO58 -> 898800 | V13: =Volume!CP57+Volume!CP58 -> 924150 | W13: =Volume!CQ57+Volume!CQ58 -> 466200 | X13: =Volume!CR57+Volume!CR58 -> 1068350 | Y13: =Volume!CS57+Volume!CS58 -> 721000 | Z13: =Volume!CT57+Volume!CT58 -> 869750 | AA13: =Volume!CU57+Volume!CU58 -> 750400 | ... AE13: =Volume!CY57+Volume!CY58 -> 802200 | AF13: =SUM(V13:AE13) -> 8017400 | AH13: Hestia 1.1 | AI13: SOP01.0 | AJ13: BAT | AK13: 45698 | AL13: Hestia 1.1 | AM13: 0 | AN13: 0 | AO13: 0 | AP13: 0 | CB13: 0 | CC13: 0 | CD13: 0 | CE13: 0 | CF13: 0 | CG13: 0 | CH13: 0 | CI13: 0 | CJ13: 0 | CK13: 0 | CL13: 0 | CM13: 0 | CN13: 0 | CO13: 0 | CP13: 0 | CQ13: 0 | CR13: 0 | CS13: 0 | CT13: 0 | CU13: 0 | CV13: 0 | CW13: 0 | CX13: 0 | CY13: 0
A14: 6 | B14: RF005_Alto | C14: Alto | D14: Alto Blister Reduction Capex | R14: 16056000 | S14: 13005000 | T14: 30684600 | U14: 16846200 | V14: =Volume!CP59*98% -> 45442551 | W14: =Volume!CQ59*98% -> 39156096 | X14: =Volume!CR59*98% -> 24996811 | Y14: =Volume!CS59*98% -> 21151928 | Z14: =Volume!CT59*98% -> 26787859 | AA14: =Volume!CU59*98% -> 22033928 | AB14: =Volume!CV59*98% -> 20502139 | AC14: =Volume!CW59*98% -> 24815952 | ... AE14: =Volume!CY59*98% -> 24784200 | AF14: =SUM(V14:AE14) -> 269216584 | AH14: Hestia 1.1 Premium | AI14: SOP01.0 | AJ14: BAT | AK14: 45698 | AL14: Hestia 1.1 Premium | AM14: 0 | AN14: 0 | AO14: 0 | AP14: 0 | CB14: 0 | CC14: 0 | CD14: 0 | CE14: 0 | CF14: 0 | CG14: 0 | CH14: 0 | CI14: 0 | CJ14: 0 | CK14: 0 | CL14: 0 | CM14: 0 | CN14: 0 | CO14: 29970 | CP14: 576000 | CQ14: 811150 | CR14: 1104660 | CS14: 817540 | CT14: 476460 | CU14: 606300 | CV14: 610230 | CW14: 481710 | CX14: 582030 | CY14: 613260
A15: 7 | B15: RF006_Alto | C15: Prismatic Pod | D15: Prismastic China project capex | AF15: =SUM(V15:AE15) -> 0 | AH15: KUMA E-Box ROW | AI15: SOP01.0 | AJ15: BAT | AK15: 45698 | AL15: Kuma 1K | AM15: 0 | AN15: 0 | AO15: 0 | AP15: 4452220 | BD15: 0 | BE15: 0 | BF15: 0 | BG15: 0 | BH15: 0 | BI15: 0 | BJ15: 0 | BK15: 0 | BL15: 0 | BM15: 0 | BN15: 0 | BO15: 0 | BP15: 0 | BQ15: 0 | BR15: 0 | BS15: 0 | BT15: 0 | BU15: 0 | BV15: 0 | BW15: 0 | BX15: 0 | BY15: 0 | BZ15: 0 | CA15: 0 | CB15: 0 | CC15: 0 | CD15: 0 | CE15: 146304 | CF15: 793652 | CG15: 1209610 | CH15: 417742 | CI15: 338164 | CJ15: 665900 | CK15: 479376 | CL15: 184320 | CM15: 217152 | CN15: 522432 | CO15: 149760 | CP15: 207792 | CQ15: 87840 | CR15: 66240 | CS15: 111600 | CT15: 65520 | CU15: 60480 | CV15: 40320 | CW15: 40320 | CX15: 65520 | CY15: 35280
A16: 8 | B16: RF007_Epod&Modi | C16: Epod&Modi | D16: Tax Stamp(Pod2+ePod3 Czech,Germany,Poland&Italy) | G16: 25920 | H16: 322380 | I16: 336240 | J16: 1478340 | K16: 229680 | L16: 1008810 | M16: 993150 | O16: 36540 | P16: 178380 | Q16: 5040 | T16: 0 | U16: 0 | V16: 0 | W16: 0 | X16: 0 | Y16: 0 | Z16: 0 | AA16: 0 | AB16: 0 | AC16: 0 | AD16: 0 | AE16: 0 | AF16: =SUM(V16:AE16) -> 0 | AH16: KUMA E-Box NZ | AI16: SOP01.0 | AJ16: BAT | AK16: 45698 | AL16: Kuma 950 | AM16: 0 | AN16: 0 | AO16: 0 | AP16: 622560 | BD16: 0 | BE16: 0 | BF16: 0 | BG16: 0 | BH16: 0 | BI16: 0 | BJ16: 0 | BK16: 0 | BL16: 0 | BM16: 0 | BN16: 0 | BO16: 0 | BP16: 0 | BQ16: 0 | BR16: 0 | BS16: 0 | BT16: 0 | BU16: 0 | BV16: 0 | BW16: 0 | BX16: 0 | BY16: 0 | BZ16: 0 | CA16: 0 | CB16: 0 | CC16: 150000 | CD16: 115200 | CE16: 24000 | CF16: 0 | CG16: 222480 | CH16: 45360 | CI16: 65520 | CJ16: 0 | CK16: 0 | CL16: 0 | CM16: 0 | CN16: 0 | CO16: 0 | CP16: 0 | CQ16: 0 | CR16: 0 | CS16: 0 | CT16: 0 | CU16: 0 | CV16: 0 | CW16: 0 | CX16: 0 | CY16: 0
A17: 9 | B17: RF008_Modi2.0 | C17: Modi 2.0 | D17: Automation Flexible Line for Modi 2.0 Platform 1K PEN Default/Full and 1k BOX Full | P17: 705120 | Q17: 8166540 | R17: 7083240 | S17: 2347320 | T17: =Volume!CN44+Volume!CN45+Volume!CN46 -> 3342680 | U17: =Volume!CO44+Volume!CO45+Volume!CO46 -> 2225760 | V17: =Volume!CP44+Volume!CP45+Volume!CP46 -> 5941992 | W17: =Volume!CQ44+Volume!CQ45+Volume!CQ46 -> 5851740 | X17: =Volume!CR44+Volume!CR45+Volume!CR46 -> 3951300 | Y17: =Volume!CS44+Volume!CS45+Volume!CS46 -> 4293600 | Z17: =Volume!CT44+Volume!CT45+Volume!CT46 -> 3621000 | AA17: =Volume!CU44+Volume!CU45+Volume!CU46 -> 5416620 | ... AE17: =Volume!CY44+Volume!CY45+Volume!CY46 -> 5507580 | AF17: =SUM(V17:AE17) -> 53381412 | AH17: Kuma Box 2.0 | AI17: SOP01.0 | AJ17: BAT | AK17: 45698 | AL17: Kuma Box 2.0 | AP17: 0 | CB17: 0 | CC17: 0 | CD17: 0 | CE17: 0 | CF17: 0 | CG17: 0 | CH17: 0 | CI17: 0 | CJ17: 0 | CK17: 0 | CL17: 0 | CM17: 0 | CN17: 0 | CO17: 0 | CP17: 0 | CQ17: 155360 | CR17: 294600 | CS17: 250560 | CT17: 142560 | CU17: 289405.95 | CV17: 173563.25 | CW17: 172374.76 | CX17: 244507.11 | CY17: 191572.99
A18: 10 | B18: RF009_Hestia1.0 | C18: Hestia 1.0 | D18: Hestia 1.0 Automation Lines Modification (Modified from ePod3 to Hestia1.0) (1-4 line) | K18: 4374450 | L18: 10070190 | M18: 20708100 | N18: 10070820 | O18: 17188320 | P18: 15151590 | Q18: 12838860 | R18: 15197040 | S18: 8947260 | T18: =Volume!CN12 -> 17350470 | U18: =Volume!CO12 -> 7948260 | V18: =Volume!CP12 -> 19106540 | W18: =Volume!CQ12 -> 20397590 | X18: =Volume!CR12 -> 14871760 | Y18: =Volume!CS12 -> 18739530 | Z18: =Volume!CT12 -> 17118810 | AA18: =Volume!CU12 -> 26215830 | ... AE18: =Volume!CY12 -> 19757020 | AF18: =SUM(V18:AE18) -> 208251130 | AH18: KUMA E-Pen 1.0 ROW | AI18: SOP01.0 | AJ18: BAT | AK18: 45698 | AL18: Kuma Pen 1K | AM18: 0 | AN18: 0 | AO18: 0 | AP18: 1741320 | BD18: 0 | BE18: 0 | BF18: 0 | BG18: 0 | BH18: 0 | BI18: 0 | BJ18: 0 | BK18: 0 | BL18: 0 | BM18: 0 | BN18: 0 | BO18: 0 | BP18: 0 | BQ18: 0 | BR18: 0 | BS18: 0 | BT18: 0 | BU18: 0 | BV18: 0 | BW18: 0 | BX18: 0 | BY18: 0 | BZ18: 0 | CA18: 0 | CB18: 0 | CC18: 0 | CD18: 0 | CE18: 0 | CF18: 0 | CG18: 0 | CH18: 39600 | CI18: 31860 | CJ18: 532440 | CK18: 709740 | CL18: 275220 | CM18: 152460 | CN18: 0 | CO18: 0 | CP18: 0 | CQ18: 0 | CR18: 0 | CS18: 0 | CT18: 0 | CU18: 0 | CV18: 0 | CW18: 0 | CX18: 0 | CY18: 0
A19: 11 | B19: RF010_Hestia1.0 | C19: Hestia 1.0 | D19: Hestia1.0 Manual line capex | AF19: =SUM(V19:AE19) -> 0 | AH19: Kuma Pen 2.0 | AI19: SOP01.0 | AJ19: BAT | AK19: 45698 | AL19: Kuma Pen 2.0 | AM19: 0 | AN19: 0 | AO19: 0 | AP19: 107460 | BD19: 0 | BE19: 0 | BF19: 0 | BG19: 0 | BH19: 0 | BI19: 0 | BJ19: 0 | BK19: 0 | BL19: 0 | BM19: 0 | BN19: 0 | BO19: 0 | BP19: 0 | BQ19: 0 | BR19: 0 | BS19: 0 | BT19: 0 | BU19: 0 | BV19: 0 | BW19: 0 | BX19: 0 | BY19: 0 | BZ19: 0 | CA19: 0 | CB19: 0 | CC19: 0 | CD19: 0 | CE19: 0 | CF19: 0 | CG19: 0 | CH19: 0 | CI19: 0 | CJ19: 0 | CK19: 0 | CL19: 50040 | CM19: 57420 | CN19: 25200 | CO19: 440 | CP19: 171720 | CQ19: 208800 | CR19: 170818 | CS19: 382597.62 | CT19: 356973.74 | CU19: 489469.07 | CV19: 481795.02 | CW19: 459653.18 | CX19: 540842.01 | CY19: 405790.38
A20: 12 | B20: RF011_ePod2Pod | C20: ePod2 Pod | D20: ePod Packer - Included in Hestia | E20: 845920 | F20: 72773897 | G20: 63660929 | H20: 5439052 | I20: 806095 | J20: 321239 | K20: 481119 | L20: 497616 | M20: 40638 | T20: 0 | AF20: =SUM(V20:AE20) -> 0 | AH20: KUMA E-Pen 1.0 ROW | AI20: SOP01.0 | AJ20: BAT | AK20: 45698 | AL20: Kuma Pen 950 | AM20: 0 | AN20: 0 | AO20: 0 | AP20: 3020760 | BD20: 0 | BE20: 0 | BF20: 0 | BG20: 0 | BH20: 0 | BI20: 0 | BJ20: 0 | BK20: 0 | BL20: 0 | BM20: 0 | BN20: 0 | BO20: 0 | BP20: 0 | BQ20: 0 | BR20: 0 | BS20: 0 | BT20: 0 | BU20: 0 | BV20: 0 | BW20: 0 | BX20: 0 | BY20: 0 | BZ20: 0 | CA20: 0 | CB20: 0 | CC20: 0 | CD20: 0 | CE20: 0 | CF20: 0 | CG20: 0 | CH20: 0 | CI20: 862920 | CJ20: 623880 | CK20: 567720 | CL20: 660240 | CM20: 306000 | CN20: 574020 | CO20: 633600 | CP20: 626220 | CQ20: 116460 | CR20: 114660 | CS20: 179460 | CT20: 169200 | CU20: 147260 | CV20: 143160 | CW20: 128580 | CX20: 116680 | CY20: 142880
A21: 13 | B21: RF012_ePod3Pod | C21: ePod3 Pod | D21: ePod 3 Automation Modification Capex Amortization (1P) Modified from ePod2 to ePod3 | G21: 12285257 | H21: 1074798 | I21: 65733 | J21: 894985 | K21: 906260 | L21: 1097616 | M21: 617546 | N21: 612910 | O21: 277678 | P21: 193824 | AF21: =SUM(V21:AE21) -> 0 | AI21: SOP01.0 | AJ21: BAT | AK21: 45698 | AL21: Kuma Pen NZ | AP21: 0 | CB21: 0 | CC21: 0 | CD21: 0 | CE21: 0 | CF21: 0 | CG21: 0 | CH21: 0 | CI21: 0 | CJ21: 0 | CK21: 0 | CL21: 0 | CM21: 0 | CN21: 0 | CO21: 0 | CP21: 0 | CQ21: 0 | CR21: 0 | CS21: 0 | CT21: 0 | CU21: 0 | CV21: 0 | CW21: 0 | CX21: 0 | CY21: 0
A22: 14 | B22: RF013_Kuma | C22: Kuma 1.0 | D22: KUMA E-ROW Ultra Sonic Machine | K22: 146304 | L22: 793652 | M22: 1209610 | N22: 417742 | O22: 338164 | P22: 665900 | Q22: 479376 | R22: 160272 | S22: 139680 | T22: =Volume!CN15 -> 522432 | U22: =Volume!CO15 -> 149760 | V22: =Volume!CP15 -> 207792 | W22: =Volume!CQ15 -> 87840 | X22: =Volume!CR15 -> 66240 | Y22: =Volume!CS15 -> 111600 | Z22: =Volume!CT15 -> 65520 | AA22: =Volume!CU15 -> 60480 | ... AE22: =Volume!CY15 -> 35280 | AF22: =SUM(V22:AE22) -> 780912 | AH22: Hestia total（include Kuma） | AI22: SOP01.0 | AJ22: BAT | AK22: 45698 | AL22: Hestia total（include Kuma） | AM22: 0 | AN22: 0 | AO22: 0 | AP22: 128856640 | AQ22: 0 | AR22: 0 | AS22: 0 | AT22: 0 | AU22: 0 | AV22: 0 | AW22: 0 | AX22: 0 | AY22: 0 | AZ22: 0 | BA22: 0 | BB22: 0 | BD22: 0 | BE22: 0 | BF22: 0 | BG22: 0 | BH22: 0 | BI22: 0 | BJ22: 0 | BK22: 0 | BL22: 0 | BM22: 0 | BN22: 0 | BO22: 0 | BP22: 0 | BQ22: 0 | BR22: 0 | BS22: 0 | BT22: 0 | BU22: 0 | BV22: 0 | BW22: 0 | BX22: 0 | BY22: 0 | BZ22: 0 | CA22: 0 | CB22: 0 | CC22: 0 | CD22: 0 | CE22: 4287474 | CF22: 11097122 | CG22: 19322470 | CH22: 13123402 | CI22: 18421264 | CJ22: 16973810 | CK22: 14595696 | CL22: 14369670 | CM22: 16665732 | CN22: 18472122 | CO22: 8762030 | CP22: 20688272 | CQ22: 21777200 | CR22: 16622738 | CS22: 20481288 | CT22: 18329524 | CU22: 27808745 | CV22: 24598438 | CW22: 22902058 | CX22: 28824839 | CY22: 21145803
A23: 15 | B23: RF014_Kuma | C23: Kuma 1.0 | D23: KUMA E-Pen Laser welding machine & Kuma E-Pen 1.0 air tightness test machine | N23: 39600 | O23: 894780 | P23: 1156320 | Q23: 1277460 | R23: 950580 | S23: 453600 | T23: =Volume!CN18+Volume!CN20 -> 574020 | U23: =Volume!CO18+Volume!CO20 -> 633600 | V23: =Volume!CP18+Volume!CP20 -> 626220 | W23: =Volume!CQ18+Volume!CQ20 -> 116460 | X23: =Volume!CR18+Volume!CR20 -> 114660 | Y23: =Volume!CS18+Volume!CS20 -> 179460 | Z23: =Volume!CT18+Volume!CT20 -> 169200 | AA23: =Volume!CU18+Volume!CU20 -> 147260 | ... AE23: =Volume!CY18+Volume!CY20 -> 142880 | AF23: =SUM(V23:AE23) -> 1884560 | AH23: Mimosa | AI23: SOP01.0 | AJ23: BAT | AK23: 45698 | AL23: Mimosa | AM23: 0 | AN23: 0 | AO23: 0 | AP23: 0 | BD23: 0 | BE23: 0 | BF23: 0 | BG23: 0 | BH23: 0 | BI23: 0 | BJ23: 0 | BK23: 0 | BL23: 0 | BM23: 0 | BN23: 0 | BO23: 0 | BP23: 0 | BQ23: 0 | BR23: 0 | BS23: 0 | BT23: 0 | BU23: 0 | BV23: 0 | BW23: 0 | BX23: 0 | BY23: 0 | BZ23: 0 | CA23: 0 | CB23: 0 | CC23: 0 | CD23: 0 | CE23: 0 | CF23: 0 | CG23: 0 | CH23: 0 | CI23: 0 | CJ23: 0 | CK23: 0 | CL23: 0 | CM23: 0 | CN23: 0 | CO23: 3744 | CP23: 72000 | CQ23: 153000 | CR23: 99000 | CS23: 18000 | CT23: 36336 | CU23: 56016 | CV23: 38736 | CW23: 46032 | CX23: 44928 | CY23: 43776
A24: 16 | B24: RF015_Modi&RCS | C24: Modi & RCS | D24: CCD&Tax Stamp Machine MD2.0 1K PEN Default Czech/Germany/Poland/Italy/BUL (Machines can be cross-used by both Modi & RCS) | P24: 36060 | Q24: 4722360 | R24: 3286440 | S24: 398760 | T24: 1150380 | U24: 231420 | V24: 1771920 | W24: 3593400 | X24: 1748640 | Y24: 752880 | Z24: 1156800 | AA24: 1870560 | AB24: 1795920 | AC24: 2130480 | AD24: 3526800 | AE24: 2150400 | AF24: =SUM(V24:AE24) -> 20497800 | AH24: ePod 2 Device(Wave 1) | AI24: SOP01.0 | AJ24: BAT | AK24: 45698 | AL24: ePod2 | AM24: 6919526 | AN24: 6734445 | AO24: 973700 | AP24: 301000 | AQ24: 355400 | AR24: 376900 | AS24: 329800 | AT24: 514000 | AU24: 392100 | AV24: 672345 | AW24: 790600 | AX24: 581700 | AY24: 493100 | AZ24: 766581 | BA24: 791000 | BB24: 856000 | BD24: 617400 | BE24: 565400 | BF24: 918400 | BG24: 1007400 | BH24: 723600 | BI24: 752700 | BJ24: 589200 | BK24: 591300 | BL24: 636055 | BM24: 45000 | BN24: 163790 | BO24: 124200 | BP24: 95000 | BQ24: 309300 | BR24: 98600 | BS24: 18000 | BT24: 41000 | BU24: 16000 | BV24: 30000 | BW24: 43800 | BX24: 72900 | BY24: 75600 | BZ24: 48400 | CA24: 125100 | CB24: 19300 | CC24: 72900 | CD24: 30200 | CE24: 21700 | CF24: 24900 | CG24: 19800 | CH24: 0 | CI24: 0 | CJ24: 0 | CK24: 69000 | CL24: 43200 | CM24: 0 | CN24: 0 | CO24: 0 | CP24: 0 | CQ24: 0 | CR24: 0 | CS24: 0 | CT24: 0 | CU24: 0 | CV24: 0 | CW24: 0 | CX24: 0 | CY24: 0
A25: 17 | B25: RF016_Sensa | C25: Sensa | D25: Sensa Manual Line Capex | AF25: =SUM(V25:AE25) -> 0 | AI25: SOP12.1 | AJ25: BAT | AK25: 0 | AL25: ePod2 | AM25: 6503406 | AN25: 7074939 | AO25: 0 | AP25: 0 | AQ25: 355400 | AR25: 376900 | AS25: 329800 | AT25: 514000 | AU25: 392100 | AV25: 672345 | AW25: 790600 | AX25: 581700 | AY25: 493100 | AZ25: 766581 | BA25: 695680 | BB25: 535200 | BD25: 845094 | BE25: 464000 | BF25: 918400 | BG25: 1206700 | BH25: 786300 | BI25: 752700 | BJ25: 589200 | BK25: 543500 | BL25: 636055 | BM25: 45000 | BN25: 163790 | BO25: 124200 | BP25: 0 | BQ25: 0 | BR25: 0 | BS25: 0 | BT25: 0 | BU25: 0 | BV25: 0 | BW25: 0 | BX25: 0 | BY25: 0 | BZ25: 0 | CA25: 0 | CB25: 0 | CC25: 0 | CD25: 0 | CE25: 0 | CF25: 0 | CG25: 0 | CH25: 0 | CI25: 0 | CJ25: 0 | CK25: 0 | CL25: 0 | CM25: 0 | CN25: 0 | CO25: 0 | CP25: 0 | CQ25: 0 | CR25: 0 | CS25: 0 | CT25: 0 | CU25: 0 | CV25: 0 | CW25: 0 | CX25: 0 | CY25: 0
A26: 18 | B26: RF017_Sensa | C26: Sensa | D26: Sensa Semi-Auto Line Capex | AF26: =SUM(V26:AE26) -> 0 | AI26: 0 | AJ26: BAT | AK26: 0 | AL26: ePod2 | AM26: 6503406 | AN26: 6529023 | AO26: 0 | AP26: 0 | AQ26: 355400 | AR26: 376900 | AS26: 329800 | AT26: 514000 | AU26: 392100 | AV26: 672345 | AW26: 790600 | AX26: 581700 | AY26: 493100 | AZ26: 766581 | BA26: 695680 | BB26: 535200 | BD26: 845094 | BE26: 464000 | BF26: 884050 | BG26: 1206700 | BH26: 484575 | BI26: 935984 | BJ26: 432680 | BK26: 306895 | BL26: 636055 | BM26: 45000 | BN26: 163790 | BO26: 124200 | BP26: 0 | BQ26: 0 | BR26: 0 | BS26: 0 | BT26: 0 | BU26: 0 | BV26: 0 | BW26: 0 | BX26: 0 | BY26: 0 | BZ26: 0 | CA26: 0 | CB26: 0 | CC26: 0 | CD26: 0 | CE26: 0 | CF26: 0 | CG26: 0 | CH26: 0 | CI26: 0 | CJ26: 0 | CK26: 0 | CL26: 0 | CM26: 0 | CN26: 0 | CO26: 0 | CP26: 0 | CQ26: 0 | CR26: 0 | CS26: 0 | CT26: 0 | CU26: 0 | CV26: 0 | CW26: 0 | CX26: 0 | CY26: 0
A27: 19 | B27: RF018_Modi | C27: Modi | D27: T&T longterm solution cost Amortize at Uzbekistan TX500 and DP1500（UZB—乌兹别克斯坦） | G27: 549000 | H27: 3000 | T27: 0 | U27: 0 | V27: 0 | W27: 0 | X27: 0 | Y27: 0 | Z27: 0 | AA27: 0 | AB27: 0 | AC27: 0 | AD27: 0 | AE27: 0 | AF27: =SUM(V27:AE27) -> 0 | AI27: 0 | AJ27: BAT | AK27: SOP7-2022/8/2 | AL27: ETMI | AM27: 45200 | AN27: 21040 | AO27: 32160 | AP27: 0 | AR27: 17760 | AT27: 14320 | AV27: 4400 | AW27: 8720 | BD27: 6000 | BF27: 3000 | BG27: 0 | BH27: 4000 | BI27: 0 | BJ27: 5040 | BK27: 3000 | BL27: 0 | BM27: 0 | BN27: 0 | BO27: 0 | BP27: 0 | BQ27: 3000 | BR27: 5040 | BS27: 0 | BT27: 3000 | BU27: 5040 | BV27: 0 | BW27: 0 | BX27: 8040 | BY27: 0 | BZ27: 0 | CA27: 8040
A28: 20 | B28: RF019_Modi | C28: Modi | D28: KZ MODI testing / support for T&T Amortize at KAZ TX500 and DP1500（KZ—哈萨克斯坦） | T28: 0 | U28: 0 | V28: 0 | W28: 0 | X28: 0 | Y28: 0 | Z28: 0 | AA28: 0 | AB28: 0 | AC28: 0 | AD28: 0 | AE28: 0 | AF28: =SUM(V28:AE28) -> 0 | AI28: SOP7-2022/8/2 | AJ28: BAT | AK28: 44805 | AL28: Atomiser | AM28: 511000 | AN28: 40500 | AO28: 0 | AP28: 0 | AR28: 181500 | AT28: 77000 | AV28: 85000 | AW28: 167500 | BD28: 3000 | BF28: 0 | BG28: 0 | BI28: 0 | BJ28: 12500 | BK28: 0 | BL28: 0 | BM28: 12500 | BN28: 12500
A29: 21 | B29: RF020_Modi | C29: Modi | D29: T&T Interim programme of Azerbaijan Amortize at Azerbaijan 1k/3k/5k product（AZB—阿塞拜疆） | T29: 0 | U29: 4680 | V29: 72000 | W29: 0 | X29: 0 | Y29: 0 | Z29: 0 | AA29: 0 | AB29: 0 | AC29: 0 | AD29: 0 | AE29: 0 | AF29: =SUM(V29:AE29) -> 72000 | AI29: 44805 | AJ29: BAT | AK29: SOP10-12/6 236M | AL29: ePod2+ | AM29: 0 | AN29: 1724245.5 | AO29: 650254.5 | AP29: 0 | BD29: 135000 | BE29: 135000 | BF29: 136696.5 | BG29: 108378 | BH29: 181110 | BI29: 121848 | BJ29: 156642 | BK29: 131443.5 | BL29: 186801 | BM29: 203887.5 | BN29: 157320 | BO29: 70119 | BP29: 75019.5 | BQ29: 79714.5 | BR29: 164461.5 | BS29: 165529.5 | BT29: 165529.5
A30: 22 | B30: RF021_Modi | C30: Modi | D30: T&T for Pre-Dispatch Advice --add extra function（UZB—乌兹别克斯坦 KZ—哈萨克斯坦） | T30: 0 | U30: 0 | V30: 0 | W30: 0 | X30: 0 | Y30: 0 | Z30: 0 | AA30: 0 | AB30: 0 | AC30: 0 | AD30: 0 | AE30: 0 | AF30: =SUM(V30:AE30) -> 0 | AI30: SOP10-12/6 236M | AJ30: BAT | AK30: 2023/1/31Core | AL30: ePod2+ | AM30: 0 | AN30: 1541050 | AO30: 235000 | AP30: 0 | BD30: 0 | BE30: 64549 | BF30: 127048 | BG30: 181303 | BH30: 24200 | BI30: 254800 | BJ30: 211000 | BK30: 214000 | BL30: 215000 | BM30: 81000 | BN30: 48150 | BO30: 120000 | BP30: 175000 | BQ30: 60000 | BR30: 0 | BS30: 0 | BT30: 0 | BU30: 0 | BV30: 0 | BW30: 0 | BX30: 0 | BY30: 0 | BZ30: 0 | CA30: 0
A31: 23 | B31: RF022_Modi | C31: Modi | D31: KZ MODI testing / support for T&T Amortize at BOX3K&5K KAZ&UZB market（KZ—哈萨克斯坦） | G31: 116160 | H31: 15840 | K31: 5400 | T31: 0 | U31: 0 | V31: 0 | W31: 0 | X31: 0 | Y31: 0 | Z31: 0 | AA31: 0 | AB31: 0 | AC31: 0 | AD31: 0 | AE31: 0 | AF31: =SUM(V31:AE31) -> 0 | AI31: SOP2 | AJ31: BAT | AK31: 2023/1/31-Core+Sensitivity | AL31: ePod2+ | AM31: 0 | AN31: 1650011 | AO31: 235000 | AP31: 0 | AQ31: 0 | AR31: 0 | AS31: 0 | AT31: 0 | AU31: 0 | AV31: 0 | AW31: 0 | AX31: 0 | AY31: 0 | AZ31: 0 | BA31: 0 | BB31: 0 | BD31: 0 | BE31: 80000 | BF31: 148648 | BG31: 181303 | BH31: 24200 | BI31: 326710 | BJ31: 211000 | BK31: 214000 | BL31: 215000 | BM31: 81000 | BN31: 48150 | BO31: 120000 | BP31: 175000 | BQ31: 60000 | BR31: 0 | BS31: 0 | BT31: 0 | BU31: 0 | BV31: 0 | BW31: 0 | BX31: 0 | BY31: 0 | BZ31: 0 | CA31: 0
A32: 24 | B32: RF023_Modi | C32: Modi | D32: AZB T&T longterm solution cost for TX500&DP1500&BOX1K&3K&5K for AZB Market（AZB—阿塞拜疆） | T32: 0 | U32: 4680 | V32: 72000 | W32: 0 | X32: 0 | Y32: 0 | Z32: 0 | AA32: 0 | AB32: 0 | AC32: 0 | AD32: 0 | AE32: 0 | AF32: =SUM(V32:AE32) -> 72000 | AI32: 2023/1/31-Core+Sensitivity | AJ32: BAT | AK32: 2023/1/31-PO+Production | AL32: ePod2+ | AM32: 0 | AN32: 1542297 | AO32: 235000 | AP32: 0 | BE32: 69349 | BF32: 148648 | BG32: 160000 | BH32: 20000 | BI32: 326710 | BJ32: 139440 | BK32: 214000 | BL32: 215000 | BM32: 81000 | BN32: 48150 | BO32: 120000 | BP32: 175000 | BQ32: 60000 | BR32: 0 | BS32: 0 | BT32: 0 | BU32: 0 | BV32: 0 | BW32: 0 | BX32: 0 | BY32: 0 | BZ32: 0 | CA32: 0
A33: 25 | B33: RF024_Modi | C33: Modi | D33: Custom development BAT CMO INEXTRACK GS1 Novarator removal CR for AZB regulation（AZB—阿塞拜疆） | T33: 0 | U33: 4680 | V33: 72000 | W33: 0 | X33: 0 | Y33: 0 | Z33: 0 | AA33: 0 | AB33: 0 | AC33: 0 | AD33: 0 | AE33: 0 | AF33: =SUM(V33:AE33) -> 72000 | AH33: ePod 3+ Device | AI33: SOP01.0 | AJ33: BAT | AK33: 45698 | AL33: ePod3+ | AM33: 0 | AN33: 0 | AO33: 283400 | AP33: 540400 | BD33: 0 | BE33: 0 | BF33: 0 | BG33: 0 | BH33: 0 | BI33: 0 | BJ33: 0 | BK33: 0 | BL33: 0 | BM33: 0 | BN33: 0 | BO33: 0 | BP33: 0 | BQ33: 0 | BR33: 0 | BS33: 0 | BT33: 61500 | BU33: 95000 | BV33: 0 | BW33: 0 | BX33: 54300 | BY33: 29900 | BZ33: 3600 | CA33: 39100 | CB33: 101800 | CC33: 40000 | CD33: 56600 | CE33: 163900 | CF33: 57700 | CG33: 37200 | CH33: 4000 | CI33: 12200 | CJ33: 38200 | CK33: 20800 | CL33: 0 | CM33: 8000 | CN33: 27600 | CO33: 17000 | CP33: 11000 | CQ33: 18200 | CR33: 14400 | CS33: 32400 | CT33: 12300 | CU33: 17300 | CV33: 28200 | CW33: 21100 | CX33: 24800 | CY33: 24800
A34: 27 | B34: RF025_Hestia1.1 | C34: Hestia 1.0 | D34: epod2 to Hestia1.1 non-smart | AF34: =SUM(V34:AE34) -> 0 | AH34: Epod Starter Kit | AI34: SOP01.0 | AJ34: BAT | AK34: 45698 | AL34: Starter Kit | AM34: 0 | AN34: 0 | AO34: 319800 | AP34: 617536 | BD34: 0 | BE34: 0 | BF34: 0 | BG34: 0 | BH34: 0 | BI34: 0 | BJ34: 0 | BK34: 0 | BL34: 0 | BM34: 0 | BN34: 0 | BO34: 0 | BP34: 0 | BQ34: 0 | BR34: 0 | BS34: 0 | BT34: 0 | BU34: 0 | BV34: 0 | BW34: 0 | BX34: 0 | BY34: 0 | BZ34: 110800 | CA34: 209000 | CB34: 43200 | CC34: 7200 | CD34: 10800 | CE34: 147920 | CF34: 44600 | CG34: 19440 | CH34: 295576 | CI34: 28640 | CJ34: 20160 | CK34: 0 | CL34: 0 | CM34: 0 | CN34: 11592 | CO34: 0 | CP34: 0 | CQ34: 0 | CR34: 0 | CS34: 0 | CT34: 0 | CU34: 0 | CV34: 0 | CW34: 0 | CX34: 0 | CY34: 0
A35: 26 | B35: RF026_Hestia1.1 | C35: Hestia 1.1 | D35: epod2 to Hestia1.1 smart | AF35: =SUM(V35:AE35) -> 0 | AH35: ePod 3 Device | AI35: SOP01.0 | AJ35: BAT | AK35: 45698 | AL35: ePod3 descope | AM35: 0 | AN35: 0 | AO35: 2085900 | AP35: 1135900 | BD35: 0 | BE35: 0 | BF35: 0 | BG35: 0 | BH35: 0 | BI35: 0 | BJ35: 0 | BK35: 0 | BL35: 0 | BM35: 0 | BN35: 0 | BO35: 0 | BP35: 0 | BQ35: 0 | BR35: 21600 | BS35: 227600 | BT35: 447400 | BU35: 285400 | BV35: 200900 | BW35: 353700 | BX35: 307000 | BY35: 121200 | BZ35: 77500 | CA35: 43600 | CB35: 46800 | CC35: 29400 | CD35: 229500 | CE35: 111600 | CF35: 154900 | CG35: 79300 | CH35: 21600 | CI35: 105200 | CJ35: 52400 | CK35: 91800 | CL35: 75600 | CM35: 137800 | CN35: 77900 | CO35: 36900 | CP35: 51000 | CQ35: 42100 | CR35: 32600 | CS35: 49400 | CT35: 40000 | CU35: 48800 | CV35: 48400 | CW35: 34700 | CX35: 23800 | CY35: 25200
A36: 28 | B36: RF027_Hestia1.0 | C36: Hestia 1.0 | D36: epod2 to Hestia1.0 (5th line) | AF36: =SUM(V36:AE36) -> 0 | AH36: TX500 | AI36: SOP12.1 | AJ36: BAT | AK36: 45635 | AL36: TX500 | AM36: 0 | AN36: 81177917 | AO36: 45566346 | AP36: 12000 | AQ36: 0 | AR36: 0 | AS36: 0 | AT36: 0 | AU36: 0 | AV36: 0 | AW36: 0 | AX36: 0 | AY36: 0 | AZ36: 0 | BA36: 0 | BB36: 0 | BD36: 0 | BE36: 0 | BF36: 0 | BG36: 932000 | BH36: 2904000 | BI36: 6345360 | BJ36: 12084000 | BK36: 12364000 | BL36: 14666000 | BM36: 7120798 | BN36: 16391759 | BO36: 8370000 | BP36: 7091800 | BQ36: 7861600 | BR36: 8626600 | BS36: 11847400 | BT36: 4344600 | BU36: 2568000 | BV36: 972000 | BW36: 905946 | BX36: 912200 | BY36: 252000 | BZ36: 48000 | CA36: 136200 | CB36: 12000 | CC36: 0 | CD36: 0 | CE36: 0 | CF36: 0 | CG36: 0 | CH36: 0 | CI36: 0 | CJ36: 0 | CK36: 0 | CL36: 0 | CM36: 0 | CN36: 0 | CO36: 0 | CP36: 0 | CQ36: 0 | CR36: 0 | CS36: 0 | CT36: 0 | CU36: 0 | CV36: 0 | CW36: 0 | CX36: 0 | CY36: 0
A37: 29 | B37: RF028_Kuma | C37: Kuma E 2.0 Pen | D37: semi-auto for Kuma E 2.0 Pen | T37: =CN19 -> 25200 | U37: =CO19 -> 440 | V37: =CP19 -> 171720 | W37: =CQ19 -> 208800 | X37: =CR19 -> 170818 | Y37: =CS19 -> 382597.62 | Z37: =CT19 -> 356973.74 | AA37: =CU19 -> 489469.07 | ... AE37: =CY19 -> 405790.38 | AF37: =SUM(V37:AE37) -> 3668459 | AI37: SOP12.1 | AJ37: BAT | AK37: 0 | AL37: TX500 | AM37: 0 | AN37: 81177917 | AO37: 0 | AP37: 0 | BG37: 932000 | BH37: 2904000 | BI37: 6345360 | BJ37: 12084000 | BK37: 12364000 | BL37: 14666000 | BM37: 7120798 | BN37: 16391759 | BO37: 8370000 | BP37: 0 | BQ37: 0 | BR37: 0 | BS37: 0 | BT37: 0 | BU37: 0 | BV37: 0 | BW37: 0 | BX37: 0 | BY37: 0 | BZ37: 0 | CA37: 0 | CB37: 0 | CC37: 0 | CD37: 0 | CE37: 0 | CF37: 0 | CG37: 0 | CH37: 0 | CI37: 0 | CJ37: 0 | CK37: 0 | CL37: 0 | CM37: 0 | CN37: 0 | CO37: 0 | CP37: 0 | CQ37: 0 | CR37: 0 | CS37: 0 | CT37: 0 | CU37: 0 | CV37: 0 | CW37: 0 | CX37: 0 | CY37: 0
A38: 30 | B38: RF029_Kuma | C38: Kuma E 2.0 Box | D38: semi-auto for Kuma E 2.0 Box | AF38: =SUM(V38:AE38) -> 0 | AI38: 0 | AJ38: BAT | AK38: 0 | AL38: TX500 | AM38: 0 | AN38: 78480075 | AO38: 0 | AP38: 0 | BF38: 0 | BG38: 932000 | BH38: 2904000 | BI38: 6344000 | BJ38: 10214553 | BK38: 11960620 | BL38: 14242345 | BM38: 7120798 | BN38: 16391759 | BO38: 8370000 | BP38: 0 | BQ38: 0 | BR38: 0 | BS38: 0 | BT38: 0 | BU38: 0 | BV38: 0 | BW38: 0 | BX38: 0 | BY38: 0 | BZ38: 0 | CA38: 0 | CB38: 0 | CC38: 0 | CD38: 0 | CE38: 0 | CF38: 0 | CG38: 0 | CH38: 0 | CI38: 0 | CJ38: 0 | CK38: 0 | CL38: 0 | CM38: 0 | CN38: 0 | CO38: 0 | CP38: 0 | CQ38: 0 | CR38: 0 | CS38: 0 | CT38: 0 | CU38: 0 | CV38: 0 | CW38: 0 | CX38: 0 | CY38: 0
A39: 31 | B39: RF030_Mimosa | C39: Mimosa | D39: semi-auto for Mimosa1.0 + 2 Glue Machine | T39: 0 | U39: 3744 | V39: 72000 | W39: 153000 | X39: 99000 | Y39: 18000 | Z39: 36336 | AA39: 56016 | AB39: 38736 | AC39: 46032 | AD39: 44928 | AE39: 43776 | AF39: =SUM(V39:AE39) -> 607824 | AH39: DP1500 | AI39: 0 | AJ39: BAT | AK39: 45635 | AL39: DP1500 | AM39: 0 | AN39: 5012030 | AO39: 13033000 | AP39: 3795000 | AQ39: 0 | AR39: 0 | AS39: 0 | AT39: 0 | AU39: 0 | AV39: 0 | AW39: 0 | AX39: 0 | AY39: 0 | AZ39: 0 | BA39: 0 | BB39: 0 | BD39: 0 | BE39: 0 | BF39: 0 | BG39: 0 | BH39: 0 | BI39: 0 | BJ39: 0 | BK39: 0 | BL39: 0 | BM39: 0 | BN39: 1812030 | BO39: 3200000 | BP39: 1984000 | BQ39: 576000 | BR39: 1716000 | BS39: 1409000 | BT39: 636000 | BU39: 1406600 | BV39: 1608000 | BW39: 840000 | BX39: 1418400 | BY39: 647000 | BZ39: 420000 | CA39: 372000 | CB39: 204000 | CC39: 279000 | CD39: 324000 | CE39: 984000 | CF39: 276000 | CG39: 862000 | CH39: 60000 | CI39: 264000 | CJ39: 242000 | CK39: 180000 | CL39: 24000 | CM39: 96000 | CN39: 96000 | CO39: 0 | CP39: 0 | CQ39: 0 | CR39: 0 | CS39: 0 | CT39: 0 | CU39: 0 | CV39: 0 | CW39: 0 | CX39: 0 | CY39: 0
A40: 32 | B40: RF031_Hestia1.0 | C40: Hestia 1.0 | D40: Tax stamp and CCD capex amortization | R40: 252540 | S40: 208440 | T40: 2761020 | U40: 2766600 | V40: 3869820 | W40: =1762020+2693340 -> 4455360 | X40: 2013300 | Y40: 2991600 | Z40: 2957040 | AA40: 3942180 | AB40: 3335760 | AC40: 3791340 | AD40: 5151240 | AE40: 3408300 | AF40: =SUM(V40:AE40) -> 35915940 | AI40: SOP12.1 | AJ40: BAT | AK40: 2022/2/3-Core+Sensitivity | AL40: DP1500 | AM40: 0 | AN40: 5012030 | AO40: 0 | AP40: 0 | BF40: 0 | BK40: 0 | BL40: 0 | BN40: 1812030 | BO40: 3200000 | BP40: 0 | BQ40: 0 | BR40: 0 | BS40: 0 | BT40: 0 | BU40: 0 | BV40: 0 | BW40: 0 | BX40: 0 | BY40: 0 | BZ40: 0 | CA40: 0 | CB40: 0 | CC40: 0 | CD40: 0 | CE40: 0 | CF40: 0 | CG40: 0 | CH40: 0 | CI40: 0 | CJ40: 0 | CK40: 0 | CL40: 0 | CM40: 0 | CN40: 0 | CO40: 0 | CP40: 0 | CQ40: 0 | CR40: 0 | CS40: 0 | CT40: 0 | CU40: 0 | CV40: 0 | CW40: 0 | CX40: 0 | CY40: 0
A41: 33 | B41: RF032_Alto | C41: Alto | D41: Alto tooling(IM tooling for 2p cost reduction) | G41: 224601000 | H41: 22785000 | I41: 22092200 | J41: 25589000 | K41: 18498600 | L41: 30742700 | M41: 18494250 | N41: 25532300 | O41: 28932600 | P41: 11088600 | Q41: 14612550 | R41: 17543850 | S41: 18060400 | T41: =Volume!CN59 -> 29540200 | U41: =Volume!CO59 -> 15516400 | V41: =Volume!CP59 -> 46369950 | W41: =Volume!CQ59 -> 39955200 | X41: =Volume!CR59 -> 25506950 | Y41: =Volume!CS59 -> 21583600 | Z41: =Volume!CT59 -> 27334550 | AA41: =Volume!CU59 -> 22483600 | ... AE41: =Volume!CY59 -> 25290000 | AF41: =SUM(V41:AE41) -> 274710800 | AI41: 2022/2/3-Core+Sensitivity | AJ41: BAT | AK41: 2022/2/3-PO+Production | AL41: DP1500 | AM41: 0 | AN41: 5012030 | AO41: 0 | AP41: 0 | BF41: 0 | BK41: 0 | BL41: 0 | BN41: 1812030 | BO41: 3200000 | BP41: 0 | BQ41: 0 | BR41: 0 | BS41: 0 | BT41: 0 | BU41: 0 | BV41: 0 | BW41: 0 | BX41: 0 | BY41: 0 | BZ41: 0 | CA41: 0 | CB41: 0 | CC41: 0 | CD41: 0 | CE41: 0 | CF41: 0 | CG41: 0 | CH41: 0 | CI41: 0 | CJ41: 0 | CK41: 0 | CL41: 0 | CM41: 0 | CN41: 0 | CO41: 0 | CP41: 0 | CQ41: 0 | CR41: 0 | CS41: 0 | CT41: 0 | CU41: 0 | CV41: 0 | CW41: 0 | CX41: 0 | CY41: 0
A42: 34 | B42: RF033_ePod2Pod | C42: ePod2 POD | D42: ePod2 POD | E42: 2.4058794e+08 | AF42: =SUM(V42:AE42) -> 0 | AH42: Box 800 1.0 | AI42: 2022/2/3-PO+Production | AJ42: BAT | AK42: 45635 | AL42: Modi Box 1K | AM42: 0 | AN42: 0 | AO42: 35856000 | AP42: 7897176 | BD42: 0 | BE42: 0 | BF42: 0 | BG42: 0 | BH42: 0 | BI42: 0 | BJ42: 0 | BK42: 0 | BL42: 0 | BM42: 0 | BN42: 0 | BO42: 0 | BP42: 0 | BQ42: 0 | BR42: 0 | BS42: 1208800 | BT42: 3315200 | BU42: 3036000 | BV42: 3184800 | BW42: 4384600 | BX42: 4778600 | BY42: 6900000 | BZ42: 7176000 | CA42: 1872000 | CB42: 2317344 | CC42: 915144 | CD42: 2029776 | CE42: 1251648 | CF42: 647600 | CG42: 387088 | CH42: 216480 | CI42: 108000 | CJ42: 24096 | CK42: 0 | CL42: 0 | CM42: 0 | CN42: 0 | CO42: 0 | CP42: 0 | CQ42: 0 | CR42: 0 | CS42: 0 | CT42: 0 | CU42: 0 | CV42: 0 | CW42: 0 | CX42: 0 | CY42: 0
A43: 35 | B43: RF034_epod2Device | C43: epod 2 Device | D43: ePod2 Device - Wave 1-B design | AF43: =SUM(V43:AE43) -> 0 | AH43: Box 800 Default 2.0 | AI43: SOP12.1 | AJ43: BAT | AK43: 45635 | AL43: Box 1K Default | AM43: 0 | AN43: 0 | AO43: 0 | AP43: 9427392 | BD43: 0 | BE43: 0 | BF43: 0 | BG43: 0 | BH43: 0 | BI43: 0 | BJ43: 0 | BK43: 0 | BL43: 0 | BM43: 0 | BN43: 0 | BO43: 0 | BP43: 0 | BQ43: 0 | BR43: 0 | BS43: 0 | BT43: 0 | BU43: 0 | BV43: 0 | BW43: 0 | BX43: 0 | BY43: 0 | BZ43: 0 | CA43: 0 | CB43: 0 | CC43: 0 | CD43: 0 | CE43: 36000 | CF43: 1370520 | CG43: 1201056 | CH43: 1603776 | CI43: 2123328 | CJ43: 1403904 | CK43: 677400 | CL43: 819168 | CM43: 192240 | CN43: 319992 | CO43: 419400 | CP43: 478200 | CQ43: 342768 | CR43: 336444 | CS43: 439644 | CT43: 412488 | CU43: 453144 | CV43: 397368 | CW43: 467268 | CX43: 585648 | CY43: 567660
...
