Workbook

Sheet Chart
A1: A360 Advanced=A360A;A360 Master=A360M;PL-200=PL200
A2: 1 | D2: 2 | H2: 3 | M2: 4
A3: Condition | D3: Condition | H3: Condition | M3: Condition
A4: 1.Range:Certified in 2022 | D4: 1.Range:Roll in 2023 | H4: 1.Range: Roll Off in 2022,2023 | M4: 1.Range: Certified in 2022,2023
A5: 2.Active members | H5: 2.Roll off reason | M5: 2.Active members
A6: Group | B6: Total Points | D6: Group | E6: SubTeam | F6: Resource Number | H6: Group | I6: Transfer | J6: Resign | M6: CertVersion | N6: Valid Certification Number
A7: Finance | B7: =IF(_xlfn.IFNA(VLOOKUP(A7,Pivot!A:B,2,0),"")=0,"",_xlfn.IFNA(VLOOKUP(A7,Pivot!A:B,2,0),"")) -> 491500 | D7: Finance | E7: Finance1 | F7: =IF(_xlfn.IFNA(VLOOKUP(D7&E7,Pivot!E:F,2,0),"")=0,"",_xlfn.IFNA(VLOOKUP(D7&E7,Pivot!E:F,2,0),"")) -> 49 | H7: Finance | I7: =IF(_xlfn.IFNA(VLOOKUP(H7,Pivot!I:L,2,0),"")=0,"",_xlfn.IFNA(VLOOKUP(H7,Pivot!I:L,2,0),"")) -> 5 | J7: =IF(_xlfn.IFNA(VLOOKUP(H7,Pivot!I:K,3,0),"")=0,"",_xlfn.IFNA(VLOOKUP(H7,Pivot!I:K,3,0),"")) -> 13 | M7: PL-100 | N7: =IF(_xlfn.IFNA(VLOOKUP(M7,Pivot!N:O,2,0),"")=0,"",_xlfn.IFNA(VLOOKUP(M7,Pivot!N:O,2,0),"")) -> 14
A8: Tech | B8: =IF(_xlfn.IFNA(VLOOKUP(A8,Pivot!A:B,2,0),"")=0,"",_xlfn.IFNA(VLOOKUP(A8,Pivot!A:B,2,0),"")) | D8: Finance | E8: Finance2 | F8: =IF(_xlfn.IFNA(VLOOKUP(D8&E8,Pivot!E:F,2,0),"")=0,"",_xlfn.IFNA(VLOOKUP(D8&E8,Pivot!E:F,2,0),"")) -> 14 | H8: Tech | I8: =IF(_xlfn.IFNA(VLOOKUP(H8,Pivot!I:L,2,0),"")=0,"",_xlfn.IFNA(VLOOKUP(H8,Pivot!I:L,2,0),"")) -> 4 | J8: =IF(_xlfn.IFNA(VLOOKUP(H8,Pivot!I:K,3,0),"")=0,"",_xlfn.IFNA(VLOOKUP(H8,Pivot!I:K,3,0),"")) -> 12 | M8: Pl-200 | N8: =IF(_xlfn.IFNA(VLOOKUP(M8,Pivot!N:O,2,0),"")=0,"",_xlfn.IFNA(VLOOKUP(M8,Pivot!N:O,2,0),"")) -> 1
A9: Sales | B9: =IF(_xlfn.IFNA(VLOOKUP(A9,Pivot!A:B,2,0),"")=0,"",_xlfn.IFNA(VLOOKUP(A9,Pivot!A:B,2,0),"")) -> 30500 | D9: HR | F9: =IF(_xlfn.IFNA(VLOOKUP(D9&E9,Pivot!E:F,2,0),"")=0,"",_xlfn.IFNA(VLOOKUP(D9&E9,Pivot!E:F,2,0),"")) -> 22 | H9: Sales | I9: =IF(_xlfn.IFNA(VLOOKUP(H9,Pivot!I:L,2,0),"")=0,"",_xlfn.IFNA(VLOOKUP(H9,Pivot!I:L,2,0),"")) -> 1 | J9: =IF(_xlfn.IFNA(VLOOKUP(H9,Pivot!I:K,3,0),"")=0,"",_xlfn.IFNA(VLOOKUP(H9,Pivot!I:K,3,0),"")) -> 5 | M9: PL-300 | N9: =IF(_xlfn.IFNA(VLOOKUP(M9,Pivot!N:O,2,0),"")=0,"",_xlfn.IFNA(VLOOKUP(M9,Pivot!N:O,2,0),"")) -> 2
A10: HR | B10: =IF(_xlfn.IFNA(VLOOKUP(A10,Pivot!A:B,2,0),"")=0,"",_xlfn.IFNA(VLOOKUP(A10,Pivot!A:B,2,0),"")) -> 10000 | D10: Sales | F10: =IF(_xlfn.IFNA(VLOOKUP(D10&E10,Pivot!E:F,2,0),"")=0,"",_xlfn.IFNA(VLOOKUP(D10&E10,Pivot!E:F,2,0),"")) -> 16 | H10: HR | I10: =IF(_xlfn.IFNA(VLOOKUP(H10,Pivot!I:L,2,0),"")=0,"",_xlfn.IFNA(VLOOKUP(H10,Pivot!I:L,2,0),"")) -> 4 | J10: =IF(_xlfn.IFNA(VLOOKUP(H10,Pivot!I:K,3,0),"")=0,"",_xlfn.IFNA(VLOOKUP(H10,Pivot!I:K,3,0),"")) -> 4 | M10: Pl-400 | N10: =IF(_xlfn.IFNA(VLOOKUP(M10,Pivot!N:O,2,0),"")=0,"",_xlfn.IFNA(VLOOKUP(M10,Pivot!N:O,2,0),"")) -> 1
A11: Total | B11: =SUM(B7:B10) -> 532000 | D11: Tech | E11: AI | F11: =IF(_xlfn.IFNA(VLOOKUP(D11&E11,Pivot!E:F,2,0),"")=0,"",_xlfn.IFNA(VLOOKUP(D11&E11,Pivot!E:F,2,0),"")) -> 16 | H11: Total | I11: =SUM(I7:I10) -> 14 | J11: =SUM(J7:J10) -> 34 | M11: PL-500 | N11: =IF(_xlfn.IFNA(VLOOKUP(M11,Pivot!N:O,2,0),"")=0,"",_xlfn.IFNA(VLOOKUP(M11,Pivot!N:O,2,0),""))
D12: Tech | E12: Non-AI | F12: =IF(_xlfn.IFNA(VLOOKUP(D12&E12,Pivot!E:F,2,0),"")=0,"",_xlfn.IFNA(VLOOKUP(D12&E12,Pivot!E:F,2,0),"")) -> 16 | M12: PL-600 | N12: =IF(_xlfn.IFNA(VLOOKUP(M12,Pivot!N:O,2,0),"")=0,"",_xlfn.IFNA(VLOOKUP(M12,Pivot!N:O,2,0),""))
D13: Totoal | F13: =SUM(F7:F12) -> 133 | M13: PL-700 | N13: =IF(_xlfn.IFNA(VLOOKUP(M13,Pivot!N:O,2,0),"")=0,"",_xlfn.IFNA(VLOOKUP(M13,Pivot!N:O,2,0),""))
M14: PL-800 | N14: =IF(_xlfn.IFNA(VLOOKUP(M14,Pivot!N:O,2,0),"")=0,"",_xlfn.IFNA(VLOOKUP(M14,Pivot!N:O,2,0),"")) -> 1
M15: PL-900 | N15: =IF(_xlfn.IFNA(VLOOKUP(M15,Pivot!N:O,2,0),"")=0,"",_xlfn.IFNA(VLOOKUP(M15,Pivot!N:O,2,0),"")) -> 2
M16: A360 Advanced | N16: =IF(_xlfn.IFNA(VLOOKUP(M16,Pivot!N:O,2,0),"")=0,"",_xlfn.IFNA(VLOOKUP(M16,Pivot!N:O,2,0),"")) -> 1
M17: A360 Master | N17: =IF(_xlfn.IFNA(VLOOKUP(M17,Pivot!N:O,2,0),"")=0,"",_xlfn.IFNA(VLOOKUP(M17,Pivot!N:O,2,0),"")) -> 4
M18: ASD01 | N18: =IF(_xlfn.IFNA(VLOOKUP(M18,Pivot!N:O,2,0),"")=0,"",_xlfn.IFNA(VLOOKUP(M18,Pivot!N:O,2,0),"")) -> 1
M19: ASDEV01 | N19: =IF(_xlfn.IFNA(VLOOKUP(M19,Pivot!N:O,2,0),"")=0,"",_xlfn.IFNA(VLOOKUP(M19,Pivot!N:O,2,0),"")) -> 2
M20: UiARD | N20: =IF(_xlfn.IFNA(VLOOKUP(M20,Pivot!N:O,2,0),"")=0,"",_xlfn.IFNA(VLOOKUP(M20,Pivot!N:O,2,0),""))
M21: UiRPA | N21: =IF(_xlfn.IFNA(VLOOKUP(M21,Pivot!N:O,2,0),"")=0,"",_xlfn.IFNA(VLOOKUP(M21,Pivot!N:O,2,0),"")) -> 1
M22: Total | N22: =SUM(N7:N21) -> 30

Sheet Pivot
A1: 1 | E1: 2 | I1: 3 | N1: 4
A2: Certified Date | B2: (多项)
A3: Is Active | B3: Yes | N3: Certified Date | O3: (多项)
A4: CertValidation | B4: Valid | E4: Join Date | F4: (多项) | I4: Roll Off Date | J4: (多项) | N4: Is Active | O4: Yes
N5: CertValidation | O5: Valid
A6: 行标签 | B6: Sum of Points | E6: 行标签 | F6: Count of EID | I6: Count of EID | J6: 列标签
A7: Finance | B7: 491500 | E7: FinanceFinance1 | F7: 49 | I7: 行标签 | J7: Transfer | K7: Resign | L7: 总计 | N7: 行标签 | O7: Count of EID
A8: HR | B8: 10000 | E8: FinanceFinance2 | F8: 14 | I8: Finance | J8: 5 | K8: 13 | L8: 18 | N8: A360 Advanced | O8: 1
A9: Sales | B9: 30500 | E9: HR | F9: 22 | I9: HR | J9: 4 | K9: 4 | L9: 8 | N9: A360 Master | O9: 4
A10: 总计 | B10: 532000 | E10: Sales | F10: 16 | I10: Sales | J10: 1 | K10: 5 | L10: 6 | N10: ASD01 | O10: 1
E11: TechAI | F11: 16 | I11: Tech | J11: 4 | K11: 12 | L11: 16 | N11: ASDEV01 | O11: 2
E12: TechNon-AI | F12: 16 | I12: 总计 | J12: 14 | K12: 34 | L12: 48 | N12: PL-100 | O12: 14
E13: 总计 | F13: 133 | N13: PL-300 | O13: 2
N14: PL-400 | O14: 1
N15: PL-800 | O15: 1
N16: PL-900 | O16: 2
N17: UiRPA | O17: 1
N18: PL-200 | O18: 1
N19: 总计 | O19: 30

Sheet Version
A1: TECHNOLOGY | B1: Cetification Version | C1: Difficulty | D1: Merge | E1: Points
A2: AA | B2: A360 Advanced | C2: Advanced | D2: AAAdvanced | E2: 500
A3: AA | B3: A360 Master | C3: Master | D3: AAMaster | E3: 10000
A4: BP | B4: ASDEV01 | C4: Medium | D4: BPMedium | E4: 500
A5: BP | B5: ASD01 | C5: Medium | D5: BPMedium | E5: 500
A6: BP | B6: AD01 | C6: Advanced | D6: BPAdvanced | E6: 300
A7: BP | B7: APD01 | C7: Master | D7: BPMaster | E7: 5000
A8: UiPath | B8: UiADA | C8: Medium | D8: UiPathMedium | E8: 500
A9: UiPath | B9: UiARD | C9: Medium | D9: UiPathMedium | E9: 500
A10: PowerPlatform | B10: PL-200 | C10: Master | D10: PowerPlatformMaster | E10: 30000
A11: PowerPlatform | B11: PL-300 | C11: Master | D11: PowerPlatformMaster | E11: 30000
A12: PowerPlatform | B12: PL-400 | C12: Master | D12: PowerPlatformMaster | E12: 30000
A13: PowerPlatform | B13: PL-500 | C13: Master | D13: PowerPlatformMaster | E13: 30000
... A16: PowerPlatform | B16: PL-900 | C16: Advanced | D16: PowerPlatformAdvanced | E16: 5000
A17: PMP | B17: PMP | C17: Master | D17: PMPMaster
A18: Azure | B18: AZ-104 | C18: Master | D18: AzureMaster | E18: 3000
A19: Azure | B19: AZ-204 | C19: Master | D19: AzureMaster | E19: 3000
A20: Azure | B20: AZ-303 | C20: Master | D20: AzureMaster | E20: 3000
A21: Azure | B21: AZ-304 | C21: Master | D21: AzureMaster | E21: 3000
A22: Azure | B22: AZ-305 | C22: Master | D22: AzureMaster | E22: 3000
A23: Azure | B23: AZ-400 | C23: Master | D23: AzureMaster | E23: 3000
A24: Azure | B24: AZ-500 | C24: Master | D24: AzureMaster | E24: 3000
A25: Azure | B25: AZ-600 | C25: Master | D25: AzureMaster | E25: 3000
A26: Azure | B26: AZ-700 | C26: Master | D26: AzureMaster | E26: 3000
A27: Azure | B27: AZ-900 | C27: Master | D27: AzureMaster | E27: 3000
A28: Azure | B28: AI-102 | C28: Master | D28: AzureMaster | E28: 3000
A29: Azure | B29: AI-109 | C29: Master | D29: AzureMaster | E29: 3000
... A33: Azure | B33: DA-100 | C33: Master | D33: AzureMaster | E33: 3000

Sheet CL
A1: EID | B1: Career Level
A2: X1 | B2: 8
A3: X10 | B3: 10
A4: X100 | B4: 13
A5: X101 | B5: 13
A6: X102 | B6: 13
A7: X103 | B7: 13
A8: X104 | B8: 13
A9: X105 | B9: 13
A10: X106 | B10: 12
A11: X107 | B11: 12
A12: X108 | B12: 12
... A136: X99 | B136: 13

Sheet CertTracker
A1: Certification Name | B1: Version | C1: Certified Date | D1: EID | E1: CertUpload | F1: CertValidation | G1: Points
A2: AA | B2: A360 Advanced | C2: 44672 | D2: X1 | E2: Yes | F2: Valid | G2: 500
A3: AA | B3: A360 Master | C3: 44897 | D3: X10 | E3: Yes | F3: Valid | G3: 10000
A4: BP | B4: ASD01 | C4: 44609 | D4: X4 | E4: Yes | F4: Valid | G4: 500
A5: BP | B5: ASD01 | C5: 44609 | D5: X13 | E5: Yes | F5: Valid | G5: 500
A6: BP | B6: ASD01 | C6: 44609 | D6: X15 | E6: Yes | F6: Valid | G6: 500
A7: BP | B7: ASD01 | C7: 44609 | D7: X27 | E7: Yes | F7: Valid | G7: 500
A8: BP | B8: ASD01 | C8: 44609 | D8: X31 | E8: Yes | F8: Valid | G8: 500
A9: BP | B9: ASDEV01 | C9: 44530 | D9: X8 | E9: Yes | F9: Valid | G9: 500
A10: BP | B10: ASDEV01 | C10: 44530 | D10: X34 | E10: Yes | F10: Valid | G10: 500
A11: BP | B11: ASDEV01 | C11: 44530 | D11: X36 | E11: Yes | F11: Valid | G11: 500
A12: BP | B12: ASDEV01 | C12: 44530 | D12: X44 | E12: Yes | F12: Valid | G12: 500
A13: BP | B13: ASDEV01 | C13: 44530 | D13: X46 | E13: Yes | F13: Valid | G13: 500
... A31: PowerApp | B31: PL-100 | C31: 44530 | D31: X52 | E31: Yes | F31: Valid | G31: 30000
A32: PowerApp | B32: PL-200 | C32: 44609 | D32: X111 | E32: Yes | F32: Valid
A33: PowerApp | B33: PL-200 | C33: 44559 | D33: X24 | E33: Yes | F33: Valid
A34: PowerApp | B34: PL-200 | C34: 44949 | D34: X25 | E34: Yes | F34: Invalid
A35: PowerApp | B35: PL-100 | C35: 44530 | D35: X53 | E35: Yes | F35: Valid | G35: 30000
A36: PowerApp | B36: PL-100 | C36: 44530 | D36: X54 | E36: Yes | F36: Valid | G36: 30000
A37: PowerApp | B37: PL-100 | C37: 44530 | D37: X55 | E37: Yes | F37: Valid | G37: 30000
A38: PowerApp | B38: PL-100 | C38: 44530 | D38: X56 | E38: Yes | F38: Valid | G38: 30000
A39: PowerApp | B39: PL-100 | C39: 44530 | D39: X57 | E39: Yes | F39: Valid | G39: 30000
A40: PowerApp | B40: PL-100 | C40: 44530 | D40: X58 | E40: Yes | F40: Valid | G40: 30000
A41: PowerApp | B41: PL-100 | C41: 44530 | D41: X59 | E41: Yes | F41: Valid | G41: 30000
A42: PowerBI | B42: PL-300 | C42: 44949 | D42: X3 | E42: Yes | F42: Valid | G42: 30000
A43: PowerBI | B43: Pl-300 | C43: 44711 | D43: X7 | E43: Yes | F43: Valid
A44: PowerBI | B44: Pl-300 | C44: 44897 | D44: X12 | E44: Yes | F44: Valid
A45: PowerBI | B45: Pl-300 | C45: 44609 | D45: X26 | E45: Yes | F45: Invalid
A46: PowerBI | B46: PL-600 | C46: 44958 | D46: X30 | E46: Yes | F46: Invalid | G46: 30000
A47: PowerBI | B47: PL-700 | C47: 44958 | D47: X33 | E47: Yes | F47: Valid
A48: PowerBI | B48: PL-800 | C48: 44958 | D48: X43 | E48: Yes | F48: Valid
A49: PowerAuto | B49: PL-900 | C49: 44559 | D49: X5 | E49: Yes | F49: Valid | G49: 5000
A50: PowerAuto | B50: PL-900 | C50: 44897 | D50: X9 | E50: Yes | F50: Valid | G50: 5000
A51: PowerAuto | B51: PL-900 | C51: 44609 | D51: X14 | E51: Yes | F51: Valid | G51: 5000
A52: PowerAuto | B52: PL-900 | C52: 44609 | D52: X16 | E52: Yes | F52: Valid | G52: 5000
A53: PowerAuto | B53: PL-900 | C53: 44562 | D53: X28 | E53: Yes | F53: Invalid | G53: 5000
A54: PowerAuto | B54: PL-900 | C54: 44958 | D54: X35 | E54: Yes | F54: Valid | G54: 5000
A55: PowerAuto | B55: PL-500 | C55: 44562 | D55: X37 | E55: Yes | F55: Valid | G55: 30000
A56: PowerAuto | B56: PL-500 | C56: 44958 | D56: X45 | E56: Yes | F56: Valid | G56: 30000
A57: PowerAuto | B57: PL-500 | C57: 44562 | D57: X47 | E57: Yes | F57: Valid | G57: 30000
...

Sheet CertDifficulty
A1: Technology | B1: Difficulty | C1: Points | D1: Merged
A2: AA | B2: Advanced | C2: 500 | D2: AAAdvanced
A3: AA | B3: Medium | C3: 1000 | D3: AAMedium
A4: AA | B4: Master | C4: 10000 | D4: AAMaster
A5: BP | B5: Advanced | C5: 300 | D5: BPAdvanced
A6: BP | B6: Medium | C6: 500 | D6: BPMedium
A7: BP | B7: Master | C7: 5000 | D7: BPMaster
A8: UiPath | B8: Advanced | C8: 200 | D8: UiPathAdvanced
A9: UiPath | B9: Medium | C9: 500 | D9: UiPathMedium
A10: UiPath | B10: Master | C10: 4000 | D10: UiPathMaster
A11: Azure | B11: Advanced | C11: 100 | D11: AzureAdvanced
A12: Azure | B12: Medium | C12: 200 | D12: AzureMedium
A13: Azure | B13: Master | C13: 3000 | D13: AzureMaster
... A16: PowerPlatform | B16: Master | C16: 30000 | D16: PowerPlatformMaster

Sheet ResourceInfo-Test
A1: Group | B1: SubTeam | C1: Group&SubTeam | D1: EID | E1: Employment Type | F1: Utilization Status | G1: Leave Start | H1: Leave End | I1: Join Date | J1: Is Active | K1: Roll Off Date | L1: Roll Off Reason | M1: Career Level | N1: Certification Name | O1: Version | P1: Certified Date | Q1: CertValidation | R1: Points
A2: Finance | B2: Finance1 | C2: FinanceFinance1 | D2: X1 | E2: Regular | F2: In Project (Digi) | I2: 43658 | J2: Yes | M2: 8 | N2: AA | O2: A360 Advanced | P2: 44672 | Q2: Valid | R2: 500
A3: Tech | B3: AI | C3: TechAI | D3: X25 | E3: Regular | F3: In Project (Digi) | I3: 42331 | J3: No | K3: 44986 | L3: Resign | M3: 5 | N3: PowerApp | O3: PL-200 | P3: 44949 | Q3: Invalid
A4: Finance | B4: Finance2 | C4: FinanceFinance2 | D4: X10 | E4: Regular | F4: In Project (Digi) | I4: 44705 | J4: Yes | M4: 10 | N4: AA | O4: A360 Master | P4: 44897 | Q4: Valid | R4: 10000
A5: Finance | B5: Finance1 | C5: FinanceFinance1 | D5: X2 | E5: Regular | F5: In Project (Digi) | I5: 43658 | J5: Yes | M5: 9 | N5: Uipath | O5: UiRPA | P5: 44681 | Q5: Valid
A6: Finance | B6: Finance1 | C6: FinanceFinance1 | D6: X4 | E6: Regular | F6: In Project (Digi) | I6: 43658 | J6: Yes | M6: 6 | N6: BP | O6: ASD01 | P6: 44609 | Q6: Valid | R6: 500
A7: Finance | B7: Finance1 | C7: FinanceFinance1 | D7: X6 | E7: Regular | F7: In Project (Digi) | I7: 43658 | J7: Yes | M7: 4 | N7: PowerApp | O7: PL-100 | P7: 44708 | Q7: Valid | R7: 30000
A8: Finance | B8: Finance2 | C8: FinanceFinance2 | D8: X13 | E8: Regular | F8: In Project (Digi) | I8: 44938 | J8: No | K8: 44986 | L8: Resign | M8: 6 | N8: BP | O8: ASD01 | P8: 44609 | Q8: Valid | R8: 500
A9: Finance | B9: Finance1 | C9: FinanceFinance1 | D9: X3 | E9: Regular | F9: In Project (Digi) | I9: 43658 | J9: Yes | M9: 6 | N9: PowerBI | O9: PL-300 | P9: 44949 | Q9: Valid | R9: 30000
A10: Finance | B10: Finance2 | C10: FinanceFinance2 | D10: X15 | E10: Regular | F10: In Project (Digi) | I10: 44938 | J10: No | K10: 44986 | L10: Resign | M10: 10 | N10: BP | O10: ASD01 | P10: 44609 | Q10: Valid | R10: 500
A11: Tech | B11: AI | C11: TechAI | D11: X26 | E11: Regular | F11: In Project (Digi) | I11: 42331 | J11: No | K11: 44986 | L11: Resign | M11: 7 | N11: PowerBI | O11: Pl-300 | P11: 44609 | Q11: Invalid
A12: Tech | B12: AI | C12: TechAI | D12: X27 | E12: Regular | F12: In Project (Digi) | I12: 42331 | J12: No | K12: 44721 | L12: Resign | M12: 9 | N12: BP | O12: ASD01 | P12: 44609 | Q12: Valid | R12: 500
A13: Tech | B13: AI | C13: TechAI | D13: X31 | E13: Contractor | F13: In Project (Digi) | I13: 42331 | J13: No | K13: 44986 | L13: Resign | M13: 6 | N13: BP | O13: ASD01 | P13: 44609 | Q13: Valid | R13: 500
A14: Tech | B14: AI | C14: TechAI | D14: X29 | E14: Regular | F14: In Project (Digi) | I14: 42331 | J14: No | K14: 44986 | L14: Resign | M14: 7 | N14: PowerApp | O14: PL-400 | P14: 44958 | Q14: Invalid | R14: 30000
A15: Finance | B15: Finance1 | C15: FinanceFinance1 | D15: X8 | E15: Regular | F15: In Project (Digi) | I15: 43658 | J15: Yes | M15: 6 | N15: BP | O15: ASDEV01 | P15: 44530 | Q15: Valid | R15: 500
A16: Finance | B16: Finance1 | C16: FinanceFinance1 | D16: X5 | E16: Regular | F16: In Project (Digi) | I16: 43658 | J16: Yes | M16: 9 | N16: PowerAuto | O16: PL-900 | P16: 44559 | Q16: Valid | R16: 5000
A17: Tech | B17: Non-AI | C17: TechNon-AI | D17: X34 | E17: Regular | F17: In Project (Digi) | I17: 42331 | J17: No | K17: 44986 | L17: Resign | M17: 13 | N17: BP | O17: ASDEV01 | P17: 44530 | Q17: Valid | R17: 500
A18: Finance | B18: Finance1 | C18: FinanceFinance1 | D18: X7 | E18: Regular | F18: In Project (Digi) | I18: 43658 | J18: Yes | M18: 7 | N18: PowerBI | O18: Pl-300 | P18: 44711 | Q18: Valid
A19: Tech | B19: Non-AI | C19: TechNon-AI | D19: X36 | E19: Regular | F19: In Project (Digi) | I19: 42005 | J19: No | K19: 44866 | L19: Transfer | M19: 13 | N19: BP | O19: ASDEV01 | P19: 44530 | Q19: Valid | R19: 500
A20: Finance | B20: Finance2 | C20: FinanceFinance2 | D20: X12 | E20: Regular | F20: In Project (Digi) | I20: 44308 | J20: No | K20: 44866 | L20: Transfer | M20: 7 | N20: PowerBI | O20: Pl-300 | P20: 44897 | Q20: Valid
A21: Sales | C21: Sales | D21: X44 | E21: Regular | F21: In Project (Digi) | I21: 42005 | J21: Yes | M21: 13 | N21: BP | O21: ASDEV01 | P21: 44530 | Q21: Valid | R21: 500
A22: HR | C22: HR | D22: X19 | E22: Regular | F22: In Project (Digi) | I22: 44938 | J22: No | K22: 44986 | L22: Resign | M22: 7
A23: Sales | C23: Sales | D23: X46 | E23: Regular | F23: In Project (Digi) | I23: 42005 | J23: No | K23: 44383 | L23: Resign | M23: 13 | N23: BP | O23: ASDEV01 | P23: 44530 | Q23: Valid | R23: 500
A24: HR | C24: HR | D24: X23 | E24: Regular | F24: In Project (Digi) | G24: 44811 | H24: 44837 | I24: 44378 | J24: No | K24: 44833 | L24: Transfer | M24: 7 | N24: PowerApp | O24: PL-400 | P24: 44609 | Q24: Valid | R24: 30000
A25: Finance | B25: Finance2 | C25: FinanceFinance2 | D25: X9 | E25: Regular | F25: In Project (Digi) | I25: 44454 | J25: Yes | M25: 8 | N25: PowerAuto | O25: PL-900 | P25: 44897 | Q25: Valid | R25: 5000
A26: Tech | B26: AI | C26: TechAI | D26: X30 | E26: Regular | F26: In Project (Digi) | I26: 42331 | J26: No | K26: 44721 | L26: Transfer | M26: 5 | N26: PowerBI | O26: PL-600 | P26: 44958 | Q26: Invalid | R26: 30000
A27: Tech | B27: Non-AI | C27: TechNon-AI | D27: X38 | E27: Regular | F27: In Project (Digi) | I27: 42005 | J27: No | K27: 44986 | L27: Resign | M27: 13 | N27: PowerApp | O27: PL-400 | P27: 44562 | Q27: Valid | R27: 30000
A28: Finance | B28: Finance2 | C28: FinanceFinance2 | D28: X11 | E28: Regular | F28: In Project (Digi) | I28: 44938 | J28: No | K28: 44986 | L28: Resign | M28: 11 | N28: Uipath | O28: UiARD | P28: 44897 | Q28: Valid | R28: 500
A29: Finance | B29: Finance2 | C29: FinanceFinance2 | D29: X14 | E29: Regular | F29: On Maternity Leave | I29: 44938 | J29: No | K29: 44721 | L29: Transfer | M29: 8 | N29: PowerAuto | O29: PL-900 | P29: 44609 | Q29: Valid | R29: 5000
A30: HR | C30: HR | D30: X17 | E30: Contractor | F30: In Project (Digi) | I30: 44938 | J30: No | K30: 44665 | L30: Resign | M30: 6
A31: Tech | B31: Non-AI | C31: TechNon-AI | D31: X39 | E31: Regular | F31: Deployed to Account/Client site | I31: 42005 | J31: No | K31: 43993 | L31: Resign | M31: 13 | N31: PowerApp | O31: PL-100 | P31: 44595 | Q31: Valid | R31: 30000
A32: Tech | B32: AI | C32: TechAI | D32: X28 | E32: Regular | F32: In Project (Digi) | I32: 42331 | J32: No | K32: 44721 | L32: Transfer | M32: 6 | N32: PowerAuto | O32: PL-900 | P32: 44562 | Q32: Invalid | R32: 5000
A33: Tech | B33: Non-AI | C33: TechNon-AI | D33: X40 | E33: Regular | F33: In Project (Digi) | I33: 42005 | J33: No | K33: 44986 | L33: Resign | M33: 13 | N33: PowerApp | O33: PL-100 | P33: 44530 | Q33: Valid | R33: 30000
A34: Finance | B34: Finance2 | C34: FinanceFinance2 | D34: X16 | E34: Regular | F34: In Project (Digi) | I34: 44938 | J34: No | K34: 44893 | L34: Resign | M34: 11 | N34: PowerAuto | O34: PL-900 | P34: 44609 | Q34: Valid | R34: 5000
A35: Sales | C35: Sales | D35: X41 | E35: Regular | F35: In Project (Digi) | I35: 42005 | J35: No | K35: 44986 | L35: Resign | M35: 13 | N35: PowerApp | O35: PL-100 | P35: 44530 | Q35: Valid | R35: 30000
A36: Sales | C36: Sales | D36: X42 | E36: Regular | F36: In Project (Digi) | I36: 42005 | J36: Yes | M36: 13 | N36: PowerApp | O36: PL-100 | P36: 44530 | Q36: Valid | R36: 30000
A37: HR | C37: HR | D37: X18 | E37: Regular | F37: In Project (Digi) | I37: 44938 | J37: No | K37: 44986 | L37: Resign | M37: 9
A38: Sales | C38: Sales | D38: X48 | E38: Regular | F38: In Project (Digi) | I38: 42005 | J38: No | K38: 44866 | L38: Resign | M38: 13 | N38: PowerApp | O38: PL-100 | P38: 44562 | Q38: Valid | R38: 30000
A39: HR | C39: HR | D39: X20 | E39: Regular | F39: In Project (Digi) | I39: 44938 | J39: No | K39: 44477 | L39: Transfer | M39: 9
A40: Finance | B40: Finance1 | C40: FinanceFinance1 | D40: X49 | E40: Regular | F40: In Project (Digi) | I40: 43658 | J40: No | K40: 43658 | L40: Resign | M40: 13 | N40: PowerApp | O40: PL-100 | P40: 44595 | Q40: Valid | R40: 30000
...
